<?xml version="1.0" ?>
<robot name="garrix_v1">
    <link name="garrix_v1_root">
        <inertial>
            <origin rpy="0.0 0.0 0.0" xyz="0.0021636029411764707 0.0021636029411764702 0.0"/>
            <mass value="2.720000e-01"/>
            <inertia ixx="2.720827e-04" ixy="5.057991e-22" ixz="-5.057991e-22" iyy="2.766833e-04" iyz="9.933154e-24" izz="3.961637e-04"/>
        </inertial>
        <collision name="garrix_v1_root_geom0">
            <geometry>
                <box size="0.089 0.089 0.0603"/>
            </geometry>
            <origin rpy="0.0 0.0 0.0" xyz="0.0 0.0 0.0"/>
        </collision>
        <collision name="garrix_v1_root_geom1">
            <geometry>
                <box size="0.018 0.053 0.0165891"/>
            </geometry>
            <origin rpy="1.5707963267948966 0.0 0.0" xyz="0.0535 0.0 0.0"/>
        </collision>
        <collision name="garrix_v1_root_geom2">
            <geometry>
                <box size="0.018 0.053 0.0165891"/>
            </geometry>
            <origin rpy="1.5707963267948963 0.0 1.5707963267948963" xyz="1.214306433183765e-17 0.0535 0.0"/>
        </collision>
    </link>
    <joint type="revolute" name="garrix_v1_root_joint0">
        <parent link="garrix_v1_root"/>
        <child link="garrix_v1_root_link0"/>
        <origin rpy="1.5707963267948966 0.0 0.0" xyz="0.07902499999999998 0.0 0.0"/>
        <axis xyz="0 1 0"/>
        <limit lower="-1.047197551" upper="1.047197551" effort="0.948013269" velocity="6.338968228"/>
    </joint>
    <link name="garrix_v1_root_link0">
        <inertial>
            <origin rpy="0.0 0.0 0.0" xyz="0.025730769230769245 0.0 0.0"/>
            <mass value="7.800000e-02"/>
            <inertia ixx="2.396696e-05" ixy="0.000000e+00" ixz="0.000000e+00" iyy="3.656843e-05" iyz="0.000000e+00" izz="4.730539e-05"/>
        </inertial>
        <collision name="garrix_v1_root_link0_geom0">
            <geometry>
                <box size="0.0583 0.0512 0.02"/>
            </geometry>
            <origin rpy="0.0 0.0 0.0" xyz="0.018000000000000016 0.0 0.0"/>
        </collision>
        <collision name="garrix_v1_root_link0_geom1">
            <geometry>
                <box size="0.002 0.053 0.053"/>
            </geometry>
            <origin rpy="0.0 0.0 0.0" xyz="0.04815000000000001 0.0 0.0"/>
        </collision>
    </link>
    <joint type="revolute" name="garrix_v1_root_joint1">
        <parent link="garrix_v1_root"/>
        <child link="garrix_v1_root_link1"/>
        <origin rpy="1.5707963267948963 0.0 1.5707963267948963" xyz="1.734723475976807e-17 0.07902499999999998 0.0"/>
        <axis xyz="0 1 0"/>
        <limit lower="-1.047197551" upper="1.047197551" effort="0.948013269" velocity="6.338968228"/>
    </joint>
    <link name="garrix_v1_root_link1">
        <inertial>
            <origin rpy="0.0 0.0 0.0" xyz="0.029737640449438205 0.0 0.0"/>
            <mass value="8.900000e-02"/>
            <inertia ixx="2.679414e-05" ixy="0.000000e+00" ixz="0.000000e+00" iyy="4.724987e-05" iyz="0.000000e+00" izz="6.030948e-05"/>
        </inertial>
        <collision name="garrix_v1_root_link1_geom0">
            <geometry>
                <box size="0.0583 0.0512 0.02"/>
            </geometry>
            <origin rpy="0.0 0.0 0.0" xyz="0.018000000000000002 0.0 0.0"/>
        </collision>
        <collision name="garrix_v1_root_link1_geom1">
            <geometry>
                <box size="0.002 0.053 0.053"/>
            </geometry>
            <origin rpy="0.0 0.0 0.0" xyz="0.04815 -1.734723475976807e-18 -1.734723475976807e-18"/>
        </collision>
        <collision name="garrix_v1_root_link1_geom2">
            <geometry>
                <box size="0.018 0.053 0.0165891"/>
            </geometry>
            <origin rpy="0.0 0.0 0.0" xyz="0.05815000000000001 -1.734723475976807e-18 -5.204170427930421e-18"/>
        </collision>
    </link>
    <joint type="revolute" name="garrix_v1_root_link1_joint1">
        <parent link="garrix_v1_root_link1"/>
        <child link="garrix_v1_root_link1_link1"/>
        <origin rpy="0.0 0.0 0.0" xyz="0.083675 0.0 0.0"/>
        <axis xyz="0 1 0"/>
        <limit lower="-1.047197551" upper="1.047197551" effort="0.948013269" velocity="6.338968228"/>
    </joint>
    <link name="garrix_v1_root_link1_link1">
        <inertial>
            <origin rpy="0.0 0.0 0.0" xyz="0.02973764044943819 0.0 -3.469446951953614e-18"/>
            <mass value="8.900000e-02"/>
            <inertia ixx="2.451623e-05" ixy="-5.057991e-22" ixz="0.000000e+00" iyy="4.952779e-05" iyz="0.000000e+00" izz="6.030948e-05"/>
        </inertial>
        <collision name="garrix_v1_root_link1_link1_geom0">
            <geometry>
                <box size="0.0583 0.0512 0.02"/>
            </geometry>
            <origin rpy="0.0 0.0 0.0" xyz="0.017999999999999988 0.0 -3.469446951953614e-18"/>
        </collision>
        <collision name="garrix_v1_root_link1_link1_geom1">
            <geometry>
                <box size="0.002 0.053 0.053"/>
            </geometry>
            <origin rpy="0.0 0.0 0.0" xyz="0.048149999999999984 0.0 -6.938893903907228e-18"/>
        </collision>
        <collision name="garrix_v1_root_link1_link1_geom2">
            <geometry>
                <box size="0.018 0.053 0.0165891"/>
            </geometry>
            <origin rpy="-1.5707963267948966 0.0 0.0" xyz="0.058149999999999986 0.0 -6.938893903907228e-18"/>
        </collision>
    </link>
    <joint type="revolute" name="garrix_v1_root_link1_link1_joint1">
        <parent link="garrix_v1_root_link1_link1"/>
        <child link="garrix_v1_root_link1_link1_link1"/>
        <origin rpy="-1.5707963267948966 0.0 0.0" xyz="0.08367499999999997 0.0 0.0"/>
        <axis xyz="0 1 0"/>
        <limit lower="-1.047197551" upper="1.047197551" effort="0.948013269" velocity="6.338968228"/>
    </joint>
    <link name="garrix_v1_root_link1_link1_link1">
        <inertial>
            <origin rpy="0.0 0.0 0.0" xyz="0.0645348951342282 0.0029857340604026797 0.0"/>
            <mass value="1.490000e-01"/>
            <inertia ixx="8.141183e-05" ixy="0.000000e+00" ixz="0.000000e+00" iyy="3.923830e-04" iyz="5.157323e-22" izz="4.190541e-04"/>
        </inertial>
        <collision name="garrix_v1_root_link1_link1_link1_geom0">
            <geometry>
                <box size="0.0583 0.0512 0.02"/>
            </geometry>
            <origin rpy="0.0 0.0 0.0" xyz="0.018000000000000016 3.469446951953614e-18 0.0"/>
        </collision>
        <collision name="garrix_v1_root_link1_link1_link1_geom1">
            <geometry>
                <box size="0.002 0.053 0.053"/>
            </geometry>
            <origin rpy="0.0 0.0 0.0" xyz="0.04815000000000001 0.0 0.0"/>
        </collision>
        <collision name="garrix_v1_root_link1_link1_link1_geom2">
            <geometry>
                <box size="0.06288625 0.06288625 0.0603"/>
            </geometry>
            <origin rpy="0.0 0.0 0.0" xyz="0.08059312500000002 6.938893903907228e-18 0.0"/>
        </collision>
        <collision name="garrix_v1_root_link1_link1_link1_geom3">
            <geometry>
                <box size="0.06288625 0.06288625 0.0603"/>
            </geometry>
            <origin rpy="0.0 0.0 0.0" xyz="0.14347937500000002 0.0 0.0"/>
        </collision>
        <collision name="garrix_v1_root_link1_link1_link1_geom4">
            <geometry>
                <box size="0.018 0.053 0.0165891"/>
            </geometry>
            <origin rpy="0.0 0.0 1.5707963267948966" xyz="0.080593125 0.04044312500000001 0.0"/>
        </collision>
    </link>
    <joint type="revolute" name="garrix_v1_root_link1_link1_link1_joint1">
        <parent link="garrix_v1_root_link1_link1_link1"/>
        <child link="garrix_v1_root_link1_link1_link1_link1"/>
        <origin rpy="0.0 0.0 1.5707963267948966" xyz="0.08059312500000003 0.06596812499999999 0.0"/>
        <axis xyz="0 1 0"/>
        <limit lower="-1.047197551" upper="1.047197551" effort="0.948013269" velocity="6.338968228"/>
    </joint>
    <link name="garrix_v1_root_link1_link1_link1_link1">
        <inertial>
            <origin rpy="0.0 0.0 0.0" xyz="0.05339887411347519 6.350475700855896e-17 0.0"/>
            <mass value="1.410000e-01"/>
            <inertia ixx="8.285382e-05" ixy="5.057991e-22" ixz="5.057991e-22" iyy="2.126056e-04" iyz="5.256654e-22" izz="2.578006e-04"/>
        </inertial>
        <collision name="garrix_v1_root_link1_link1_link1_link1_geom0">
            <geometry>
                <box size="0.0583 0.0512 0.02"/>
            </geometry>
            <origin rpy="0.0 0.0 0.0" xyz="0.018000000000000016 6.350475700855896e-17 0.0"/>
        </collision>
        <collision name="garrix_v1_root_link1_link1_link1_link1_geom1">
            <geometry>
                <box size="0.002 0.053 0.053"/>
            </geometry>
            <origin rpy="0.0 0.0 0.0" xyz="0.04815000000000001 6.350475700855896e-17 0.0"/>
        </collision>
        <collision name="garrix_v1_root_link1_link1_link1_link1_geom2">
            <geometry>
                <box size="0.06288625 0.06288625 0.0603"/>
            </geometry>
            <origin rpy="0.0 0.0 0.0" xyz="0.08059312500000002 6.350475700855896e-17 0.0"/>
        </collision>
        <collision name="garrix_v1_root_link1_link1_link1_link1_geom3">
            <geometry>
                <box size="0.018 0.053 0.0165891"/>
            </geometry>
            <origin rpy="1.5707963267948966 0.0 0.0" xyz="0.12103625000000001 6.350475700855896e-17 0.0"/>
        </collision>
        <collision name="garrix_v1_root_link1_link1_link1_link1_geom4">
            <geometry>
                <box size="0.018 0.053 0.0165891"/>
            </geometry>
            <origin rpy="0.0 0.0 1.5707963267948966" xyz="0.08059312500000002 0.04044312500000007 0.0"/>
        </collision>
        <collision name="garrix_v1_root_link1_link1_link1_link1_geom5">
            <geometry>
                <box size="0.018 0.053 0.0165891"/>
            </geometry>
            <origin rpy="1.5707963267948966 0.0 -1.5707963267948966" xyz="0.08059312500000002 -0.040443124999999934 0.0"/>
        </collision>
    </link>
    <joint type="revolute" name="garrix_v1_root_link1_link1_link1_link1_joint1">
        <parent link="garrix_v1_root_link1_link1_link1_link1"/>
        <child link="garrix_v1_root_link1_link1_link1_link1_link1"/>
        <origin rpy="1.5707963267948966 0.0 0.0" xyz="0.14656125 6.508626970713749e-17 0.0"/>
        <axis xyz="0 1 0"/>
        <limit lower="-1.047197551" upper="1.047197551" effort="0.948013269" velocity="6.338968228"/>
    </joint>
    <link name="garrix_v1_root_link1_link1_link1_link1_link1">
        <inertial>
            <origin rpy="4.930380657631324e-32 0.0 0.0" xyz="0.025730769230769245 1.925929944387236e-33 -7.993605777301134e-18"/>
            <mass value="7.800000e-02"/>
            <inertia ixx="2.396696e-05" ixy="0.000000e+00" ixz="0.000000e+00" iyy="3.656843e-05" iyz="0.000000e+00" izz="4.730539e-05"/>
        </inertial>
        <collision name="garrix_v1_root_link1_link1_link1_link1_link1_geom0">
            <geometry>
                <box size="0.0583 0.0512 0.02"/>
            </geometry>
            <origin rpy="4.930380657631324e-32 0.0 0.0" xyz="0.018000000000000016 1.5407439555097887e-33 -7.993605777301134e-18"/>
        </collision>
        <collision name="garrix_v1_root_link1_link1_link1_link1_link1_geom1">
            <geometry>
                <box size="0.002 0.053 0.053"/>
            </geometry>
            <origin rpy="4.930380657631324e-32 0.0 0.0" xyz="0.04815000000000001 0.0 -7.993605777301134e-18"/>
        </collision>
    </link>
    <joint type="revolute" name="garrix_v1_root_link1_link1_link1_link1_joint2">
        <parent link="garrix_v1_root_link1_link1_link1_link1"/>
        <child link="garrix_v1_root_link1_link1_link1_link1_link2"/>
        <origin rpy="0.0 0.0 1.5707963267948966" xyz="0.08059312500000002 0.06596812500000007 0.0"/>
        <axis xyz="0 1 0"/>
        <limit lower="-1.047197551" upper="1.047197551" effort="0.948013269" velocity="6.338968228"/>
    </joint>
    <link name="garrix_v1_root_link1_link1_link1_link1_link2">
        <inertial>
            <origin rpy="0.0 0.0 0.0" xyz="0.02973764044943819 6.938893903907228e-18 -0.0"/>
            <mass value="8.900000e-02"/>
            <inertia ixx="2.451623e-05" ixy="5.057991e-22" ixz="0.000000e+00" iyy="4.952779e-05" iyz="0.000000e+00" izz="6.030948e-05"/>
        </inertial>
        <collision name="garrix_v1_root_link1_link1_link1_link1_link2_geom0">
            <geometry>
                <box size="0.0583 0.0512 0.02"/>
            </geometry>
            <origin rpy="0.0 0.0 0.0" xyz="0.017999999999999988 8.673617379884035e-18 -0.0"/>
        </collision>
        <collision name="garrix_v1_root_link1_link1_link1_link1_link2_geom1">
            <geometry>
                <box size="0.002 0.053 0.053"/>
            </geometry>
            <origin rpy="0.0 0.0 0.0" xyz="0.048149999999999984 1.734723475976807e-17 -0.0"/>
        </collision>
        <collision name="garrix_v1_root_link1_link1_link1_link1_link2_geom2">
            <geometry>
                <box size="0.018 0.053 0.0165891"/>
            </geometry>
            <origin rpy="1.5707963267948966 0.0 0.0" xyz="0.058149999999999986 6.938893903907228e-18 -0.0"/>
        </collision>
    </link>
    <joint type="revolute" name="garrix_v1_root_link1_link1_link1_link1_link2_joint1">
        <parent link="garrix_v1_root_link1_link1_link1_link1_link2"/>
        <child link="garrix_v1_root_link1_link1_link1_link1_link2_link1"/>
        <origin rpy="1.5707963267948966 -2.220446049250313e-16 1.1102230246251565e-16" xyz="0.083675 6.938893903907228e-18 -0.0"/>
        <axis xyz="0 1 0"/>
        <limit lower="-1.047197551" upper="1.047197551" effort="0.948013269" velocity="6.338968228"/>
    </joint>
    <link name="garrix_v1_root_link1_link1_link1_link1_link2_link1">
        <inertial>
            <origin rpy="1.1102230246251563e-16 0.0 1.1102230246251563e-16" xyz="0.029737640449438198 -1.734723475976807e-18 1.5612511283791264e-17"/>
            <mass value="8.900000e-02"/>
            <inertia ixx="2.451623e-05" ixy="-5.057991e-22" ixz="0.000000e+00" iyy="4.952779e-05" iyz="0.000000e+00" izz="6.030948e-05"/>
        </inertial>
        <collision name="garrix_v1_root_link1_link1_link1_link1_link2_link1_geom0">
            <geometry>
                <box size="0.0583 0.0512 0.02"/>
            </geometry>
            <origin rpy="1.1102230246251563e-16 0.0 1.1102230246251563e-16" xyz="0.01799999999999999 0.0 1.734723475976807e-17"/>
        </collision>
        <collision name="garrix_v1_root_link1_link1_link1_link1_link2_link1_geom1">
            <geometry>
                <box size="0.002 0.053 0.053"/>
            </geometry>
            <origin rpy="1.1102230246251563e-16 0.0 1.1102230246251563e-16" xyz="0.04815 -3.469446951953614e-18 1.0408340855860843e-17"/>
        </collision>
        <collision name="garrix_v1_root_link1_link1_link1_link1_link2_link1_geom2">
            <geometry>
                <box size="0.018 0.053 0.0165891"/>
            </geometry>
            <origin rpy="-1.5707963267948966 2.220446049250313e-16 1.1102230246251565e-16" xyz="0.05815000000000001 0.0 6.938893903907228e-18"/>
        </collision>
    </link>
    <joint type="revolute" name="garrix_v1_root_link1_link1_link1_link1_link2_link1_joint1">
        <parent link="garrix_v1_root_link1_link1_link1_link1_link2_link1"/>
        <child link="garrix_v1_root_link1_link1_link1_link1_link2_link1_link1"/>
        <origin rpy="-1.5707963267948966 0.0 0.0" xyz="0.083675 6.938893903907228e-18 0.0"/>
        <axis xyz="0 1 0"/>
        <limit lower="-1.047197551" upper="1.047197551" effort="0.948013269" velocity="6.338968228"/>
    </joint>
    <link name="garrix_v1_root_link1_link1_link1_link1_link2_link1_link1">
        <inertial>
            <origin rpy="0.0 0.0 0.0" xyz="0.040970312499999995 1.0408340855860843e-17 -1.413083212815398e-18"/>
            <mass value="1.080000e-01"/>
            <inertia ixx="4.294389e-05" ixy="0.000000e+00" ixz="0.000000e+00" iyy="1.207594e-04" iyz="0.000000e+00" izz="1.322928e-04"/>
        </inertial>
        <collision name="garrix_v1_root_link1_link1_link1_link1_link2_link1_link1_geom0">
            <geometry>
                <box size="0.0583 0.0512 0.02"/>
            </geometry>
            <origin rpy="0.0 0.0 0.0" xyz="0.018000000000000002 1.0408340855860843e-17 -1.4130832128153981e-18"/>
        </collision>
        <collision name="garrix_v1_root_link1_link1_link1_link1_link2_link1_link1_geom1">
            <geometry>
                <box size="0.002 0.053 0.053"/>
            </geometry>
            <origin rpy="0.0 0.0 0.0" xyz="0.04815 1.3877787807814457e-17 -1.413083212815398e-18"/>
        </collision>
        <collision name="garrix_v1_root_link1_link1_link1_link1_link2_link1_link1_geom2">
            <geometry>
                <box size="0.06288625 0.06288625 0.0603"/>
            </geometry>
            <origin rpy="0.0 0.0 0.0" xyz="0.08059312499999999 0.0 -1.413083212815398e-18"/>
        </collision>
    </link>
    <joint type="revolute" name="garrix_v1_root_link1_link1_link1_link1_joint3">
        <parent link="garrix_v1_root_link1_link1_link1_link1"/>
        <child link="garrix_v1_root_link1_link1_link1_link1_link3"/>
        <origin rpy="1.5707963267948966 0.0 -1.5707963267948966" xyz="0.08059312500000002 -0.06596812499999996 0.0"/>
        <axis xyz="0 1 0"/>
        <limit lower="-1.047197551" upper="1.047197551" effort="0.948013269" velocity="6.338968228"/>
    </joint>
    <link name="garrix_v1_root_link1_link1_link1_link1_link3">
        <inertial>
            <origin rpy="0.0 0.0 0.0" xyz="0.02573076923076925 0.0 -1.214306433183765e-17"/>
            <mass value="7.800000e-02"/>
            <inertia ixx="2.396696e-05" ixy="0.000000e+00" ixz="0.000000e+00" iyy="3.656843e-05" iyz="0.000000e+00" izz="4.730539e-05"/>
        </inertial>
        <collision name="garrix_v1_root_link1_link1_link1_link1_link3_geom0">
            <geometry>
                <box size="0.0583 0.0512 0.02"/>
            </geometry>
            <origin rpy="0.0 0.0 0.0" xyz="0.018000000000000016 0.0 -1.0408340855860843e-17"/>
        </collision>
        <collision name="garrix_v1_root_link1_link1_link1_link1_link3_geom1">
            <geometry>
                <box size="0.002 0.053 0.053"/>
            </geometry>
            <origin rpy="0.0 0.0 0.0" xyz="0.04815000000000001 0.0 -1.3877787807814457e-17"/>
        </collision>
    </link>
</robot>
