<?xml version="1.0" ?>
<robot name="park_v1">
    <link name="park_v1_root">
        <inertial>
            <origin rpy="0.0 0.0 0.0" xyz="-0.002254789272030651 2.7613204647441273e-19 -2.0292365314424896e-36"/>
            <mass value="2.610000e-01"/>
            <inertia ixx="2.413220e-04" ixy="-5.057991e-22" ixz="-6.333805e-38" iyy="2.737577e-04" iyz="-5.478451e-24" izz="3.630714e-04"/>
        </inertial>
        <collision name="park_v1_root_geom0">
            <geometry>
                <box size="0.089 0.089 0.0603"/>
            </geometry>
            <origin rpy="0.0 0.0 0.0" xyz="0.0 0.0 0.0"/>
        </collision>
        <collision name="park_v1_root_geom1">
            <geometry>
                <box size="0.018 0.053 0.0165891"/>
            </geometry>
            <origin rpy="1.5707963267948966 0.0 3.141592653589793" xyz="-0.0535 6.551860375438339e-18 -4.81482486096809e-35"/>
        </collision>
    </link>
    <joint type="revolute" name="park_v1_root_joint0">
        <parent link="park_v1_root"/>
        <child link="park_v1_root_link0"/>
        <origin rpy="1.5707963267948966 0.0 3.141592653589793" xyz="-0.07902499999999998 9.677771330261958e-18 -1.925929944387236e-34"/>
        <axis xyz="0 1 0"/>
        <limit lower="-1.047197551" upper="1.047197551" effort="0.948013269" velocity="6.338968228"/>
    </joint>
    <link name="park_v1_root_link0">
        <inertial>
            <origin rpy="3.749399456654644e-33 0.0 0.0" xyz="0.02973764044943822 -1.925929944387236e-34 -1.925929944387236e-33"/>
            <mass value="8.900000e-02"/>
            <inertia ixx="2.451623e-05" ixy="-5.057991e-22" ixz="0.000000e+00" iyy="4.952779e-05" iyz="0.000000e+00" izz="6.030948e-05"/>
        </inertial>
        <collision name="park_v1_root_link0_geom0">
            <geometry>
                <box size="0.0583 0.0512 0.02"/>
            </geometry>
            <origin rpy="3.749399456654644e-33 0.0 0.0" xyz="0.018000000000000016 9.62964972193618e-35 -2.311115933264683e-33"/>
        </collision>
        <collision name="park_v1_root_link0_geom1">
            <geometry>
                <box size="0.002 0.053 0.053"/>
            </geometry>
            <origin rpy="3.749399456654644e-33 0.0 0.0" xyz="0.04815000000000001 -5.7777898331617076e-34 -2.1185229388259594e-33"/>
        </collision>
        <collision name="park_v1_root_link0_geom2">
            <geometry>
                <box size="0.018 0.053 0.0165891"/>
            </geometry>
            <origin rpy="-1.5707963267948966 0.0 0.0" xyz="0.05815000000000002 0.0 -2.6963019221421302e-33"/>
        </collision>
    </link>
    <joint type="revolute" name="park_v1_root_link0_joint1">
        <parent link="park_v1_root_link0"/>
        <child link="park_v1_root_link0_link1"/>
        <origin rpy="-1.5707963267948966 0.0 0.0" xyz="0.08367500000000003 -3.851859888774472e-34 -4.237045877651919e-33"/>
        <axis xyz="0 1 0"/>
        <limit lower="-1.047197551" upper="1.047197551" effort="0.948013269" velocity="6.338968228"/>
    </joint>
    <link name="park_v1_root_link0_link1">
        <inertial>
            <origin rpy="0.0 0.0 0.0" xyz="0.08119427771226412 -0.006800533608490564 -3.851859888774472e-34"/>
            <mass value="2.120000e-01"/>
            <inertia ixx="2.504630e-04" ixy="-5.057991e-22" ixz="-5.057991e-22" iyy="6.635224e-04" iyz="1.218251e-21" izz="8.332229e-04"/>
        </inertial>
        <collision name="park_v1_root_link0_link1_geom0">
            <geometry>
                <box size="0.0583 0.0512 0.02"/>
            </geometry>
            <origin rpy="0.0 0.0 0.0" xyz="0.017999999999999988 -2.6963019221421302e-33 -3.851859888774472e-34"/>
        </collision>
        <collision name="park_v1_root_link0_link1_geom1">
            <geometry>
                <box size="0.002 0.053 0.053"/>
            </geometry>
            <origin rpy="0.0 0.0 0.0" xyz="0.048149999999999984 -3.0814879110195774e-33 -3.851859888774472e-34"/>
        </collision>
        <collision name="park_v1_root_link0_link1_geom2">
            <geometry>
                <box size="0.06288625 0.06288625 0.0603"/>
            </geometry>
            <origin rpy="0.0 0.0 0.0" xyz="0.08059312499999999 -3.0814879110195774e-33 -3.851859888774472e-34"/>
        </collision>
        <collision name="park_v1_root_link0_link1_geom3">
            <geometry>
                <box size="0.06288625 0.06288625 0.0603"/>
            </geometry>
            <origin rpy="0.0 0.0 0.0" xyz="0.143479375 -3.0814879110195774e-33 -3.851859888774472e-34"/>
        </collision>
        <collision name="park_v1_root_link0_link1_geom4">
            <geometry>
                <box size="0.018 0.053 0.0165891"/>
            </geometry>
            <origin rpy="0.0 0.0 1.5707963267948966" xyz="0.08059312499999999 0.040443125 -3.851859888774472e-34"/>
        </collision>
        <collision name="park_v1_root_link0_link1_geom5">
            <geometry>
                <box size="0.06288625 0.06288625 0.0603"/>
            </geometry>
            <origin rpy="0.0 0.0 -1.5707963267948966" xyz="0.08059312499999999 -0.06288625 -3.851859888774472e-34"/>
        </collision>
        <collision name="park_v1_root_link0_link1_geom6">
            <geometry>
                <box size="0.018 0.053 0.0165891"/>
            </geometry>
            <origin rpy="-1.5707963267948966 0.0 0.0" xyz="0.18392250000000002 0.0 -3.851859888774472e-34"/>
        </collision>
        <collision name="park_v1_root_link0_link1_geom7">
            <geometry>
                <box size="0.018 0.053 0.0165891"/>
            </geometry>
            <origin rpy="0.0 0.0 1.5707963267948966" xyz="0.143479375 0.040443125 -3.851859888774472e-34"/>
        </collision>
        <collision name="park_v1_root_link0_link1_geom8">
            <geometry>
                <box size="0.018 0.053 0.0165891"/>
            </geometry>
            <origin rpy="-1.5707963267948966 0.0 -1.5707963267948966" xyz="0.143479375 -0.040443125 -3.851859888774472e-34"/>
        </collision>
    </link>
    <joint type="revolute" name="park_v1_root_link0_link1_joint1">
        <parent link="park_v1_root_link0_link1"/>
        <child link="park_v1_root_link0_link1_link1"/>
        <origin rpy="0.0 0.0 1.5707963267948966" xyz="0.08059312499999999 0.06596812499999999 -3.851859888774472e-34"/>
        <axis xyz="0 1 0"/>
        <limit lower="-1.047197551" upper="1.047197551" effort="0.948013269" velocity="6.338968228"/>
    </joint>
    <link name="park_v1_root_link0_link1_link1">
        <inertial>
            <origin rpy="0.0 0.0 0.0" xyz="0.025730769230769234 5.204170427930421e-18 -0.0"/>
            <mass value="7.800000e-02"/>
            <inertia ixx="2.396696e-05" ixy="0.000000e+00" ixz="0.000000e+00" iyy="3.656843e-05" iyz="0.000000e+00" izz="4.730539e-05"/>
        </inertial>
        <collision name="park_v1_root_link0_link1_link1_geom0">
            <geometry>
                <box size="0.0583 0.0512 0.02"/>
            </geometry>
            <origin rpy="0.0 0.0 0.0" xyz="0.018000000000000002 1.734723475976807e-18 -0.0"/>
        </collision>
        <collision name="park_v1_root_link0_link1_link1_geom1">
            <geometry>
                <box size="0.002 0.053 0.053"/>
            </geometry>
            <origin rpy="0.0 0.0 0.0" xyz="0.04815 -6.938893903907228e-18 -0.0"/>
        </collision>
    </link>
    <joint type="revolute" name="park_v1_root_link0_link1_joint2">
        <parent link="park_v1_root_link0_link1"/>
        <child link="park_v1_root_link0_link1_link2"/>
        <origin rpy="-1.5707963267948966 0.0 0.0" xyz="0.2094475 -6.162975822039155e-33 -3.851859888774472e-34"/>
        <axis xyz="0 1 0"/>
        <limit lower="-1.047197551" upper="1.047197551" effort="0.948013269" velocity="6.338968228"/>
    </joint>
    <link name="park_v1_root_link0_link1_link2">
        <inertial>
            <origin rpy="-3.749399456654644e-33 0.0 0.0" xyz="0.025730769230769245 5.7777898331617076e-34 6.548161810916602e-33"/>
            <mass value="7.800000e-02"/>
            <inertia ixx="2.396696e-05" ixy="0.000000e+00" ixz="0.000000e+00" iyy="3.656843e-05" iyz="0.000000e+00" izz="4.730539e-05"/>
        </inertial>
        <collision name="park_v1_root_link0_link1_link2_geom0">
            <geometry>
                <box size="0.0583 0.0512 0.02"/>
            </geometry>
            <origin rpy="-3.749399456654644e-33 0.0 0.0" xyz="0.018000000000000016 1.925929944387236e-34 6.933347799794049e-33"/>
        </collision>
        <collision name="park_v1_root_link0_link1_link2_geom1">
            <geometry>
                <box size="0.002 0.053 0.053"/>
            </geometry>
            <origin rpy="-3.749399456654644e-33 0.0 0.0" xyz="0.04815000000000001 -1.925929944387236e-34 7.703719777548943e-33"/>
        </collision>
    </link>
    <joint type="revolute" name="park_v1_root_link0_link1_joint3">
        <parent link="park_v1_root_link0_link1"/>
        <child link="park_v1_root_link0_link1_link3"/>
        <origin rpy="0.0 0.0 1.5707963267948966" xyz="0.14347937500000002 0.06596812499999999 -3.851859888774472e-34"/>
        <axis xyz="0 1 0"/>
        <limit lower="-1.047197551" upper="1.047197551" effort="0.948013269" velocity="6.338968228"/>
    </joint>
    <link name="park_v1_root_link0_link1_link3">
        <inertial>
            <origin rpy="0.0 0.0 0.0" xyz="0.05662819140625 0.009010707031250006 -0.0"/>
            <mass value="1.600000e-01"/>
            <inertia ixx="1.889389e-04" ixy="1.393908e-37" ixz="-5.057991e-22" iyy="2.396117e-04" iyz="1.867864e-22" izz="3.762682e-04"/>
        </inertial>
        <collision name="park_v1_root_link0_link1_link3_geom0">
            <geometry>
                <box size="0.0583 0.0512 0.02"/>
            </geometry>
            <origin rpy="0.0 0.0 0.0" xyz="0.018000000000000002 1.734723475976807e-18 -0.0"/>
        </collision>
        <collision name="park_v1_root_link0_link1_link3_geom1">
            <geometry>
                <box size="0.002 0.053 0.053"/>
            </geometry>
            <origin rpy="0.0 0.0 0.0" xyz="0.04815 -6.938893903907228e-18 -0.0"/>
        </collision>
        <collision name="park_v1_root_link0_link1_link3_geom2">
            <geometry>
                <box size="0.06288625 0.06288625 0.0603"/>
            </geometry>
            <origin rpy="0.0 0.0 0.0" xyz="0.080593125 0.0 -0.0"/>
        </collision>
        <collision name="park_v1_root_link0_link1_link3_geom3">
            <geometry>
                <box size="0.018 0.053 0.0165891"/>
            </geometry>
            <origin rpy="0.0 0.0 0.0" xyz="0.12103625000000001 0.0 -0.0"/>
        </collision>
        <collision name="park_v1_root_link0_link1_link3_geom4">
            <geometry>
                <box size="0.06288625 0.06288625 0.0603"/>
            </geometry>
            <origin rpy="0.0 0.0 1.5707963267948966" xyz="0.08059312499999999 0.06288625000000002 -0.0"/>
        </collision>
        <collision name="park_v1_root_link0_link1_link3_geom5">
            <geometry>
                <box size="0.018 0.053 0.0165891"/>
            </geometry>
            <origin rpy="-1.5707963267948966 0.0 -1.5707963267948966" xyz="0.08059312499999999 -0.040443124999999996 -0.0"/>
        </collision>
    </link>
    <joint type="revolute" name="park_v1_root_link0_link1_link3_joint1">
        <parent link="park_v1_root_link0_link1_link3"/>
        <child link="park_v1_root_link0_link1_link3_link1"/>
        <origin rpy="0.0 0.0 0.0" xyz="0.14656124999999998 1.3877787807814457e-17 -0.0"/>
        <axis xyz="0 1 0"/>
        <limit lower="-1.047197551" upper="1.047197551" effort="0.948013269" velocity="6.338968228"/>
    </joint>
    <link name="park_v1_root_link0_link1_link3_link1">
        <inertial>
            <origin rpy="0.0 0.0 0.0" xyz="0.040970312500000015 6.938893903907228e-18 -0.0"/>
            <mass value="1.080000e-01"/>
            <inertia ixx="4.294389e-05" ixy="0.000000e+00" ixz="0.000000e+00" iyy="1.207594e-04" iyz="0.000000e+00" izz="1.322928e-04"/>
        </inertial>
        <collision name="park_v1_root_link0_link1_link3_link1_geom0">
            <geometry>
                <box size="0.0583 0.0512 0.02"/>
            </geometry>
            <origin rpy="0.0 0.0 0.0" xyz="0.018000000000000016 3.469446951953614e-18 -0.0"/>
        </collision>
        <collision name="park_v1_root_link0_link1_link3_link1_geom1">
            <geometry>
                <box size="0.002 0.053 0.053"/>
            </geometry>
            <origin rpy="0.0 0.0 0.0" xyz="0.04815000000000001 0.0 -0.0"/>
        </collision>
        <collision name="park_v1_root_link0_link1_link3_link1_geom2">
            <geometry>
                <box size="0.06288625 0.06288625 0.0603"/>
            </geometry>
            <origin rpy="0.0 0.0 0.0" xyz="0.08059312500000002 6.938893903907228e-18 -0.0"/>
        </collision>
    </link>
    <joint type="revolute" name="park_v1_root_link0_link1_link3_joint2">
        <parent link="park_v1_root_link0_link1_link3"/>
        <child link="park_v1_root_link0_link1_link3_link2"/>
        <origin rpy="-1.5707963267948963 0.0 -1.5707963267948966" xyz="0.08059312499999999 -0.06596812500000003 -0.0"/>
        <axis xyz="0 1 0"/>
        <limit lower="-1.047197551" upper="1.047197551" effort="0.948013269" velocity="6.338968228"/>
    </joint>
    <link name="park_v1_root_link0_link1_link3_link2">
        <inertial>
            <origin rpy="-2.465190328815662e-32 0.0 0.0" xyz="0.02573076923076919 3.851859888774472e-34 5.652332851261576e-18"/>
            <mass value="7.800000e-02"/>
            <inertia ixx="2.396696e-05" ixy="0.000000e+00" ixz="0.000000e+00" iyy="3.656843e-05" iyz="0.000000e+00" izz="4.730539e-05"/>
        </inertial>
        <collision name="park_v1_root_link0_link1_link3_link2_geom0">
            <geometry>
                <box size="0.0583 0.0512 0.02"/>
            </geometry>
            <origin rpy="-2.465190328815662e-32 0.0 0.0" xyz="0.01799999999999996 3.851859888774472e-34 5.652332851261578e-18"/>
        </collision>
        <collision name="park_v1_root_link0_link1_link3_link2_geom1">
            <geometry>
                <box size="0.002 0.053 0.053"/>
            </geometry>
            <origin rpy="-2.465190328815662e-32 0.0 0.0" xyz="0.048149999999999964 0.0 5.652332851261578e-18"/>
        </collision>
    </link>
    <joint type="revolute" name="park_v1_root_link0_link1_joint4">
        <parent link="park_v1_root_link0_link1"/>
        <child link="park_v1_root_link0_link1_link4"/>
        <origin rpy="-1.5707963267948963 0.0 -1.5707963267948966" xyz="0.14347937500000002 -0.06596812500000002 -3.851859888774472e-34"/>
        <axis xyz="0 1 0"/>
        <limit lower="-1.047197551" upper="1.047197551" effort="0.948013269" velocity="6.338968228"/>
    </joint>
    <link name="park_v1_root_link0_link1_link4">
        <inertial>
            <origin rpy="0.0 0.0 -1.1102230246251565e-16" xyz="0.025730769230769238 -1.734723475976807e-18 8.673617379884035e-18"/>
            <mass value="7.800000e-02"/>
            <inertia ixx="2.396696e-05" ixy="0.000000e+00" ixz="0.000000e+00" iyy="3.656843e-05" iyz="0.000000e+00" izz="4.730539e-05"/>
        </inertial>
        <collision name="park_v1_root_link0_link1_link4_geom0">
            <geometry>
                <box size="0.0583 0.0512 0.02"/>
            </geometry>
            <origin rpy="0.0 0.0 -1.1102230246251565e-16" xyz="0.018000000000000006 0.0 6.938893903907228e-18"/>
        </collision>
        <collision name="park_v1_root_link0_link1_link4_geom1">
            <geometry>
                <box size="0.002 0.053 0.053"/>
            </geometry>
            <origin rpy="0.0 0.0 -1.1102230246251565e-16" xyz="0.04815000000000001 -3.469446951953614e-18 1.3877787807814457e-17"/>
        </collision>
    </link>
</robot>
