<?xml version="1.0" ?>
<robot name="queen_v1">
    <link name="queen_v1_root">
        <inertial>
            <origin rpy="0.0 0.0 0.0" xyz="-0.0021636029411764707 -0.00216360294117647 -1.9471718187738595e-36"/>
            <mass value="2.720000e-01"/>
            <inertia ixx="2.720827e-04" ixy="-5.057991e-22" ixz="5.057991e-22" iyy="2.766833e-04" iyz="4.454703e-24" izz="3.961637e-04"/>
        </inertial>
        <collision name="queen_v1_root_geom0">
            <geometry>
                <box size="0.089 0.089 0.0603"/>
            </geometry>
            <origin rpy="0.0 0.0 0.0" xyz="0.0 0.0 0.0"/>
        </collision>
        <collision name="queen_v1_root_geom1">
            <geometry>
                <box size="0.018 0.053 0.0165891"/>
            </geometry>
            <origin rpy="1.5707963267948966 0.0 3.141592653589793" xyz="-0.0535 6.551860375438339e-18 -4.81482486096809e-35"/>
        </collision>
        <collision name="queen_v1_root_geom2">
            <geometry>
                <box size="0.018 0.053 0.0165891"/>
            </geometry>
            <origin rpy="1.5707963267948966 0.0 -1.5707963267948966" xyz="-1.214306433183765e-17 -0.0535 0.0"/>
        </collision>
    </link>
    <joint type="revolute" name="queen_v1_root_joint0">
        <parent link="queen_v1_root"/>
        <child link="queen_v1_root_link0"/>
        <origin rpy="1.5707963267948966 0.0 3.141592653589793" xyz="-0.07902499999999998 9.677771330261958e-18 -1.925929944387236e-34"/>
        <axis xyz="0 1 0"/>
        <limit lower="-1.047197551" upper="1.047197551" effort="0.948013269" velocity="6.338968228"/>
    </joint>
    <link name="queen_v1_root_link0">
        <inertial>
            <origin rpy="3.749399456654644e-33 0.0 0.0" xyz="0.025730769230769245 2.8888949165808538e-34 -2.0222264416065976e-33"/>
            <mass value="7.800000e-02"/>
            <inertia ixx="2.396696e-05" ixy="0.000000e+00" ixz="0.000000e+00" iyy="3.656843e-05" iyz="0.000000e+00" izz="4.730539e-05"/>
        </inertial>
        <collision name="queen_v1_root_link0_geom0">
            <geometry>
                <box size="0.0583 0.0512 0.02"/>
            </geometry>
            <origin rpy="3.749399456654644e-33 0.0 0.0" xyz="0.018000000000000016 9.62964972193618e-35 -2.311115933264683e-33"/>
        </collision>
        <collision name="queen_v1_root_link0_geom1">
            <geometry>
                <box size="0.002 0.053 0.053"/>
            </geometry>
            <origin rpy="3.749399456654644e-33 0.0 0.0" xyz="0.04815000000000001 -5.7777898331617076e-34 -2.1185229388259594e-33"/>
        </collision>
    </link>
    <joint type="revolute" name="queen_v1_root_joint1">
        <parent link="queen_v1_root"/>
        <child link="queen_v1_root_link1"/>
        <origin rpy="1.5707963267948966 0.0 -1.5707963267948966" xyz="-1.734723475976807e-17 -0.07902499999999998 0.0"/>
        <axis xyz="0 1 0"/>
        <limit lower="-1.047197551" upper="1.047197551" effort="0.948013269" velocity="6.338968228"/>
    </joint>
    <link name="queen_v1_root_link1">
        <inertial>
            <origin rpy="0.0 0.0 0.0" xyz="0.029737640449438205 0.0 0.0"/>
            <mass value="8.900000e-02"/>
            <inertia ixx="2.679414e-05" ixy="0.000000e+00" ixz="0.000000e+00" iyy="4.724987e-05" iyz="0.000000e+00" izz="6.030948e-05"/>
        </inertial>
        <collision name="queen_v1_root_link1_geom0">
            <geometry>
                <box size="0.0583 0.0512 0.02"/>
            </geometry>
            <origin rpy="0.0 0.0 0.0" xyz="0.018000000000000002 0.0 0.0"/>
        </collision>
        <collision name="queen_v1_root_link1_geom1">
            <geometry>
                <box size="0.002 0.053 0.053"/>
            </geometry>
            <origin rpy="0.0 0.0 0.0" xyz="0.04815 -1.734723475976807e-18 -1.734723475976807e-18"/>
        </collision>
        <collision name="queen_v1_root_link1_geom2">
            <geometry>
                <box size="0.018 0.053 0.0165891"/>
            </geometry>
            <origin rpy="0.0 0.0 0.0" xyz="0.05815 -1.734723475976807e-18 -5.204170427930421e-18"/>
        </collision>
    </link>
    <joint type="revolute" name="queen_v1_root_link1_joint1">
        <parent link="queen_v1_root_link1"/>
        <child link="queen_v1_root_link1_link1"/>
        <origin rpy="0.0 0.0 0.0" xyz="0.083675 0.0 0.0"/>
        <axis xyz="0 1 0"/>
        <limit lower="-1.047197551" upper="1.047197551" effort="0.948013269" velocity="6.338968228"/>
    </joint>
    <link name="queen_v1_root_link1_link1">
        <inertial>
            <origin rpy="0.0 0.0 0.0" xyz="0.02973764044943819 0.0 -3.469446951953614e-18"/>
            <mass value="8.900000e-02"/>
            <inertia ixx="2.451623e-05" ixy="-5.057991e-22" ixz="0.000000e+00" iyy="4.952779e-05" iyz="0.000000e+00" izz="6.030948e-05"/>
        </inertial>
        <collision name="queen_v1_root_link1_link1_geom0">
            <geometry>
                <box size="0.0583 0.0512 0.02"/>
            </geometry>
            <origin rpy="0.0 0.0 0.0" xyz="0.017999999999999988 0.0 -3.469446951953614e-18"/>
        </collision>
        <collision name="queen_v1_root_link1_link1_geom1">
            <geometry>
                <box size="0.002 0.053 0.053"/>
            </geometry>
            <origin rpy="0.0 0.0 0.0" xyz="0.048149999999999984 0.0 -6.938893903907228e-18"/>
        </collision>
        <collision name="queen_v1_root_link1_link1_geom2">
            <geometry>
                <box size="0.018 0.053 0.0165891"/>
            </geometry>
            <origin rpy="-1.5707963267948966 0.0 0.0" xyz="0.05814999999999998 0.0 -6.938893903907228e-18"/>
        </collision>
    </link>
    <joint type="revolute" name="queen_v1_root_link1_link1_joint1">
        <parent link="queen_v1_root_link1_link1"/>
        <child link="queen_v1_root_link1_link1_link1"/>
        <origin rpy="-1.5707963267948966 0.0 0.0" xyz="0.08367499999999997 0.0 0.0"/>
        <axis xyz="0 1 0"/>
        <limit lower="-1.047197551" upper="1.047197551" effort="0.948013269" velocity="6.338968228"/>
    </joint>
    <link name="queen_v1_root_link1_link1_link1">
        <inertial>
            <origin rpy="0.0 0.0 0.0" xyz="0.05041761105371901 -0.04363727014462809 -0.0"/>
            <mass value="2.420000e-01"/>
            <inertia ixx="7.694343e-04" ixy="-5.057991e-22" ixz="-2.246199e-37" iyy="4.073525e-04" iyz="-1.567063e-21" izz="1.080986e-03"/>
        </inertial>
        <collision name="queen_v1_root_link1_link1_link1_geom0">
            <geometry>
                <box size="0.0583 0.0512 0.02"/>
            </geometry>
            <origin rpy="0.0 0.0 0.0" xyz="0.018000000000000016 3.469446951953614e-18 -0.0"/>
        </collision>
        <collision name="queen_v1_root_link1_link1_link1_geom1">
            <geometry>
                <box size="0.002 0.053 0.053"/>
            </geometry>
            <origin rpy="0.0 0.0 0.0" xyz="0.04815000000000001 0.0 -0.0"/>
        </collision>
        <collision name="queen_v1_root_link1_link1_link1_geom2">
            <geometry>
                <box size="0.06288625 0.06288625 0.0603"/>
            </geometry>
            <origin rpy="0.0 0.0 0.0" xyz="0.08059312500000002 6.938893903907228e-18 -0.0"/>
        </collision>
        <collision name="queen_v1_root_link1_link1_link1_geom3">
            <geometry>
                <box size="0.018 0.053 0.0165891"/>
            </geometry>
            <origin rpy="0.0 0.0 1.5707963267948966" xyz="0.080593125 0.04044312500000001 -0.0"/>
        </collision>
        <collision name="queen_v1_root_link1_link1_link1_geom4">
            <geometry>
                <box size="0.06288625 0.06288625 0.0603"/>
            </geometry>
            <origin rpy="0.0 0.0 -1.5707963267948966" xyz="0.080593125 -0.06288625 -0.0"/>
        </collision>
        <collision name="queen_v1_root_link1_link1_link1_geom5">
            <geometry>
                <box size="0.06288625 0.06288625 0.0603"/>
            </geometry>
            <origin rpy="0.0 0.0 -1.5707963267948966" xyz="0.08059312500000002 -0.1257725 0.0"/>
        </collision>
        <collision name="queen_v1_root_link1_link1_link1_geom6">
            <geometry>
                <box size="0.06288625 0.06288625 0.0603"/>
            </geometry>
            <origin rpy="0.0 0.0 3.1415926535897927" xyz="0.017706875000000025 -0.06288624999999998 0.0"/>
        </collision>
        <collision name="queen_v1_root_link1_link1_link1_geom7">
            <geometry>
                <box size="0.018 0.053 0.0165891"/>
            </geometry>
            <origin rpy="0.0 0.0 0.0" xyz="0.12103625000000001 -0.12577250000000004 0.0"/>
        </collision>
        <collision name="queen_v1_root_link1_link1_link1_geom8">
            <geometry>
                <box size="0.018 0.053 0.0165891"/>
            </geometry>
            <origin rpy="0.0 0.0 3.1415926535897927" xyz="0.04015000000000002 -0.12577249999999998 0.0"/>
        </collision>
        <collision name="queen_v1_root_link1_link1_link1_geom9">
            <geometry>
                <box size="0.018 0.053 0.0165891"/>
            </geometry>
            <origin rpy="1.5707963267948963 0.0 -3.141592653589793" xyz="-0.022736249999999996 -0.06288624999999998 0.0"/>
        </collision>
    </link>
    <joint type="revolute" name="queen_v1_root_link1_link1_link1_joint1">
        <parent link="queen_v1_root_link1_link1_link1"/>
        <child link="queen_v1_root_link1_link1_link1_link1"/>
        <origin rpy="0.0 0.0 1.5707963267948966" xyz="0.08059312500000003 0.06596812499999999 -0.0"/>
        <axis xyz="0 1 0"/>
        <limit lower="-1.047197551" upper="1.047197551" effort="0.948013269" velocity="6.338968228"/>
    </joint>
    <link name="queen_v1_root_link1_link1_link1_link1">
        <inertial>
            <origin rpy="0.0 0.0 0.0" xyz="0.025730769230769248 6.350475700855895e-17 0.0"/>
            <mass value="7.800000e-02"/>
            <inertia ixx="2.396696e-05" ixy="0.000000e+00" ixz="0.000000e+00" iyy="3.656843e-05" iyz="0.000000e+00" izz="4.730539e-05"/>
        </inertial>
        <collision name="queen_v1_root_link1_link1_link1_link1_geom0">
            <geometry>
                <box size="0.0583 0.0512 0.02"/>
            </geometry>
            <origin rpy="0.0 0.0 0.0" xyz="0.018000000000000016 6.350475700855896e-17 0.0"/>
        </collision>
        <collision name="queen_v1_root_link1_link1_link1_link1_geom1">
            <geometry>
                <box size="0.002 0.053 0.053"/>
            </geometry>
            <origin rpy="0.0 0.0 0.0" xyz="0.04815000000000001 6.350475700855896e-17 0.0"/>
        </collision>
    </link>
    <joint type="revolute" name="queen_v1_root_link1_link1_link1_joint2">
        <parent link="queen_v1_root_link1_link1_link1"/>
        <child link="queen_v1_root_link1_link1_link1_link2"/>
        <origin rpy="0.0 0.0 0.0" xyz="0.14656125000000003 -0.12577250000000006 -0.0"/>
        <axis xyz="0 1 0"/>
        <limit lower="-1.047197551" upper="1.047197551" effort="0.948013269" velocity="6.338968228"/>
    </joint>
    <link name="queen_v1_root_link1_link1_link1_link2">
        <inertial>
            <origin rpy="0.0 0.0 0.0" xyz="0.025730769230769248 6.938893903907228e-18 0.0"/>
            <mass value="7.800000e-02"/>
            <inertia ixx="2.396696e-05" ixy="0.000000e+00" ixz="0.000000e+00" iyy="3.656843e-05" iyz="0.000000e+00" izz="4.730539e-05"/>
        </inertial>
        <collision name="queen_v1_root_link1_link1_link1_link2_geom0">
            <geometry>
                <box size="0.0583 0.0512 0.02"/>
            </geometry>
            <origin rpy="0.0 0.0 0.0" xyz="0.018000000000000016 6.938893903907228e-18 0.0"/>
        </collision>
        <collision name="queen_v1_root_link1_link1_link1_link2_geom1">
            <geometry>
                <box size="0.002 0.053 0.053"/>
            </geometry>
            <origin rpy="0.0 0.0 0.0" xyz="0.04815000000000001 1.3877787807814457e-17 0.0"/>
        </collision>
    </link>
    <joint type="revolute" name="queen_v1_root_link1_link1_link1_joint3">
        <parent link="queen_v1_root_link1_link1_link1"/>
        <child link="queen_v1_root_link1_link1_link1_link3"/>
        <origin rpy="0.0 0.0 3.1415926535897927" xyz="0.014625000000000006 -0.12577249999999995 0.0"/>
        <axis xyz="0 1 0"/>
        <limit lower="-1.047197551" upper="1.047197551" effort="0.948013269" velocity="6.338968228"/>
    </joint>
    <link name="queen_v1_root_link1_link1_link1_link3">
        <inertial>
            <origin rpy="0.0 0.0 0.0" xyz="0.02573076923076922 6.938893903907228e-18 0.0"/>
            <mass value="7.800000e-02"/>
            <inertia ixx="2.396696e-05" ixy="0.000000e+00" ixz="0.000000e+00" iyy="3.656843e-05" iyz="0.000000e+00" izz="4.730539e-05"/>
        </inertial>
        <collision name="queen_v1_root_link1_link1_link1_link3_geom0">
            <geometry>
                <box size="0.0583 0.0512 0.02"/>
            </geometry>
            <origin rpy="0.0 0.0 0.0" xyz="0.017999999999999988 8.673617379884035e-18 0.0"/>
        </collision>
        <collision name="queen_v1_root_link1_link1_link1_link3_geom1">
            <geometry>
                <box size="0.002 0.053 0.053"/>
            </geometry>
            <origin rpy="0.0 0.0 0.0" xyz="0.048149999999999984 1.734723475976807e-17 0.0"/>
        </collision>
    </link>
    <joint type="revolute" name="queen_v1_root_link1_link1_link1_joint4">
        <parent link="queen_v1_root_link1_link1_link1"/>
        <child link="queen_v1_root_link1_link1_link1_link4"/>
        <origin rpy="1.5707963267948966 0.0 3.1415926535897922" xyz="-0.048261249999999985 -0.06288624999999992 0.0"/>
        <axis xyz="0 1 0"/>
        <limit lower="-1.047197551" upper="1.047197551" effort="0.948013269" velocity="6.338968228"/>
    </joint>
    <link name="queen_v1_root_link1_link1_link1_link4">
        <inertial>
            <origin rpy="0.0 0.0 0.0" xyz="0.02973764044943819 0.0 -1.214306433183765e-17"/>
            <mass value="8.900000e-02"/>
            <inertia ixx="2.679414e-05" ixy="0.000000e+00" ixz="0.000000e+00" iyy="4.724987e-05" iyz="0.000000e+00" izz="6.030948e-05"/>
        </inertial>
        <collision name="queen_v1_root_link1_link1_link1_link4_geom0">
            <geometry>
                <box size="0.0583 0.0512 0.02"/>
            </geometry>
            <origin rpy="0.0 0.0 0.0" xyz="0.017999999999999988 0.0 -1.0408340855860843e-17"/>
        </collision>
        <collision name="queen_v1_root_link1_link1_link1_link4_geom1">
            <geometry>
                <box size="0.002 0.053 0.053"/>
            </geometry>
            <origin rpy="0.0 0.0 0.0" xyz="0.048149999999999984 0.0 -1.3877787807814457e-17"/>
        </collision>
        <collision name="queen_v1_root_link1_link1_link1_link4_geom2">
            <geometry>
                <box size="0.018 0.053 0.0165891"/>
            </geometry>
            <origin rpy="0.0 0.0 0.0" xyz="0.058149999999999986 0.0 -1.3877787807814457e-17"/>
        </collision>
    </link>
    <joint type="revolute" name="queen_v1_root_link1_link1_link1_link4_joint1">
        <parent link="queen_v1_root_link1_link1_link1_link4"/>
        <child link="queen_v1_root_link1_link1_link1_link4_link1"/>
        <origin rpy="0.0 0.0 0.0" xyz="0.08367499999999999 0.0 -1.3877787807814457e-17"/>
        <axis xyz="0 1 0"/>
        <limit lower="-1.047197551" upper="1.047197551" effort="0.948013269" velocity="6.338968228"/>
    </joint>
    <link name="queen_v1_root_link1_link1_link1_link4_link1">
        <inertial>
            <origin rpy="0.0 0.0 0.0" xyz="0.025730769230769238 0.0 1.734723475976807e-18"/>
            <mass value="7.800000e-02"/>
            <inertia ixx="2.396696e-05" ixy="0.000000e+00" ixz="0.000000e+00" iyy="3.656843e-05" iyz="0.000000e+00" izz="4.730539e-05"/>
        </inertial>
        <collision name="queen_v1_root_link1_link1_link1_link4_link1_geom0">
            <geometry>
                <box size="0.0583 0.0512 0.02"/>
            </geometry>
            <origin rpy="0.0 0.0 0.0" xyz="0.018000000000000002 0.0 3.469446951953614e-18"/>
        </collision>
        <collision name="queen_v1_root_link1_link1_link1_link4_link1_geom1">
            <geometry>
                <box size="0.002 0.053 0.053"/>
            </geometry>
            <origin rpy="0.0 0.0 0.0" xyz="0.04815 0.0 0.0"/>
        </collision>
    </link>
</robot>
