<?xml version="1.0" ?>
<robot name="snake_v1">
    <link name="snake_v1_root">
        <inertial>
            <origin rpy="0.0 0.0 0.0" xyz="5.117766576636557e-19 0.002254789272030651 0.0"/>
            <mass value="2.610000e-01"/>
            <inertia ixx="2.737577e-04" ixy="0.000000e+00" ixz="0.000000e+00" iyy="2.436446e-04" iyz="5.157323e-22" izz="3.607487e-04"/>
        </inertial>
        <collision name="snake_v1_root_geom0">
            <geometry>
                <box size="0.089 0.089 0.0603"/>
            </geometry>
            <origin rpy="0.0 0.0 0.0" xyz="0.0 0.0 0.0"/>
        </collision>
        <collision name="snake_v1_root_geom1">
            <geometry>
                <box size="0.018 0.053 0.0165891"/>
            </geometry>
            <origin rpy="0.0 0.0 1.5707963267948966" xyz="1.214306433183765e-17 0.0535 0.0"/>
        </collision>
    </link>
    <joint type="revolute" name="snake_v1_root_joint0">
        <parent link="snake_v1_root"/>
        <child link="snake_v1_root_link0"/>
        <origin rpy="0.0 0.0 1.5707963267948966" xyz="1.8214596497756474e-17 0.07902499999999998 0.0"/>
        <axis xyz="0 1 0"/>
        <limit lower="-1.047197551" upper="1.047197551" effort="0.948013269" velocity="6.338968228"/>
    </joint>
    <link name="snake_v1_root_link0">
        <inertial>
            <origin rpy="0.0 0.0 0.0" xyz="0.0483713655462185 0.0 0.0"/>
            <mass value="1.190000e-01"/>
            <inertia ixx="4.349315e-05" ixy="5.057991e-22" ixz="0.000000e+00" iyy="1.875844e-04" iyz="0.000000e+00" izz="1.991625e-04"/>
        </inertial>
        <collision name="snake_v1_root_link0_geom0">
            <geometry>
                <box size="0.0583 0.0512 0.02"/>
            </geometry>
            <origin rpy="0.0 0.0 0.0" xyz="0.018000000000000016 0.0 0.0"/>
        </collision>
        <collision name="snake_v1_root_link0_geom1">
            <geometry>
                <box size="0.002 0.053 0.053"/>
            </geometry>
            <origin rpy="0.0 0.0 0.0" xyz="0.04815000000000001 0.0 0.0"/>
        </collision>
        <collision name="snake_v1_root_link0_geom2">
            <geometry>
                <box size="0.06288625 0.06288625 0.0603"/>
            </geometry>
            <origin rpy="0.0 0.0 0.0" xyz="0.08059312500000002 6.938893903907228e-18 0.0"/>
        </collision>
        <collision name="snake_v1_root_link0_geom3">
            <geometry>
                <box size="0.018 0.053 0.0165891"/>
            </geometry>
            <origin rpy="1.5707963267948966 0.0 0.0" xyz="0.12103625000000001 0.0 0.0"/>
        </collision>
    </link>
    <joint type="revolute" name="snake_v1_root_link0_joint1">
        <parent link="snake_v1_root_link0"/>
        <child link="snake_v1_root_link0_link1"/>
        <origin rpy="1.5707963267948966 0.0 0.0" xyz="0.14656125000000003 -2.7755575615628914e-17 0.0"/>
        <axis xyz="0 1 0"/>
        <limit lower="-1.047197551" upper="1.047197551" effort="0.948013269" velocity="6.338968228"/>
    </joint>
    <link name="snake_v1_root_link0_link1">
        <inertial>
            <origin rpy="0.0 0.0 0.0" xyz="0.0483713655462185 0.0 -6.938893903907228e-18"/>
            <mass value="1.190000e-01"/>
            <inertia ixx="4.349315e-05" ixy="-5.057991e-22" ixz="0.000000e+00" iyy="1.875844e-04" iyz="0.000000e+00" izz="1.991625e-04"/>
        </inertial>
        <collision name="snake_v1_root_link0_link1_geom0">
            <geometry>
                <box size="0.0583 0.0512 0.02"/>
            </geometry>
            <origin rpy="0.0 0.0 0.0" xyz="0.018000000000000016 0.0 -3.469446951953614e-18"/>
        </collision>
        <collision name="snake_v1_root_link0_link1_geom1">
            <geometry>
                <box size="0.002 0.053 0.053"/>
            </geometry>
            <origin rpy="0.0 0.0 0.0" xyz="0.04815000000000001 0.0 -6.938893903907228e-18"/>
        </collision>
        <collision name="snake_v1_root_link0_link1_geom2">
            <geometry>
                <box size="0.06288625 0.06288625 0.0603"/>
            </geometry>
            <origin rpy="-1.5707963267948966 0.0 0.0" xyz="0.08059312500000002 0.0 0.0"/>
        </collision>
        <collision name="snake_v1_root_link0_link1_geom3">
            <geometry>
                <box size="0.018 0.053 0.0165891"/>
            </geometry>
            <origin rpy="-1.5707963267948966 0.0 0.0" xyz="0.12103625000000001 0.0 0.0"/>
        </collision>
    </link>
    <joint type="revolute" name="snake_v1_root_link0_link1_joint1">
        <parent link="snake_v1_root_link0_link1"/>
        <child link="snake_v1_root_link0_link1_link1"/>
        <origin rpy="-1.5707963267948966 0.0 0.0" xyz="0.14656124999999998 0.0 0.0"/>
        <axis xyz="0 1 0"/>
        <limit lower="-1.047197551" upper="1.047197551" effort="0.948013269" velocity="6.338968228"/>
    </joint>
    <link name="snake_v1_root_link0_link1_link1">
        <inertial>
            <origin rpy="0.0 0.0 0.0" xyz="0.0483713655462185 0.0 0.0"/>
            <mass value="1.190000e-01"/>
            <inertia ixx="4.349315e-05" ixy="5.057991e-22" ixz="0.000000e+00" iyy="1.875844e-04" iyz="0.000000e+00" izz="1.991625e-04"/>
        </inertial>
        <collision name="snake_v1_root_link0_link1_link1_geom0">
            <geometry>
                <box size="0.0583 0.0512 0.02"/>
            </geometry>
            <origin rpy="0.0 0.0 0.0" xyz="0.018000000000000016 3.469446951953614e-18 0.0"/>
        </collision>
        <collision name="snake_v1_root_link0_link1_link1_geom1">
            <geometry>
                <box size="0.002 0.053 0.053"/>
            </geometry>
            <origin rpy="0.0 0.0 0.0" xyz="0.04815000000000001 0.0 0.0"/>
        </collision>
        <collision name="snake_v1_root_link0_link1_link1_geom2">
            <geometry>
                <box size="0.06288625 0.06288625 0.0603"/>
            </geometry>
            <origin rpy="0.0 0.0 0.0" xyz="0.08059312500000002 6.938893903907228e-18 0.0"/>
        </collision>
        <collision name="snake_v1_root_link0_link1_link1_geom3">
            <geometry>
                <box size="0.018 0.053 0.0165891"/>
            </geometry>
            <origin rpy="1.5707963267948966 0.0 0.0" xyz="0.12103625000000001 0.0 0.0"/>
        </collision>
    </link>
    <joint type="revolute" name="snake_v1_root_link0_link1_link1_joint1">
        <parent link="snake_v1_root_link0_link1_link1"/>
        <child link="snake_v1_root_link0_link1_link1_link1"/>
        <origin rpy="1.5707963267948966 0.0 0.0" xyz="0.14656124999999998 0.0 0.0"/>
        <axis xyz="0 1 0"/>
        <limit lower="-1.047197551" upper="1.047197551" effort="0.948013269" velocity="6.338968228"/>
    </joint>
    <link name="snake_v1_root_link0_link1_link1_link1">
        <inertial>
            <origin rpy="0.0 0.0 0.0" xyz="0.0483713655462185 0.0 -6.938893903907228e-18"/>
            <mass value="1.190000e-01"/>
            <inertia ixx="4.349315e-05" ixy="-5.057991e-22" ixz="0.000000e+00" iyy="1.875844e-04" iyz="0.000000e+00" izz="1.991625e-04"/>
        </inertial>
        <collision name="snake_v1_root_link0_link1_link1_link1_geom0">
            <geometry>
                <box size="0.0583 0.0512 0.02"/>
            </geometry>
            <origin rpy="0.0 0.0 0.0" xyz="0.018000000000000016 0.0 -3.469446951953614e-18"/>
        </collision>
        <collision name="snake_v1_root_link0_link1_link1_link1_geom1">
            <geometry>
                <box size="0.002 0.053 0.053"/>
            </geometry>
            <origin rpy="0.0 0.0 0.0" xyz="0.04815000000000001 0.0 -6.938893903907228e-18"/>
        </collision>
        <collision name="snake_v1_root_link0_link1_link1_link1_geom2">
            <geometry>
                <box size="0.06288625 0.06288625 0.0603"/>
            </geometry>
            <origin rpy="-1.5707963267948966 0.0 0.0" xyz="0.08059312500000002 0.0 0.0"/>
        </collision>
        <collision name="snake_v1_root_link0_link1_link1_link1_geom3">
            <geometry>
                <box size="0.018 0.053 0.0165891"/>
            </geometry>
            <origin rpy="-1.5707963267948966 0.0 0.0" xyz="0.12103625000000001 0.0 0.0"/>
        </collision>
    </link>
    <joint type="revolute" name="snake_v1_root_link0_link1_link1_link1_joint1">
        <parent link="snake_v1_root_link0_link1_link1_link1"/>
        <child link="snake_v1_root_link0_link1_link1_link1_link1"/>
        <origin rpy="-1.5707963267948966 0.0 0.0" xyz="0.14656124999999998 0.0 0.0"/>
        <axis xyz="0 1 0"/>
        <limit lower="-1.047197551" upper="1.047197551" effort="0.948013269" velocity="6.338968228"/>
    </joint>
    <link name="snake_v1_root_link0_link1_link1_link1_link1">
        <inertial>
            <origin rpy="0.0 0.0 0.0" xyz="0.0483713655462185 0.0 0.0"/>
            <mass value="1.190000e-01"/>
            <inertia ixx="4.349315e-05" ixy="5.057991e-22" ixz="0.000000e+00" iyy="1.875844e-04" iyz="0.000000e+00" izz="1.991625e-04"/>
        </inertial>
        <collision name="snake_v1_root_link0_link1_link1_link1_link1_geom0">
            <geometry>
                <box size="0.0583 0.0512 0.02"/>
            </geometry>
            <origin rpy="0.0 0.0 0.0" xyz="0.018000000000000016 3.469446951953614e-18 0.0"/>
        </collision>
        <collision name="snake_v1_root_link0_link1_link1_link1_link1_geom1">
            <geometry>
                <box size="0.002 0.053 0.053"/>
            </geometry>
            <origin rpy="0.0 0.0 0.0" xyz="0.04815000000000001 0.0 0.0"/>
        </collision>
        <collision name="snake_v1_root_link0_link1_link1_link1_link1_geom2">
            <geometry>
                <box size="0.06288625 0.06288625 0.0603"/>
            </geometry>
            <origin rpy="0.0 0.0 0.0" xyz="0.08059312500000002 6.938893903907228e-18 0.0"/>
        </collision>
        <collision name="snake_v1_root_link0_link1_link1_link1_link1_geom3">
            <geometry>
                <box size="0.018 0.053 0.0165891"/>
            </geometry>
            <origin rpy="1.5707963267948966 0.0 0.0" xyz="0.12103625000000001 0.0 0.0"/>
        </collision>
    </link>
    <joint type="revolute" name="snake_v1_root_link0_link1_link1_link1_link1_joint1">
        <parent link="snake_v1_root_link0_link1_link1_link1_link1"/>
        <child link="snake_v1_root_link0_link1_link1_link1_link1_link1"/>
        <origin rpy="1.5707963267948966 0.0 0.0" xyz="0.14656124999999998 0.0 0.0"/>
        <axis xyz="0 1 0"/>
        <limit lower="-1.047197551" upper="1.047197551" effort="0.948013269" velocity="6.338968228"/>
    </joint>
    <link name="snake_v1_root_link0_link1_link1_link1_link1_link1">
        <inertial>
            <origin rpy="0.0 0.0 0.0" xyz="0.0483713655462185 0.0 -6.938893903907228e-18"/>
            <mass value="1.190000e-01"/>
            <inertia ixx="4.349315e-05" ixy="-5.057991e-22" ixz="0.000000e+00" iyy="1.875844e-04" iyz="0.000000e+00" izz="1.991625e-04"/>
        </inertial>
        <collision name="snake_v1_root_link0_link1_link1_link1_link1_link1_geom0">
            <geometry>
                <box size="0.0583 0.0512 0.02"/>
            </geometry>
            <origin rpy="0.0 0.0 0.0" xyz="0.018000000000000016 0.0 -3.469446951953614e-18"/>
        </collision>
        <collision name="snake_v1_root_link0_link1_link1_link1_link1_link1_geom1">
            <geometry>
                <box size="0.002 0.053 0.053"/>
            </geometry>
            <origin rpy="0.0 0.0 0.0" xyz="0.04815000000000001 0.0 -6.938893903907228e-18"/>
        </collision>
        <collision name="snake_v1_root_link0_link1_link1_link1_link1_link1_geom2">
            <geometry>
                <box size="0.06288625 0.06288625 0.0603"/>
            </geometry>
            <origin rpy="-1.5707963267948966 0.0 0.0" xyz="0.08059312500000002 0.0 0.0"/>
        </collision>
        <collision name="snake_v1_root_link0_link1_link1_link1_link1_link1_geom3">
            <geometry>
                <box size="0.018 0.053 0.0165891"/>
            </geometry>
            <origin rpy="-1.5707963267948966 0.0 0.0" xyz="0.12103625000000001 0.0 0.0"/>
        </collision>
    </link>
    <joint type="revolute" name="snake_v1_root_link0_link1_link1_link1_link1_link1_joint1">
        <parent link="snake_v1_root_link0_link1_link1_link1_link1_link1"/>
        <child link="snake_v1_root_link0_link1_link1_link1_link1_link1_link1"/>
        <origin rpy="-1.5707963267948966 0.0 0.0" xyz="0.14656124999999998 0.0 0.0"/>
        <axis xyz="0 1 0"/>
        <limit lower="-1.047197551" upper="1.047197551" effort="0.948013269" velocity="6.338968228"/>
    </joint>
    <link name="snake_v1_root_link0_link1_link1_link1_link1_link1_link1">
        <inertial>
            <origin rpy="0.0 0.0 0.0" xyz="0.0483713655462185 0.0 0.0"/>
            <mass value="1.190000e-01"/>
            <inertia ixx="4.349315e-05" ixy="5.057991e-22" ixz="0.000000e+00" iyy="1.875844e-04" iyz="0.000000e+00" izz="1.991625e-04"/>
        </inertial>
        <collision name="snake_v1_root_link0_link1_link1_link1_link1_link1_link1_geom0">
            <geometry>
                <box size="0.0583 0.0512 0.02"/>
            </geometry>
            <origin rpy="0.0 0.0 0.0" xyz="0.018000000000000016 3.469446951953614e-18 0.0"/>
        </collision>
        <collision name="snake_v1_root_link0_link1_link1_link1_link1_link1_link1_geom1">
            <geometry>
                <box size="0.002 0.053 0.053"/>
            </geometry>
            <origin rpy="0.0 0.0 0.0" xyz="0.04815000000000001 0.0 0.0"/>
        </collision>
        <collision name="snake_v1_root_link0_link1_link1_link1_link1_link1_link1_geom2">
            <geometry>
                <box size="0.06288625 0.06288625 0.0603"/>
            </geometry>
            <origin rpy="0.0 0.0 0.0" xyz="0.08059312500000002 6.938893903907228e-18 0.0"/>
        </collision>
        <collision name="snake_v1_root_link0_link1_link1_link1_link1_link1_link1_geom3">
            <geometry>
                <box size="0.018 0.053 0.0165891"/>
            </geometry>
            <origin rpy="1.5707963267948966 0.0 0.0" xyz="0.12103625000000001 0.0 0.0"/>
        </collision>
    </link>
    <joint type="revolute" name="snake_v1_root_link0_link1_link1_link1_link1_link1_link1_joint1">
        <parent link="snake_v1_root_link0_link1_link1_link1_link1_link1_link1"/>
        <child link="snake_v1_root_link0_link1_link1_link1_link1_link1_link1_link1"/>
        <origin rpy="1.5707963267948966 0.0 0.0" xyz="0.1465612500000001 0.0 0.0"/>
        <axis xyz="0 1 0"/>
        <limit lower="-1.047197551" upper="1.047197551" effort="0.948013269" velocity="6.338968228"/>
    </joint>
    <link name="snake_v1_root_link0_link1_link1_link1_link1_link1_link1_link1">
        <inertial>
            <origin rpy="0.0 0.0 0.0" xyz="0.02573076923076925 -8.673617379884035e-19 -4.336808689942018e-18"/>
            <mass value="7.800000e-02"/>
            <inertia ixx="2.396696e-05" ixy="0.000000e+00" ixz="0.000000e+00" iyy="3.656843e-05" iyz="0.000000e+00" izz="4.730539e-05"/>
        </inertial>
        <collision name="snake_v1_root_link0_link1_link1_link1_link1_link1_link1_link1_geom0">
            <geometry>
                <box size="0.0583 0.0512 0.02"/>
            </geometry>
            <origin rpy="0.0 0.0 0.0" xyz="0.018000000000000016 0.0 -3.469446951953614e-18"/>
        </collision>
        <collision name="snake_v1_root_link0_link1_link1_link1_link1_link1_link1_link1_geom1">
            <geometry>
                <box size="0.002 0.053 0.053"/>
            </geometry>
            <origin rpy="0.0 0.0 0.0" xyz="0.04815000000000001 0.0 -6.938893903907228e-18"/>
        </collision>
    </link>
</robot>
