<?xml version="1.0" ?>
<robot name="turtle_v1">
    <link name="turtle_v1_root">
        <inertial>
            <origin rpy="0.0 0.0 0.0" xyz="2.8720587350609385e-18 0.01307629966887417 0.0"/>
            <mass value="3.020000e-01"/>
            <inertia ixx="5.113898e-04" ixy="-5.057991e-22" ixz="-2.246199e-37" iyy="2.999068e-04" iyz="-8.744776e-22" izz="6.390104e-04"/>
        </inertial>
        <collision name="turtle_v1_root_geom0">
            <geometry>
                <box size="0.089 0.089 0.0603"/>
            </geometry>
            <origin rpy="0.0 0.0 0.0" xyz="0.0 0.0 0.0"/>
        </collision>
        <collision name="turtle_v1_root_geom1">
            <geometry>
                <box size="0.06288625 0.06288625 0.0603"/>
            </geometry>
            <origin rpy="0.0 0.0 1.5707963267948966" xyz="1.734723475976807e-17 0.075943125 0.0"/>
        </collision>
        <collision name="turtle_v1_root_geom2">
            <geometry>
                <box size="0.018 0.053 0.0165891"/>
            </geometry>
            <origin rpy="1.5707963267948966 0.0 3.141592653589793" xyz="-0.04044312499999999 0.07594312500000001 0.0"/>
        </collision>
        <collision name="turtle_v1_root_geom3">
            <geometry>
                <box size="0.018 0.053 0.0165891"/>
            </geometry>
            <origin rpy="0.0 0.0 0.0" xyz="0.04044312500000002 0.07594312499999999 0.0"/>
        </collision>
    </link>
    <joint type="revolute" name="turtle_v1_root_joint0">
        <parent link="turtle_v1_root"/>
        <child link="turtle_v1_root_link0"/>
        <origin rpy="1.5707963267948966 0.0 3.141592653589793" xyz="-0.06596812499999999 0.07594312500000003 0.0"/>
        <axis xyz="0 1 0"/>
        <limit lower="-1.047197551" upper="1.047197551" effort="0.948013269" velocity="6.338968228"/>
    </joint>
    <link name="turtle_v1_root_link0">
        <inertial>
            <origin rpy="4.930380657631324e-32 0.0 0.0" xyz="0.029737640449438205 -2.6963019221421302e-33 5.88418203051333e-18"/>
            <mass value="8.900000e-02"/>
            <inertia ixx="2.451623e-05" ixy="-5.057991e-22" ixz="0.000000e+00" iyy="4.952779e-05" iyz="0.000000e+00" izz="6.030948e-05"/>
        </inertial>
        <collision name="turtle_v1_root_link0_geom0">
            <geometry>
                <box size="0.0583 0.0512 0.02"/>
            </geometry>
            <origin rpy="4.930380657631324e-32 0.0 0.0" xyz="0.018000000000000002 -3.851859888774472e-34 5.88418203051333e-18"/>
        </collision>
        <collision name="turtle_v1_root_link0_geom1">
            <geometry>
                <box size="0.002 0.053 0.053"/>
            </geometry>
            <origin rpy="4.930380657631324e-32 0.0 0.0" xyz="0.04815 -7.703719777548943e-34 5.884182030513332e-18"/>
        </collision>
        <collision name="turtle_v1_root_link0_geom2">
            <geometry>
                <box size="0.018 0.053 0.0165891"/>
            </geometry>
            <origin rpy="-1.5707963267948966 0.0 0.0" xyz="0.05814999999999999 7.703719777548943e-34 5.884182030513327e-18"/>
        </collision>
    </link>
    <joint type="revolute" name="turtle_v1_root_link0_joint1">
        <parent link="turtle_v1_root_link0"/>
        <child link="turtle_v1_root_link0_link1"/>
        <origin rpy="-1.5707963267948966 0.0 0.0" xyz="0.083675 -3.0814879110195774e-33 4.474198789239381e-18"/>
        <axis xyz="0 1 0"/>
        <limit lower="-1.047197551" upper="1.047197551" effort="0.948013269" velocity="6.338968228"/>
    </joint>
    <link name="turtle_v1_root_link0_link1">
        <inertial>
            <origin rpy="0.0 0.0 0.0" xyz="0.06563889843750001 -5.8841820305133226e-18 0.0"/>
            <mass value="1.600000e-01"/>
            <inertia ixx="1.012815e-04" ixy="1.393908e-37" ixz="-5.057991e-22" iyy="3.978964e-04" iyz="5.256654e-22" izz="4.438431e-04"/>
        </inertial>
        <collision name="turtle_v1_root_link0_link1_geom0">
            <geometry>
                <box size="0.0583 0.0512 0.02"/>
            </geometry>
            <origin rpy="0.0 0.0 0.0" xyz="0.018000000000000016 -5.8841820305133226e-18 0.0"/>
        </collision>
        <collision name="turtle_v1_root_link0_link1_geom1">
            <geometry>
                <box size="0.002 0.053 0.053"/>
            </geometry>
            <origin rpy="0.0 0.0 0.0" xyz="0.04815000000000001 -5.8841820305133226e-18 0.0"/>
        </collision>
        <collision name="turtle_v1_root_link0_link1_geom2">
            <geometry>
                <box size="0.06288625 0.06288625 0.0603"/>
            </geometry>
            <origin rpy="0.0 0.0 0.0" xyz="0.08059312500000002 -5.8841820305133226e-18 0.0"/>
        </collision>
        <collision name="turtle_v1_root_link0_link1_geom3">
            <geometry>
                <box size="0.06288625 0.06288625 0.0603"/>
            </geometry>
            <origin rpy="0.0 0.0 0.0" xyz="0.14347937500000002 -5.8841820305133226e-18 0.0"/>
        </collision>
        <collision name="turtle_v1_root_link0_link1_geom4">
            <geometry>
                <box size="0.018 0.053 0.0165891"/>
            </geometry>
            <origin rpy="1.5707963267948963 0.0 1.5707963267948963" xyz="0.08059312500000002 0.040443125 0.0"/>
        </collision>
        <collision name="turtle_v1_root_link0_link1_geom5">
            <geometry>
                <box size="0.018 0.053 0.0165891"/>
            </geometry>
            <origin rpy="0.0 0.0 -1.5707963267948966" xyz="0.08059312500000002 -0.040443125 0.0"/>
        </collision>
    </link>
    <joint type="revolute" name="turtle_v1_root_link0_link1_joint1">
        <parent link="turtle_v1_root_link0_link1"/>
        <child link="turtle_v1_root_link0_link1_link1"/>
        <origin rpy="1.5707963267948963 0.0 1.5707963267948963" xyz="0.08059312500000002 0.06596812499999999 0.0"/>
        <axis xyz="0 1 0"/>
        <limit lower="-1.047197551" upper="1.047197551" effort="0.948013269" velocity="6.338968228"/>
    </joint>
    <link name="turtle_v1_root_link0_link1_link1">
        <inertial>
            <origin rpy="0.0 0.0 0.0" xyz="0.025730769230769234 0.0 -1.214306433183765e-17"/>
            <mass value="7.800000e-02"/>
            <inertia ixx="2.396696e-05" ixy="0.000000e+00" ixz="0.000000e+00" iyy="3.656843e-05" iyz="0.000000e+00" izz="4.730539e-05"/>
        </inertial>
        <collision name="turtle_v1_root_link0_link1_link1_geom0">
            <geometry>
                <box size="0.0583 0.0512 0.02"/>
            </geometry>
            <origin rpy="0.0 0.0 0.0" xyz="0.018000000000000002 0.0 -1.0408340855860843e-17"/>
        </collision>
        <collision name="turtle_v1_root_link0_link1_link1_geom1">
            <geometry>
                <box size="0.002 0.053 0.053"/>
            </geometry>
            <origin rpy="0.0 0.0 0.0" xyz="0.04815 0.0 -1.3877787807814457e-17"/>
        </collision>
    </link>
    <joint type="revolute" name="turtle_v1_root_link0_link1_joint2">
        <parent link="turtle_v1_root_link0_link1"/>
        <child link="turtle_v1_root_link0_link1_link2"/>
        <origin rpy="0.0 0.0 -1.5707963267948966" xyz="0.08059312500000002 -0.065968125 0.0"/>
        <axis xyz="0 1 0"/>
        <limit lower="-1.047197551" upper="1.047197551" effort="0.948013269" velocity="6.338968228"/>
    </joint>
    <link name="turtle_v1_root_link0_link1_link2">
        <inertial>
            <origin rpy="0.0 0.0 0.0" xyz="0.06563889843750001 1.3877787807814457e-17 0.0"/>
            <mass value="1.600000e-01"/>
            <inertia ixx="1.012815e-04" ixy="1.393908e-37" ixz="-5.057991e-22" iyy="3.978964e-04" iyz="5.256654e-22" izz="4.438431e-04"/>
        </inertial>
        <collision name="turtle_v1_root_link0_link1_link2_geom0">
            <geometry>
                <box size="0.0583 0.0512 0.02"/>
            </geometry>
            <origin rpy="0.0 0.0 0.0" xyz="0.018000000000000016 6.938893903907228e-18 0.0"/>
        </collision>
        <collision name="turtle_v1_root_link0_link1_link2_geom1">
            <geometry>
                <box size="0.002 0.053 0.053"/>
            </geometry>
            <origin rpy="0.0 0.0 0.0" xyz="0.04815000000000001 1.3877787807814457e-17 0.0"/>
        </collision>
        <collision name="turtle_v1_root_link0_link1_link2_geom2">
            <geometry>
                <box size="0.06288625 0.06288625 0.0603"/>
            </geometry>
            <origin rpy="0.0 0.0 0.0" xyz="0.08059312500000002 1.3877787807814457e-17 0.0"/>
        </collision>
        <collision name="turtle_v1_root_link0_link1_link2_geom3">
            <geometry>
                <box size="0.06288625 0.06288625 0.0603"/>
            </geometry>
            <origin rpy="0.0 0.0 0.0" xyz="0.14347937500000002 1.3877787807814457e-17 0.0"/>
        </collision>
        <collision name="turtle_v1_root_link0_link1_link2_geom4">
            <geometry>
                <box size="0.018 0.053 0.0165891"/>
            </geometry>
            <origin rpy="1.5707963267948963 0.0 1.5707963267948963" xyz="0.08059312500000002 0.04044312500000001 0.0"/>
        </collision>
        <collision name="turtle_v1_root_link0_link1_link2_geom5">
            <geometry>
                <box size="0.018 0.053 0.0165891"/>
            </geometry>
            <origin rpy="0.0 0.0 -1.5707963267948966" xyz="0.080593125 -0.040443124999999996 0.0"/>
        </collision>
    </link>
    <joint type="revolute" name="turtle_v1_root_link0_link1_link2_joint1">
        <parent link="turtle_v1_root_link0_link1_link2"/>
        <child link="turtle_v1_root_link0_link1_link2_link1"/>
        <origin rpy="1.5707963267948966 0.0 1.5707963267948966" xyz="0.08059312500000002 0.06596812500000002 0.0"/>
        <axis xyz="0 1 0"/>
        <limit lower="-1.047197551" upper="1.047197551" effort="0.948013269" velocity="6.338968228"/>
    </joint>
    <link name="turtle_v1_root_link0_link1_link2_link1">
        <inertial>
            <origin rpy="9.860761315262648e-32 0.0 0.0" xyz="0.02973764044943822 1.5407439555097887e-33 -1.130466570252319e-17"/>
            <mass value="8.900000e-02"/>
            <inertia ixx="2.451623e-05" ixy="-5.057991e-22" ixz="0.000000e+00" iyy="4.952779e-05" iyz="0.000000e+00" izz="6.030948e-05"/>
        </inertial>
        <collision name="turtle_v1_root_link0_link1_link2_link1_geom0">
            <geometry>
                <box size="0.0583 0.0512 0.02"/>
            </geometry>
            <origin rpy="9.860761315262648e-32 0.0 0.0" xyz="0.018000000000000016 7.703719777548943e-34 -1.130466570252319e-17"/>
        </collision>
        <collision name="turtle_v1_root_link0_link1_link2_link1_geom1">
            <geometry>
                <box size="0.002 0.053 0.053"/>
            </geometry>
            <origin rpy="9.860761315262648e-32 0.0 0.0" xyz="0.04815000000000001 -1.5407439555097887e-33 -1.130466570252319e-17"/>
        </collision>
        <collision name="turtle_v1_root_link0_link1_link2_link1_geom2">
            <geometry>
                <box size="0.018 0.053 0.0165891"/>
            </geometry>
            <origin rpy="-1.5707963267948966 0.0 0.0" xyz="0.05815000000000002 1.5407439555097887e-33 -1.1304665702523193e-17"/>
        </collision>
    </link>
    <joint type="revolute" name="turtle_v1_root_link0_link1_link2_link1_joint1">
        <parent link="turtle_v1_root_link0_link1_link2_link1"/>
        <child link="turtle_v1_root_link0_link1_link2_link1_link1"/>
        <origin rpy="-1.5707963267948966 0.0 0.0" xyz="0.083675 4.622231866529366e-33 -2.4795418976517036e-17"/>
        <axis xyz="0 1 0"/>
        <limit lower="-1.047197551" upper="1.047197551" effort="0.948013269" velocity="6.338968228"/>
    </joint>
    <link name="turtle_v1_root_link0_link1_link2_link1_link1">
        <inertial>
            <origin rpy="0.0 0.0 0.0" xyz="0.025730769230769248 -1.6450909913105724e-17 2.1940193926459383e-33"/>
            <mass value="7.800000e-02"/>
            <inertia ixx="2.396696e-05" ixy="0.000000e+00" ixz="0.000000e+00" iyy="3.656843e-05" iyz="0.000000e+00" izz="4.730539e-05"/>
        </inertial>
        <collision name="turtle_v1_root_link0_link1_link2_link1_link1_geom0">
            <geometry>
                <box size="0.0583 0.0512 0.02"/>
            </geometry>
            <origin rpy="0.0 0.0 0.0" xyz="0.018000000000000016 -1.6450909913105724e-17 2.1940193926459383e-33"/>
        </collision>
        <collision name="turtle_v1_root_link0_link1_link2_link1_link1_geom1">
            <geometry>
                <box size="0.002 0.053 0.053"/>
            </geometry>
            <origin rpy="0.0 0.0 0.0" xyz="0.04815000000000001 -1.6450909913105724e-17 2.1940193926459386e-33"/>
        </collision>
    </link>
    <joint type="revolute" name="turtle_v1_root_link0_link1_link2_joint2">
        <parent link="turtle_v1_root_link0_link1_link2"/>
        <child link="turtle_v1_root_link0_link1_link2_link2"/>
        <origin rpy="0.0 0.0 -1.5707963267948966" xyz="0.08059312500000002 -0.065968125 0.0"/>
        <axis xyz="0 1 0"/>
        <limit lower="-1.047197551" upper="1.047197551" effort="0.948013269" velocity="6.338968228"/>
    </joint>
    <link name="turtle_v1_root_link0_link1_link2_link2">
        <inertial>
            <origin rpy="0.0 0.0 0.0" xyz="0.04767571153846152 9.9920072216264e-18 0.0"/>
            <mass value="1.300000e-01"/>
            <inertia ixx="8.230455e-05" ixy="1.393908e-37" ixz="-5.057991e-22" iyy="1.551974e-04" iyz="5.256654e-22" izz="2.003477e-04"/>
        </inertial>
        <collision name="turtle_v1_root_link0_link1_link2_link2_geom0">
            <geometry>
                <box size="0.0583 0.0512 0.02"/>
            </geometry>
            <origin rpy="0.0 0.0 0.0" xyz="0.017999999999999988 9.992007221626402e-18 0.0"/>
        </collision>
        <collision name="turtle_v1_root_link0_link1_link2_link2_geom1">
            <geometry>
                <box size="0.002 0.053 0.053"/>
            </geometry>
            <origin rpy="0.0 0.0 0.0" xyz="0.048149999999999984 9.9920072216264e-18 0.0"/>
        </collision>
        <collision name="turtle_v1_root_link0_link1_link2_link2_geom2">
            <geometry>
                <box size="0.06288625 0.06288625 0.0603"/>
            </geometry>
            <origin rpy="0.0 0.0 0.0" xyz="0.08059312499999999 9.9920072216264e-18 0.0"/>
        </collision>
        <collision name="turtle_v1_root_link0_link1_link2_link2_geom3">
            <geometry>
                <box size="0.018 0.053 0.0165891"/>
            </geometry>
            <origin rpy="1.5707963267948963 0.0 1.5707963267948963" xyz="0.08059312499999999 0.040443125 0.0"/>
        </collision>
        <collision name="turtle_v1_root_link0_link1_link2_link2_geom4">
            <geometry>
                <box size="0.018 0.053 0.0165891"/>
            </geometry>
            <origin rpy="0.0 0.0 -1.5707963267948966" xyz="0.08059312499999999 -0.040443125 0.0"/>
        </collision>
    </link>
    <joint type="revolute" name="turtle_v1_root_link0_link1_link2_link2_joint1">
        <parent link="turtle_v1_root_link0_link1_link2_link2"/>
        <child link="turtle_v1_root_link0_link1_link2_link2_link1"/>
        <origin rpy="1.5707963267948966 0.0 1.5707963267948966" xyz="0.08059312499999999 0.06596812500000004 0.0"/>
        <axis xyz="0 1 0"/>
        <limit lower="-1.047197551" upper="1.047197551" effort="0.948013269" velocity="6.338968228"/>
    </joint>
    <link name="turtle_v1_root_link0_link1_link2_link2_link1">
        <inertial>
            <origin rpy="-1.1102230246251565e-16 0.0 0.0" xyz="0.029737640449438163 1.734723475976807e-18 1.3877787807814457e-17"/>
            <mass value="8.900000e-02"/>
            <inertia ixx="2.451623e-05" ixy="-5.057991e-22" ixz="0.000000e+00" iyy="4.952779e-05" iyz="0.000000e+00" izz="6.030948e-05"/>
        </inertial>
        <collision name="turtle_v1_root_link0_link1_link2_link2_link1_geom0">
            <geometry>
                <box size="0.0583 0.0512 0.02"/>
            </geometry>
            <origin rpy="-1.1102230246251565e-16 0.0 0.0" xyz="0.01799999999999996 1.734723475976807e-18 1.5612511283791264e-17"/>
        </collision>
        <collision name="turtle_v1_root_link0_link1_link2_link2_link1_geom1">
            <geometry>
                <box size="0.002 0.053 0.053"/>
            </geometry>
            <origin rpy="-1.1102230246251565e-16 0.0 0.0" xyz="0.04814999999999996 0.0 1.3877787807814457e-17"/>
        </collision>
        <collision name="turtle_v1_root_link0_link1_link2_link2_link1_geom2">
            <geometry>
                <box size="0.018 0.053 0.0165891"/>
            </geometry>
            <origin rpy="-1.5707963267948966 0.0 0.0" xyz="0.05814999999999995 0.0 1.3877787807814457e-17"/>
        </collision>
    </link>
    <joint type="revolute" name="turtle_v1_root_link0_link1_link2_link2_link1_joint1">
        <parent link="turtle_v1_root_link0_link1_link2_link2_link1"/>
        <child link="turtle_v1_root_link0_link1_link2_link2_link1_link1"/>
        <origin rpy="-1.5707963267948966 2.220446049250313e-16 1.1102230246251565e-16" xyz="0.08367499999999994 0.0 2.0816681711721685e-17"/>
        <axis xyz="0 1 0"/>
        <limit lower="-1.047197551" upper="1.047197551" effort="0.948013269" velocity="6.338968228"/>
    </joint>
    <link name="turtle_v1_root_link0_link1_link2_link2_link1_link1">
        <inertial>
            <origin rpy="0.0 0.0 0.0" xyz="0.029737640449438222 1.3877787807814457e-17 1.4130832128153999e-18"/>
            <mass value="8.900000e-02"/>
            <inertia ixx="2.679414e-05" ixy="0.000000e+00" ixz="0.000000e+00" iyy="4.724987e-05" iyz="0.000000e+00" izz="6.030948e-05"/>
        </inertial>
        <collision name="turtle_v1_root_link0_link1_link2_link2_link1_link1_geom0">
            <geometry>
                <box size="0.0583 0.0512 0.02"/>
            </geometry>
            <origin rpy="0.0 0.0 0.0" xyz="0.018000000000000016 1.0408340855860843e-17 1.4130832128153997e-18"/>
        </collision>
        <collision name="turtle_v1_root_link0_link1_link2_link2_link1_link1_geom1">
            <geometry>
                <box size="0.002 0.053 0.053"/>
            </geometry>
            <origin rpy="0.0 0.0 0.0" xyz="0.04815000000000001 1.0408340855860843e-17 1.4130832128153997e-18"/>
        </collision>
        <collision name="turtle_v1_root_link0_link1_link2_link2_link1_link1_geom2">
            <geometry>
                <box size="0.018 0.053 0.0165891"/>
            </geometry>
            <origin rpy="0.0 0.0 0.0" xyz="0.058150000000000014 6.938893903907228e-18 1.4130832128153997e-18"/>
        </collision>
    </link>
    <joint type="revolute" name="turtle_v1_root_link0_link1_link2_link2_link1_link1_joint1">
        <parent link="turtle_v1_root_link0_link1_link2_link2_link1_link1"/>
        <child link="turtle_v1_root_link0_link1_link2_link2_link1_link1_link1"/>
        <origin rpy="0.0 0.0 0.0" xyz="0.08367500000000001 1.3877787807814457e-17 1.4130832128153989e-18"/>
        <axis xyz="0 1 0"/>
        <limit lower="-1.047197551" upper="1.047197551" effort="0.948013269" velocity="6.338968228"/>
    </joint>
    <link name="turtle_v1_root_link0_link1_link2_link2_link1_link1_link1">
        <inertial>
            <origin rpy="0.0 0.0 0.0" xyz="0.029737640449438225 0.0 3.1749497040295234e-33"/>
            <mass value="8.900000e-02"/>
            <inertia ixx="2.679414e-05" ixy="0.000000e+00" ixz="0.000000e+00" iyy="4.724987e-05" iyz="0.000000e+00" izz="6.030948e-05"/>
        </inertial>
        <collision name="turtle_v1_root_link0_link1_link2_link2_link1_link1_link1_geom0">
            <geometry>
                <box size="0.0583 0.0512 0.02"/>
            </geometry>
            <origin rpy="0.0 0.0 0.0" xyz="0.018000000000000016 -3.469446951953614e-18 2.749876399994793e-33"/>
        </collision>
        <collision name="turtle_v1_root_link0_link1_link2_link2_link1_link1_link1_geom1">
            <geometry>
                <box size="0.002 0.053 0.053"/>
            </geometry>
            <origin rpy="0.0 0.0 0.0" xyz="0.04815000000000001 0.0 2.789763715152076e-33"/>
        </collision>
        <collision name="turtle_v1_root_link0_link1_link2_link2_link1_link1_link1_geom2">
            <geometry>
                <box size="0.018 0.053 0.0165891"/>
            </geometry>
            <origin rpy="0.0 0.0 0.0" xyz="0.05815000000000002 0.0 3.447317328782812e-33"/>
        </collision>
    </link>
    <joint type="revolute" name="turtle_v1_root_link0_link1_link2_link2_link1_link1_link1_joint1">
        <parent link="turtle_v1_root_link0_link1_link2_link2_link1_link1_link1"/>
        <child link="turtle_v1_root_link0_link1_link2_link2_link1_link1_link1_link1"/>
        <origin rpy="0.0 0.0 0.0" xyz="0.08367499999999996 -6.938893903907228e-18 -2.630214454522945e-33"/>
        <axis xyz="0 1 0"/>
        <limit lower="-1.047197551" upper="1.047197551" effort="0.948013269" velocity="6.338968228"/>
    </joint>
    <link name="turtle_v1_root_link0_link1_link2_link2_link1_link1_link1_link1">
        <inertial>
            <origin rpy="0.0 0.0 0.0" xyz="0.025730769230769248 -5.204170427930421e-18 2.6535799027754313e-33"/>
            <mass value="7.800000e-02"/>
            <inertia ixx="2.396696e-05" ixy="0.000000e+00" ixz="0.000000e+00" iyy="3.656843e-05" iyz="0.000000e+00" izz="4.730539e-05"/>
        </inertial>
        <collision name="turtle_v1_root_link0_link1_link2_link2_link1_link1_link1_link1_geom0">
            <geometry>
                <box size="0.0583 0.0512 0.02"/>
            </geometry>
            <origin rpy="0.0 0.0 0.0" xyz="0.018000000000000016 -3.469446951953614e-18 2.749876399994793e-33"/>
        </collision>
        <collision name="turtle_v1_root_link0_link1_link2_link2_link1_link1_link1_link1_geom1">
            <geometry>
                <box size="0.002 0.053 0.053"/>
            </geometry>
            <origin rpy="0.0 0.0 0.0" xyz="0.04815000000000001 0.0 2.789763715152076e-33"/>
        </collision>
    </link>
    <joint type="revolute" name="turtle_v1_root_link0_link1_link2_link2_joint2">
        <parent link="turtle_v1_root_link0_link1_link2_link2"/>
        <child link="turtle_v1_root_link0_link1_link2_link2_link2"/>
        <origin rpy="0.0 0.0 -1.5707963267948966" xyz="0.08059312499999999 -0.06596812499999999 0.0"/>
        <axis xyz="0 1 0"/>
        <limit lower="-1.047197551" upper="1.047197551" effort="0.948013269" velocity="6.338968228"/>
    </joint>
    <link name="turtle_v1_root_link0_link1_link2_link2_link2">
        <inertial>
            <origin rpy="0.0 0.0 0.0" xyz="0.025730769230769217 -1.3877787807814457e-17 -0.0"/>
            <mass value="7.800000e-02"/>
            <inertia ixx="2.396696e-05" ixy="0.000000e+00" ixz="0.000000e+00" iyy="3.656843e-05" iyz="0.000000e+00" izz="4.730539e-05"/>
        </inertial>
        <collision name="turtle_v1_root_link0_link1_link2_link2_link2_geom0">
            <geometry>
                <box size="0.0583 0.0512 0.02"/>
            </geometry>
            <origin rpy="0.0 0.0 0.0" xyz="0.017999999999999988 -1.214306433183765e-17 -0.0"/>
        </collision>
        <collision name="turtle_v1_root_link0_link1_link2_link2_link2_geom1">
            <geometry>
                <box size="0.002 0.053 0.053"/>
            </geometry>
            <origin rpy="0.0 0.0 0.0" xyz="0.048149999999999984 -1.3877787807814457e-17 -0.0"/>
        </collision>
    </link>
    <joint type="revolute" name="turtle_v1_root_joint1">
        <parent link="turtle_v1_root"/>
        <child link="turtle_v1_root_link1"/>
        <origin rpy="0.0 0.0 0.0" xyz="0.06596812500000002 0.07594312499999997 0.0"/>
        <axis xyz="0 1 0"/>
        <limit lower="-1.047197551" upper="1.047197551" effort="0.948013269" velocity="6.338968228"/>
    </joint>
    <link name="turtle_v1_root_link1">
        <inertial>
            <origin rpy="0.0 0.0 0.0" xyz="0.025730769230769234 -5.8841820305133264e-18 -0.0"/>
            <mass value="7.800000e-02"/>
            <inertia ixx="2.396696e-05" ixy="0.000000e+00" ixz="0.000000e+00" iyy="3.656843e-05" iyz="0.000000e+00" izz="4.730539e-05"/>
        </inertial>
        <collision name="turtle_v1_root_link1_geom0">
            <geometry>
                <box size="0.0583 0.0512 0.02"/>
            </geometry>
            <origin rpy="0.0 0.0 0.0" xyz="0.018000000000000002 -5.884182030513329e-18 -0.0"/>
        </collision>
        <collision name="turtle_v1_root_link1_geom1">
            <geometry>
                <box size="0.002 0.053 0.053"/>
            </geometry>
            <origin rpy="0.0 0.0 0.0" xyz="0.04815 -5.884182030513329e-18 -0.0"/>
        </collision>
    </link>
</robot>
