<?xml version="1.0" ?>
<robot name="blokky_v1">
    <link name="blokky_v1_root">
        <inertial>
            <origin rpy="0.0 0.0 0.0" xyz="-0.01403807308306709 0.0033015155750798727 -1.692110973503162e-36"/>
            <mass value="3.130000e-01"/>
            <inertia ixx="3.074626e-04" ixy="-5.057991e-22" ixz="-1.011598e-21" iyy="5.921036e-04" iyz="-8.315233e-23" izz="7.281894e-04"/>
        </inertial>
        <collision name="blokky_v1_root_geom0">
            <geometry>
                <box size="0.089 0.089 0.0603"/>
            </geometry>
            <origin rpy="0.0 0.0 0.0" xyz="0.0 0.0 0.0"/>
        </collision>
        <collision name="blokky_v1_root_geom1">
            <geometry>
                <box size="0.06288625 0.06288625 0.0603"/>
            </geometry>
            <origin rpy="0.0 0.0 3.141592653589793" xyz="-0.075943125 9.300350494849734e-18 0.0"/>
        </collision>
        <collision name="blokky_v1_root_geom2">
            <geometry>
                <box size="0.018 0.053 0.0165891"/>
            </geometry>
            <origin rpy="1.5707963267948963 0.0 1.5707963267948963" xyz="1.214306433183765e-17 0.0535 0.0"/>
        </collision>
        <collision name="blokky_v1_root_geom3">
            <geometry>
                <box size="0.018 0.053 0.0165891"/>
            </geometry>
            <origin rpy="1.5707963267948966 0.0 3.141592653589793" xyz="-0.11638625 1.4253204852726365e-17 -4.81482486096809e-35"/>
        </collision>
        <collision name="blokky_v1_root_geom4">
            <geometry>
                <box size="0.018 0.053 0.0165891"/>
            </geometry>
            <origin rpy="1.5707963267948966 0.0 1.5707963267948963" xyz="-0.075943125 0.04044312500000001 0.0"/>
        </collision>
    </link>
    <joint type="revolute" name="blokky_v1_root_joint0">
        <parent link="blokky_v1_root"/>
        <child link="blokky_v1_root_link0"/>
        <origin rpy="1.5707963267948963 0.0 1.5707963267948963" xyz="1.734723475976807e-17 0.07902499999999998 0.0"/>
        <axis xyz="0 1 0"/>
        <limit lower="-1.047197551" upper="1.047197551" effort="0.948013269" velocity="6.338968228"/>
    </joint>
    <link name="blokky_v1_root_link0">
        <inertial>
            <origin rpy="0.0 0.0 0.0" xyz="0.025730769230769238 -8.673617379884035e-19 -2.6020852139652106e-18"/>
            <mass value="7.800000e-02"/>
            <inertia ixx="2.396696e-05" ixy="0.000000e+00" ixz="0.000000e+00" iyy="3.656843e-05" iyz="0.000000e+00" izz="4.730539e-05"/>
        </inertial>
        <collision name="blokky_v1_root_link0_geom0">
            <geometry>
                <box size="0.0583 0.0512 0.02"/>
            </geometry>
            <origin rpy="0.0 0.0 0.0" xyz="0.018000000000000002 0.0 0.0"/>
        </collision>
        <collision name="blokky_v1_root_link0_geom1">
            <geometry>
                <box size="0.002 0.053 0.053"/>
            </geometry>
            <origin rpy="0.0 0.0 0.0" xyz="0.04815 -1.734723475976807e-18 -1.734723475976807e-18"/>
        </collision>
    </link>
    <joint type="revolute" name="blokky_v1_root_joint1">
        <parent link="blokky_v1_root"/>
        <child link="blokky_v1_root_link1"/>
        <origin rpy="1.5707963267948966 0.0 3.141592653589793" xyz="-0.14191125 1.7379115807549985e-17 -1.925929944387236e-34"/>
        <axis xyz="0 1 0"/>
        <limit lower="-1.047197551" upper="1.047197551" effort="0.948013269" velocity="6.338968228"/>
    </joint>
    <link name="blokky_v1_root_link1">
        <inertial>
            <origin rpy="3.749399456654644e-33 0.0 0.0" xyz="0.02973764044943822 -1.925929944387236e-34 -3.851859888774472e-34"/>
            <mass value="8.900000e-02"/>
            <inertia ixx="2.451623e-05" ixy="-5.057991e-22" ixz="0.000000e+00" iyy="4.952779e-05" iyz="0.000000e+00" izz="6.030948e-05"/>
        </inertial>
        <collision name="blokky_v1_root_link1_geom0">
            <geometry>
                <box size="0.0583 0.0512 0.02"/>
            </geometry>
            <origin rpy="3.749399456654644e-33 0.0 0.0" xyz="0.018000000000000016 9.62964972193618e-35 -6.7407548053553255e-34"/>
        </collision>
        <collision name="blokky_v1_root_link1_geom1">
            <geometry>
                <box size="0.002 0.053 0.053"/>
            </geometry>
            <origin rpy="3.749399456654644e-33 0.0 0.0" xyz="0.04815000000000001 -5.7777898331617076e-34 -9.62964972193618e-34"/>
        </collision>
        <collision name="blokky_v1_root_link1_geom2">
            <geometry>
                <box size="0.018 0.053 0.0165891"/>
            </geometry>
            <origin rpy="-1.5707963267948966 0.0 0.0" xyz="0.05815000000000002 0.0 -1.925929944387236e-33"/>
        </collision>
    </link>
    <joint type="revolute" name="blokky_v1_root_link1_joint1">
        <parent link="blokky_v1_root_link1"/>
        <child link="blokky_v1_root_link1_link1"/>
        <origin rpy="-1.5707963267948966 0.0 0.0" xyz="0.083675 -3.851859888774472e-34 1.1555579666323415e-33"/>
        <axis xyz="0 1 0"/>
        <limit lower="-1.047197551" upper="1.047197551" effort="0.948013269" velocity="6.338968228"/>
    </joint>
    <link name="blokky_v1_root_link1_link1">
        <inertial>
            <origin rpy="0.0 0.0 0.0" xyz="0.09052347834346505 -0.05716613791793312 -3.851859888774472e-34"/>
            <mass value="3.290000e-01"/>
            <inertia ixx="1.186958e-03" ixy="0.000000e+00" ixz="0.000000e+00" iyy="1.345892e-03" iyz="5.157323e-22" izz="2.362655e-03"/>
        </inertial>
        <collision name="blokky_v1_root_link1_link1_geom0">
            <geometry>
                <box size="0.0583 0.0512 0.02"/>
            </geometry>
            <origin rpy="0.0 0.0 0.0" xyz="0.018000000000000016 7.703719777548943e-34 -3.851859888774472e-34"/>
        </collision>
        <collision name="blokky_v1_root_link1_link1_geom1">
            <geometry>
                <box size="0.002 0.053 0.053"/>
            </geometry>
            <origin rpy="0.0 0.0 0.0" xyz="0.04815000000000001 0.0 -3.851859888774472e-34"/>
        </collision>
        <collision name="blokky_v1_root_link1_link1_geom2">
            <geometry>
                <box size="0.06288625 0.06288625 0.0603"/>
            </geometry>
            <origin rpy="0.0 0.0 0.0" xyz="0.08059312500000002 0.0 -3.851859888774472e-34"/>
        </collision>
        <collision name="blokky_v1_root_link1_link1_geom3">
            <geometry>
                <box size="0.06288625 0.06288625 0.0603"/>
            </geometry>
            <origin rpy="0.0 0.0 0.0" xyz="0.14347937500000002 0.0 -3.851859888774472e-34"/>
        </collision>
        <collision name="blokky_v1_root_link1_link1_geom4">
            <geometry>
                <box size="0.06288625 0.06288625 0.0603"/>
            </geometry>
            <origin rpy="0.0 0.0 -1.5707963267948966" xyz="0.08059312500000002 -0.06288625 -3.851859888774472e-34"/>
        </collision>
        <collision name="blokky_v1_root_link1_link1_geom5">
            <geometry>
                <box size="0.06288625 0.06288625 0.0603"/>
            </geometry>
            <origin rpy="0.0 0.0 -1.5707963267948966" xyz="0.14347937500000002 -0.06288625 -3.851859888774472e-34"/>
        </collision>
        <collision name="blokky_v1_root_link1_link1_geom6">
            <geometry>
                <box size="0.06288625 0.06288625 0.0603"/>
            </geometry>
            <origin rpy="0.0 0.0 -1.5707963267948966" xyz="0.08059312500000002 -0.1257725 -3.851859888774472e-34"/>
        </collision>
        <collision name="blokky_v1_root_link1_link1_geom7">
            <geometry>
                <box size="0.06288625 0.06288625 0.0603"/>
            </geometry>
            <origin rpy="0.0 0.0 -1.5707963267948966" xyz="0.14347937500000002 -0.1257725 -3.851859888774472e-34"/>
        </collision>
        <collision name="blokky_v1_root_link1_link1_geom8">
            <geometry>
                <box size="0.06288625 0.06288625 0.0603"/>
            </geometry>
            <origin rpy="0.0 0.0 0.0" xyz="0.20636562500000005 -0.06288625000000003 -3.851859888774472e-34"/>
        </collision>
        <collision name="blokky_v1_root_link1_link1_geom9">
            <geometry>
                <box size="0.018 0.053 0.0165891"/>
            </geometry>
            <origin rpy="0.0 0.0 -1.5707963267948966" xyz="0.08059312500000002 -0.16621562500000003 -3.851859888774472e-34"/>
        </collision>
        <collision name="blokky_v1_root_link1_link1_geom10">
            <geometry>
                <box size="0.06288625 0.06288625 0.0603"/>
            </geometry>
            <origin rpy="0.0 0.0 3.1415926535897927" xyz="0.01770687500000001 -0.12577249999999995 -3.851859888774472e-34"/>
        </collision>
    </link>
    <joint type="revolute" name="blokky_v1_root_link1_link1_joint1">
        <parent link="blokky_v1_root_link1_link1"/>
        <child link="blokky_v1_root_link1_link1_link1"/>
        <origin rpy="0.0 0.0 -1.5707963267948966" xyz="0.08059312500000002 -0.19174062500000003 -3.851859888774472e-34"/>
        <axis xyz="0 1 0"/>
        <limit lower="-1.047197551" upper="1.047197551" effort="0.948013269" velocity="6.338968228"/>
    </joint>
    <link name="blokky_v1_root_link1_link1_link1">
        <inertial>
            <origin rpy="0.0 0.0 0.0" xyz="0.025730769230769245 1.734723475976807e-18 0.0"/>
            <mass value="7.800000e-02"/>
            <inertia ixx="2.396696e-05" ixy="0.000000e+00" ixz="0.000000e+00" iyy="3.656843e-05" iyz="0.000000e+00" izz="4.730539e-05"/>
        </inertial>
        <collision name="blokky_v1_root_link1_link1_link1_geom0">
            <geometry>
                <box size="0.0583 0.0512 0.02"/>
            </geometry>
            <origin rpy="0.0 0.0 0.0" xyz="0.018000000000000016 3.469446951953614e-18 0.0"/>
        </collision>
        <collision name="blokky_v1_root_link1_link1_link1_geom1">
            <geometry>
                <box size="0.002 0.053 0.053"/>
            </geometry>
            <origin rpy="0.0 0.0 0.0" xyz="0.04815000000000001 0.0 0.0"/>
        </collision>
    </link>
    <joint type="revolute" name="blokky_v1_root_joint2">
        <parent link="blokky_v1_root"/>
        <child link="blokky_v1_root_link2"/>
        <origin rpy="1.5707963267948966 0.0 1.5707963267948963" xyz="-0.075943125 0.06596812500000002 0.0"/>
        <axis xyz="0 1 0"/>
        <limit lower="-1.047197551" upper="1.047197551" effort="0.948013269" velocity="6.338968228"/>
    </joint>
    <link name="blokky_v1_root_link2">
        <inertial>
            <origin rpy="0.0 0.0 0.0" xyz="0.025730769230769224 -8.673617379884035e-19 -4.336808689942018e-18"/>
            <mass value="7.800000e-02"/>
            <inertia ixx="2.396696e-05" ixy="0.000000e+00" ixz="0.000000e+00" iyy="3.656843e-05" iyz="0.000000e+00" izz="4.730539e-05"/>
        </inertial>
        <collision name="blokky_v1_root_link2_geom0">
            <geometry>
                <box size="0.0583 0.0512 0.02"/>
            </geometry>
            <origin rpy="0.0 0.0 0.0" xyz="0.017999999999999988 0.0 -3.469446951953614e-18"/>
        </collision>
        <collision name="blokky_v1_root_link2_geom1">
            <geometry>
                <box size="0.002 0.053 0.053"/>
            </geometry>
            <origin rpy="0.0 0.0 0.0" xyz="0.048149999999999984 0.0 -6.938893903907228e-18"/>
        </collision>
    </link>
</robot>
