<?xml version="1.0" ?>
<robot name="insect_v1">
    <link name="insect_v1_root">
        <inertial>
            <origin rpy="0.0 0.0 0.0" xyz="-5.117766576636557e-19 -0.002254789272030651 0.0"/>
            <mass value="2.610000e-01"/>
            <inertia ixx="2.714798e-04" ixy="-1.393908e-37" ixz="5.057991e-22" iyy="2.436446e-04" iyz="9.933154e-24" izz="3.630267e-04"/>
        </inertial>
        <collision name="insect_v1_root_geom0">
            <geometry>
                <box size="0.089 0.089 0.0603"/>
            </geometry>
            <origin rpy="0.0 0.0 0.0" xyz="0.0 0.0 0.0"/>
        </collision>
        <collision name="insect_v1_root_geom1">
            <geometry>
                <box size="0.018 0.053 0.0165891"/>
            </geometry>
            <origin rpy="1.5707963267948966 0.0 -1.5707963267948966" xyz="-1.214306433183765e-17 -0.0535 0.0"/>
        </collision>
    </link>
    <joint type="revolute" name="insect_v1_root_joint0">
        <parent link="insect_v1_root"/>
        <child link="insect_v1_root_link0"/>
        <origin rpy="1.5707963267948966 0.0 -1.5707963267948966" xyz="-1.734723475976807e-17 -0.07902499999999998 0.0"/>
        <axis xyz="0 1 0"/>
        <limit lower="-1.047197551" upper="1.047197551" effort="0.948013269" velocity="6.338968228"/>
    </joint>
    <link name="insect_v1_root_link0">
        <inertial>
            <origin rpy="0.0 0.0 0.0" xyz="0.029737640449438205 0.0 0.0"/>
            <mass value="8.900000e-02"/>
            <inertia ixx="2.451623e-05" ixy="-5.057991e-22" ixz="0.000000e+00" iyy="4.952779e-05" iyz="0.000000e+00" izz="6.030948e-05"/>
        </inertial>
        <collision name="insect_v1_root_link0_geom0">
            <geometry>
                <box size="0.0583 0.0512 0.02"/>
            </geometry>
            <origin rpy="0.0 0.0 0.0" xyz="0.018000000000000002 0.0 0.0"/>
        </collision>
        <collision name="insect_v1_root_link0_geom1">
            <geometry>
                <box size="0.002 0.053 0.053"/>
            </geometry>
            <origin rpy="0.0 0.0 0.0" xyz="0.04815 -1.734723475976807e-18 -1.734723475976807e-18"/>
        </collision>
        <collision name="insect_v1_root_link0_geom2">
            <geometry>
                <box size="0.018 0.053 0.0165891"/>
            </geometry>
            <origin rpy="-1.5707963267948966 0.0 0.0" xyz="0.05815 -1.734723475976807e-18 -5.204170427930421e-18"/>
        </collision>
    </link>
    <joint type="revolute" name="insect_v1_root_link0_joint1">
        <parent link="insect_v1_root_link0"/>
        <child link="insect_v1_root_link0_link1"/>
        <origin rpy="-1.5707963267948966 0.0 0.0" xyz="0.083675 0.0 0.0"/>
        <axis xyz="0 1 0"/>
        <limit lower="-1.047197551" upper="1.047197551" effort="0.948013269" velocity="6.338968228"/>
    </joint>
    <link name="insect_v1_root_link0_link1">
        <inertial>
            <origin rpy="0.0 0.0 0.0" xyz="0.05339887411347516 1.0408340855860843e-17 -0.0"/>
            <mass value="1.410000e-01"/>
            <inertia ixx="8.285382e-05" ixy="5.057991e-22" ixz="-5.057991e-22" iyy="2.126056e-04" iyz="5.256654e-22" izz="2.578006e-04"/>
        </inertial>
        <collision name="insect_v1_root_link0_link1_geom0">
            <geometry>
                <box size="0.0583 0.0512 0.02"/>
            </geometry>
            <origin rpy="0.0 0.0 0.0" xyz="0.017999999999999988 3.469446951953614e-18 -0.0"/>
        </collision>
        <collision name="insect_v1_root_link0_link1_geom1">
            <geometry>
                <box size="0.002 0.053 0.053"/>
            </geometry>
            <origin rpy="0.0 0.0 0.0" xyz="0.048149999999999984 0.0 -0.0"/>
        </collision>
        <collision name="insect_v1_root_link0_link1_geom2">
            <geometry>
                <box size="0.06288625 0.06288625 0.0603"/>
            </geometry>
            <origin rpy="0.0 0.0 0.0" xyz="0.08059312499999999 6.938893903907228e-18 -0.0"/>
        </collision>
        <collision name="insect_v1_root_link0_link1_geom3">
            <geometry>
                <box size="0.018 0.053 0.0165891"/>
            </geometry>
            <origin rpy="1.5707963267948966 0.0 0.0" xyz="0.12103624999999998 0.0 -0.0"/>
        </collision>
        <collision name="insect_v1_root_link0_link1_geom4">
            <geometry>
                <box size="0.018 0.053 0.0165891"/>
            </geometry>
            <origin rpy="1.5707963267948963 0.0 1.5707963267948963" xyz="0.08059312499999999 0.04044312500000001 -0.0"/>
        </collision>
        <collision name="insect_v1_root_link0_link1_geom5">
            <geometry>
                <box size="0.018 0.053 0.0165891"/>
            </geometry>
            <origin rpy="0.0 0.0 -1.5707963267948966" xyz="0.08059312499999997 -0.04044312500000001 -0.0"/>
        </collision>
    </link>
    <joint type="revolute" name="insect_v1_root_link0_link1_joint1">
        <parent link="insect_v1_root_link0_link1"/>
        <child link="insect_v1_root_link0_link1_link1"/>
        <origin rpy="1.5707963267948966 0.0 0.0" xyz="0.14656124999999995 0.0 -0.0"/>
        <axis xyz="0 1 0"/>
        <limit lower="-1.047197551" upper="1.047197551" effort="0.948013269" velocity="6.338968228"/>
    </joint>
    <link name="insect_v1_root_link0_link1_link1">
        <inertial>
            <origin rpy="0.0 0.0 0.0" xyz="0.02573076923076925 -8.673617379884035e-19 -4.336808689942018e-18"/>
            <mass value="7.800000e-02"/>
            <inertia ixx="2.396696e-05" ixy="0.000000e+00" ixz="0.000000e+00" iyy="3.656843e-05" iyz="0.000000e+00" izz="4.730539e-05"/>
        </inertial>
        <collision name="insect_v1_root_link0_link1_link1_geom0">
            <geometry>
                <box size="0.0583 0.0512 0.02"/>
            </geometry>
            <origin rpy="0.0 0.0 0.0" xyz="0.018000000000000016 0.0 -3.469446951953614e-18"/>
        </collision>
        <collision name="insect_v1_root_link0_link1_link1_geom1">
            <geometry>
                <box size="0.002 0.053 0.053"/>
            </geometry>
            <origin rpy="0.0 0.0 0.0" xyz="0.04815000000000001 0.0 -6.938893903907228e-18"/>
        </collision>
    </link>
    <joint type="revolute" name="insect_v1_root_link0_link1_joint2">
        <parent link="insect_v1_root_link0_link1"/>
        <child link="insect_v1_root_link0_link1_link2"/>
        <origin rpy="1.5707963267948966 0.0 1.5707963267948966" xyz="0.08059312500000002 0.06596812500000002 -0.0"/>
        <axis xyz="0 1 0"/>
        <limit lower="-1.047197551" upper="1.047197551" effort="0.948013269" velocity="6.338968228"/>
    </joint>
    <link name="insect_v1_root_link0_link1_link2">
        <inertial>
            <origin rpy="0.0 0.0 0.0" xyz="0.05109782211538459 -1.3010426069826053e-18 0.003422110576923043"/>
            <mass value="1.300000e-01"/>
            <inertia ixx="6.511269e-05" ixy="9.933154e-24" ixz="5.157323e-22" iyy="2.150576e-04" iyz="1.415964e-37" izz="2.101661e-04"/>
        </inertial>
        <collision name="insect_v1_root_link0_link1_link2_geom0">
            <geometry>
                <box size="0.0583 0.0512 0.02"/>
            </geometry>
            <origin rpy="0.0 0.0 0.0" xyz="0.017999999999999988 6.162975822039155e-33 -3.3407908466890496e-17"/>
        </collision>
        <collision name="insect_v1_root_link0_link1_link2_geom1">
            <geometry>
                <box size="0.002 0.053 0.053"/>
            </geometry>
            <origin rpy="0.0 0.0 0.0" xyz="0.04814999999999999 4.622231866529366e-33 -3.3407908466890496e-17"/>
        </collision>
        <collision name="insect_v1_root_link0_link1_link2_geom2">
            <geometry>
                <box size="0.06288625 0.06288625 0.0603"/>
            </geometry>
            <origin rpy="-1.5707963267948966 0.0 0.0" xyz="0.08059312499999999 4.622231866529366e-33 -3.34079084668905e-17"/>
        </collision>
        <collision name="insect_v1_root_link0_link1_link2_geom3">
            <geometry>
                <box size="0.018 0.053 0.0165891"/>
            </geometry>
            <origin rpy="0.0 0.0 0.0" xyz="0.12103624999999998 4.622231866529366e-33 -3.340790846689051e-17"/>
        </collision>
        <collision name="insect_v1_root_link0_link1_link2_geom4">
            <geometry>
                <box size="0.018 0.053 0.0165891"/>
            </geometry>
            <origin rpy="-1.5707963267948966 -1.5707963267948963 0.0" xyz="0.08059312499999999 -1.0408340855860843e-17 0.04044312499999997"/>
        </collision>
    </link>
    <joint type="revolute" name="insect_v1_root_link0_link1_link2_joint1">
        <parent link="insect_v1_root_link0_link1_link2"/>
        <child link="insect_v1_root_link0_link1_link2_link1"/>
        <origin rpy="0.0 0.0 0.0" xyz="0.14656124999999998 9.244463733058732e-33 -4.602294267205347e-17"/>
        <axis xyz="0 1 0"/>
        <limit lower="-1.047197551" upper="1.047197551" effort="0.948013269" velocity="6.338968228"/>
    </joint>
    <link name="insect_v1_root_link0_link1_link2_link1">
        <inertial>
            <origin rpy="0.0 0.0 0.0" xyz="0.025730769230769245 -3.0814879110195774e-33 2.2103242764367313e-17"/>
            <mass value="7.800000e-02"/>
            <inertia ixx="2.396696e-05" ixy="0.000000e+00" ixz="0.000000e+00" iyy="3.656843e-05" iyz="0.000000e+00" izz="4.730539e-05"/>
        </inertial>
        <collision name="insect_v1_root_link0_link1_link2_link1_geom0">
            <geometry>
                <box size="0.0583 0.0512 0.02"/>
            </geometry>
            <origin rpy="0.0 0.0 0.0" xyz="0.018000000000000016 -4.622231866529366e-33 2.210324276436732e-17"/>
        </collision>
        <collision name="insect_v1_root_link0_link1_link2_link1_geom1">
            <geometry>
                <box size="0.002 0.053 0.053"/>
            </geometry>
            <origin rpy="0.0 0.0 0.0" xyz="0.04815000000000001 -3.0814879110195774e-33 2.210324276436732e-17"/>
        </collision>
    </link>
    <joint type="revolute" name="insect_v1_root_link0_link1_link2_joint2">
        <parent link="insect_v1_root_link0_link1_link2"/>
        <child link="insect_v1_root_link0_link1_link2_link2"/>
        <origin rpy="-1.5707963267948966 -1.5707963267948963 0.0" xyz="0.08059312499999999 -6.938893903907228e-18 0.06596812499999996"/>
        <axis xyz="0 1 0"/>
        <limit lower="-1.047197551" upper="1.047197551" effort="0.948013269" velocity="6.338968228"/>
    </joint>
    <link name="insect_v1_root_link0_link1_link2_link2">
        <inertial>
            <origin rpy="0.0 0.0 0.0" xyz="0.02973764044943822 8.673617379884035e-18 -6.938893903907228e-18"/>
            <mass value="8.900000e-02"/>
            <inertia ixx="2.679414e-05" ixy="0.000000e+00" ixz="0.000000e+00" iyy="4.724987e-05" iyz="0.000000e+00" izz="6.030948e-05"/>
        </inertial>
        <collision name="insect_v1_root_link0_link1_link2_link2_geom0">
            <geometry>
                <box size="0.0583 0.0512 0.02"/>
            </geometry>
            <origin rpy="0.0 0.0 0.0" xyz="0.018000000000000016 6.938893903907228e-18 -6.938893903907228e-18"/>
        </collision>
        <collision name="insect_v1_root_link0_link1_link2_link2_geom1">
            <geometry>
                <box size="0.002 0.053 0.053"/>
            </geometry>
            <origin rpy="0.0 0.0 0.0" xyz="0.04815000000000001 1.3877787807814457e-17 -6.938893903907228e-18"/>
        </collision>
        <collision name="insect_v1_root_link0_link1_link2_link2_geom2">
            <geometry>
                <box size="0.018 0.053 0.0165891"/>
            </geometry>
            <origin rpy="0.0 0.0 0.0" xyz="0.05815000000000002 1.0408340855860843e-17 -6.938893903907228e-18"/>
        </collision>
    </link>
    <joint type="revolute" name="insect_v1_root_link0_link1_link2_link2_joint1">
        <parent link="insect_v1_root_link0_link1_link2_link2"/>
        <child link="insect_v1_root_link0_link1_link2_link2_link1"/>
        <origin rpy="0.0 0.0 0.0" xyz="0.083675 6.938893903907228e-18 -6.938893903907228e-18"/>
        <axis xyz="0 1 0"/>
        <limit lower="-1.047197551" upper="1.047197551" effort="0.948013269" velocity="6.338968228"/>
    </joint>
    <link name="insect_v1_root_link0_link1_link2_link2_link1">
        <inertial>
            <origin rpy="0.0 0.0 0.0" xyz="0.02973764044943822 -1.9081958235744878e-17 0.0"/>
            <mass value="8.900000e-02"/>
            <inertia ixx="2.451623e-05" ixy="5.057991e-22" ixz="0.000000e+00" iyy="4.952779e-05" iyz="0.000000e+00" izz="6.030948e-05"/>
        </inertial>
        <collision name="insect_v1_root_link0_link1_link2_link2_link1_geom0">
            <geometry>
                <box size="0.0583 0.0512 0.02"/>
            </geometry>
            <origin rpy="0.0 0.0 0.0" xyz="0.018000000000000016 -1.9081958235744878e-17 0.0"/>
        </collision>
        <collision name="insect_v1_root_link0_link1_link2_link2_link1_geom1">
            <geometry>
                <box size="0.002 0.053 0.053"/>
            </geometry>
            <origin rpy="0.0 0.0 0.0" xyz="0.04815000000000001 -1.3877787807814457e-17 0.0"/>
        </collision>
        <collision name="insect_v1_root_link0_link1_link2_link2_link1_geom2">
            <geometry>
                <box size="0.018 0.053 0.0165891"/>
            </geometry>
            <origin rpy="1.5707963267948966 0.0 0.0" xyz="0.058150000000000014 -2.0816681711721685e-17 0.0"/>
        </collision>
    </link>
    <joint type="revolute" name="insect_v1_root_link0_link1_link2_link2_link1_joint1">
        <parent link="insect_v1_root_link0_link1_link2_link2_link1"/>
        <child link="insect_v1_root_link0_link1_link2_link2_link1_link1"/>
        <origin rpy="1.5707963267948966 -2.220446049250313e-16 1.1102230246251565e-16" xyz="0.083675 -2.0816681711721685e-17 0.0"/>
        <axis xyz="0 1 0"/>
        <limit lower="-1.047197551" upper="1.047197551" effort="0.948013269" velocity="6.338968228"/>
    </joint>
    <link name="insect_v1_root_link0_link1_link2_link2_link1_link1">
        <inertial>
            <origin rpy="1.1102230246251563e-16 0.0 1.1102230246251563e-16" xyz="0.02573076923076925 -1.734723475976807e-18 1.5612511283791264e-17"/>
            <mass value="7.800000e-02"/>
            <inertia ixx="2.396696e-05" ixy="0.000000e+00" ixz="0.000000e+00" iyy="3.656843e-05" iyz="0.000000e+00" izz="4.730539e-05"/>
        </inertial>
        <collision name="insect_v1_root_link0_link1_link2_link2_link1_link1_geom0">
            <geometry>
                <box size="0.0583 0.0512 0.02"/>
            </geometry>
            <origin rpy="1.1102230246251563e-16 0.0 1.1102230246251563e-16" xyz="0.01800000000000002 0.0 1.734723475976807e-17"/>
        </collision>
        <collision name="insect_v1_root_link0_link1_link2_link2_link1_link1_geom1">
            <geometry>
                <box size="0.002 0.053 0.053"/>
            </geometry>
            <origin rpy="1.1102230246251563e-16 0.0 1.1102230246251563e-16" xyz="0.048150000000000026 -3.469446951953614e-18 1.0408340855860843e-17"/>
        </collision>
    </link>
    <joint type="revolute" name="insect_v1_root_link0_link1_joint3">
        <parent link="insect_v1_root_link0_link1"/>
        <child link="insect_v1_root_link0_link1_link3"/>
        <origin rpy="0.0 0.0 -1.5707963267948966" xyz="0.08059312499999996 -0.06596812500000002 -0.0"/>
        <axis xyz="0 1 0"/>
        <limit lower="-1.047197551" upper="1.047197551" effort="0.948013269" velocity="6.338968228"/>
    </joint>
    <link name="insect_v1_root_link0_link1_link3">
        <inertial>
            <origin rpy="0.0 0.0 0.0" xyz="0.02573076923076922 7.993605777301122e-18 0.0"/>
            <mass value="7.800000e-02"/>
            <inertia ixx="2.396696e-05" ixy="0.000000e+00" ixz="0.000000e+00" iyy="3.656843e-05" iyz="0.000000e+00" izz="4.730539e-05"/>
        </inertial>
        <collision name="insect_v1_root_link0_link1_link3_geom0">
            <geometry>
                <box size="0.0583 0.0512 0.02"/>
            </geometry>
            <origin rpy="0.0 0.0 0.0" xyz="0.017999999999999988 7.993605777301122e-18 0.0"/>
        </collision>
        <collision name="insect_v1_root_link0_link1_link3_geom1">
            <geometry>
                <box size="0.002 0.053 0.053"/>
            </geometry>
            <origin rpy="0.0 0.0 0.0" xyz="0.048149999999999984 7.99360577730112e-18 0.0"/>
        </collision>
    </link>
</robot>
