<?xml version="1.0" ?>
<robot name="longleg_v1">
    <link name="longleg_v1_root">
        <inertial>
            <origin rpy="0.0 0.0 0.0" xyz="5.117766576636557e-19 0.002254789272030651 0.0"/>
            <mass value="2.610000e-01"/>
            <inertia ixx="2.714798e-04" ixy="1.393908e-37" ixz="-5.057991e-22" iyy="2.436446e-04" iyz="9.933154e-24" izz="3.630267e-04"/>
        </inertial>
        <collision name="longleg_v1_root_geom0">
            <geometry>
                <box size="0.089 0.089 0.0603"/>
            </geometry>
            <origin rpy="0.0 0.0 0.0" xyz="0.0 0.0 0.0"/>
        </collision>
        <collision name="longleg_v1_root_geom1">
            <geometry>
                <box size="0.018 0.053 0.0165891"/>
            </geometry>
            <origin rpy="1.5707963267948963 0.0 1.5707963267948963" xyz="1.214306433183765e-17 0.0535 0.0"/>
        </collision>
    </link>
    <joint type="revolute" name="longleg_v1_root_joint0">
        <parent link="longleg_v1_root"/>
        <child link="longleg_v1_root_link0"/>
        <origin rpy="1.5707963267948963 0.0 1.5707963267948963" xyz="1.734723475976807e-17 0.07902499999999998 0.0"/>
        <axis xyz="0 1 0"/>
        <limit lower="-1.047197551" upper="1.047197551" effort="0.948013269" velocity="6.338968228"/>
    </joint>
    <link name="longleg_v1_root_link0">
        <inertial>
            <origin rpy="0.0 0.0 0.0" xyz="0.029737640449438205 0.0 0.0"/>
            <mass value="8.900000e-02"/>
            <inertia ixx="2.679414e-05" ixy="0.000000e+00" ixz="0.000000e+00" iyy="4.724987e-05" iyz="0.000000e+00" izz="6.030948e-05"/>
        </inertial>
        <collision name="longleg_v1_root_link0_geom0">
            <geometry>
                <box size="0.0583 0.0512 0.02"/>
            </geometry>
            <origin rpy="0.0 0.0 0.0" xyz="0.018000000000000002 0.0 0.0"/>
        </collision>
        <collision name="longleg_v1_root_link0_geom1">
            <geometry>
                <box size="0.002 0.053 0.053"/>
            </geometry>
            <origin rpy="0.0 0.0 0.0" xyz="0.04815 -1.734723475976807e-18 -1.734723475976807e-18"/>
        </collision>
        <collision name="longleg_v1_root_link0_geom2">
            <geometry>
                <box size="0.018 0.053 0.0165891"/>
            </geometry>
            <origin rpy="0.0 0.0 0.0" xyz="0.05815000000000001 -1.734723475976807e-18 -5.204170427930421e-18"/>
        </collision>
    </link>
    <joint type="revolute" name="longleg_v1_root_link0_joint1">
        <parent link="longleg_v1_root_link0"/>
        <child link="longleg_v1_root_link0_link1"/>
        <origin rpy="0.0 0.0 0.0" xyz="0.083675 0.0 0.0"/>
        <axis xyz="0 1 0"/>
        <limit lower="-1.047197551" upper="1.047197551" effort="0.948013269" velocity="6.338968228"/>
    </joint>
    <link name="longleg_v1_root_link0_link1">
        <inertial>
            <origin rpy="0.0 0.0 0.0" xyz="0.02973764044943819 0.0 -3.469446951953614e-18"/>
            <mass value="8.900000e-02"/>
            <inertia ixx="2.679414e-05" ixy="0.000000e+00" ixz="0.000000e+00" iyy="4.724987e-05" iyz="0.000000e+00" izz="6.030948e-05"/>
        </inertial>
        <collision name="longleg_v1_root_link0_link1_geom0">
            <geometry>
                <box size="0.0583 0.0512 0.02"/>
            </geometry>
            <origin rpy="0.0 0.0 0.0" xyz="0.017999999999999988 0.0 -3.469446951953614e-18"/>
        </collision>
        <collision name="longleg_v1_root_link0_link1_geom1">
            <geometry>
                <box size="0.002 0.053 0.053"/>
            </geometry>
            <origin rpy="0.0 0.0 0.0" xyz="0.048149999999999984 0.0 -6.938893903907228e-18"/>
        </collision>
        <collision name="longleg_v1_root_link0_link1_geom2">
            <geometry>
                <box size="0.018 0.053 0.0165891"/>
            </geometry>
            <origin rpy="0.0 0.0 0.0" xyz="0.058149999999999986 0.0 -6.938893903907228e-18"/>
        </collision>
    </link>
    <joint type="revolute" name="longleg_v1_root_link0_link1_joint1">
        <parent link="longleg_v1_root_link0_link1"/>
        <child link="longleg_v1_root_link0_link1_link1"/>
        <origin rpy="0.0 0.0 0.0" xyz="0.08367499999999997 0.0 0.0"/>
        <axis xyz="0 1 0"/>
        <limit lower="-1.047197551" upper="1.047197551" effort="0.948013269" velocity="6.338968228"/>
    </joint>
    <link name="longleg_v1_root_link0_link1_link1">
        <inertial>
            <origin rpy="0.0 0.0 0.0" xyz="0.02973764044943822 0.0 -3.469446951953614e-18"/>
            <mass value="8.900000e-02"/>
            <inertia ixx="2.451623e-05" ixy="-5.057991e-22" ixz="0.000000e+00" iyy="4.952779e-05" iyz="0.000000e+00" izz="6.030948e-05"/>
        </inertial>
        <collision name="longleg_v1_root_link0_link1_link1_geom0">
            <geometry>
                <box size="0.0583 0.0512 0.02"/>
            </geometry>
            <origin rpy="0.0 0.0 0.0" xyz="0.018000000000000016 0.0 -3.469446951953614e-18"/>
        </collision>
        <collision name="longleg_v1_root_link0_link1_link1_geom1">
            <geometry>
                <box size="0.002 0.053 0.053"/>
            </geometry>
            <origin rpy="0.0 0.0 0.0" xyz="0.04815000000000001 0.0 -6.938893903907228e-18"/>
        </collision>
        <collision name="longleg_v1_root_link0_link1_link1_geom2">
            <geometry>
                <box size="0.018 0.053 0.0165891"/>
            </geometry>
            <origin rpy="-1.5707963267948966 0.0 0.0" xyz="0.058150000000000014 0.0 -6.938893903907228e-18"/>
        </collision>
    </link>
    <joint type="revolute" name="longleg_v1_root_link0_link1_link1_joint1">
        <parent link="longleg_v1_root_link0_link1_link1"/>
        <child link="longleg_v1_root_link0_link1_link1_link1"/>
        <origin rpy="-1.5707963267948966 0.0 0.0" xyz="0.083675 0.0 0.0"/>
        <axis xyz="0 1 0"/>
        <limit lower="-1.047197551" upper="1.047197551" effort="0.948013269" velocity="6.338968228"/>
    </joint>
    <link name="longleg_v1_root_link0_link1_link1_link1">
        <inertial>
            <origin rpy="0.0 0.0 0.0" xyz="0.02973764044943822 0.0 0.0"/>
            <mass value="8.900000e-02"/>
            <inertia ixx="2.679414e-05" ixy="0.000000e+00" ixz="0.000000e+00" iyy="4.724987e-05" iyz="0.000000e+00" izz="6.030948e-05"/>
        </inertial>
        <collision name="longleg_v1_root_link0_link1_link1_link1_geom0">
            <geometry>
                <box size="0.0583 0.0512 0.02"/>
            </geometry>
            <origin rpy="0.0 0.0 0.0" xyz="0.018000000000000016 3.469446951953614e-18 0.0"/>
        </collision>
        <collision name="longleg_v1_root_link0_link1_link1_link1_geom1">
            <geometry>
                <box size="0.002 0.053 0.053"/>
            </geometry>
            <origin rpy="0.0 0.0 0.0" xyz="0.04815000000000001 0.0 0.0"/>
        </collision>
        <collision name="longleg_v1_root_link0_link1_link1_link1_geom2">
            <geometry>
                <box size="0.018 0.053 0.0165891"/>
            </geometry>
            <origin rpy="0.0 0.0 0.0" xyz="0.05815000000000002 0.0 0.0"/>
        </collision>
    </link>
    <joint type="revolute" name="longleg_v1_root_link0_link1_link1_link1_joint1">
        <parent link="longleg_v1_root_link0_link1_link1_link1"/>
        <child link="longleg_v1_root_link0_link1_link1_link1_link1"/>
        <origin rpy="0.0 0.0 0.0" xyz="0.083675 6.938893903907228e-18 0.0"/>
        <axis xyz="0 1 0"/>
        <limit lower="-1.047197551" upper="1.047197551" effort="0.948013269" velocity="6.338968228"/>
    </joint>
    <link name="longleg_v1_root_link0_link1_link1_link1_link1">
        <inertial>
            <origin rpy="0.0 0.0 0.0" xyz="0.05339887411347519 3.469446951953614e-18 0.0"/>
            <mass value="1.410000e-01"/>
            <inertia ixx="8.513173e-05" ixy="1.393908e-37" ixz="-5.057991e-22" iyy="2.103277e-04" iyz="5.256654e-22" izz="2.578006e-04"/>
        </inertial>
        <collision name="longleg_v1_root_link0_link1_link1_link1_link1_geom0">
            <geometry>
                <box size="0.0583 0.0512 0.02"/>
            </geometry>
            <origin rpy="0.0 0.0 0.0" xyz="0.018000000000000016 3.469446951953614e-18 0.0"/>
        </collision>
        <collision name="longleg_v1_root_link0_link1_link1_link1_link1_geom1">
            <geometry>
                <box size="0.002 0.053 0.053"/>
            </geometry>
            <origin rpy="0.0 0.0 0.0" xyz="0.04815000000000001 0.0 0.0"/>
        </collision>
        <collision name="longleg_v1_root_link0_link1_link1_link1_link1_geom2">
            <geometry>
                <box size="0.06288625 0.06288625 0.0603"/>
            </geometry>
            <origin rpy="0.0 0.0 0.0" xyz="0.08059312500000002 6.938893903907228e-18 0.0"/>
        </collision>
        <collision name="longleg_v1_root_link0_link1_link1_link1_link1_geom3">
            <geometry>
                <box size="0.018 0.053 0.0165891"/>
            </geometry>
            <origin rpy="0.0 0.0 0.0" xyz="0.12103625000000001 0.0 0.0"/>
        </collision>
        <collision name="longleg_v1_root_link0_link1_link1_link1_link1_geom4">
            <geometry>
                <box size="0.018 0.053 0.0165891"/>
            </geometry>
            <origin rpy="1.5707963267948963 0.0 1.5707963267948963" xyz="0.080593125 0.04044312500000001 0.0"/>
        </collision>
        <collision name="longleg_v1_root_link0_link1_link1_link1_link1_geom5">
            <geometry>
                <box size="0.018 0.053 0.0165891"/>
            </geometry>
            <origin rpy="0.0 0.0 -1.5707963267948966" xyz="0.08059312500000002 -0.040443124999999996 0.0"/>
        </collision>
    </link>
    <joint type="revolute" name="longleg_v1_root_link0_link1_link1_link1_link1_joint1">
        <parent link="longleg_v1_root_link0_link1_link1_link1_link1"/>
        <child link="longleg_v1_root_link0_link1_link1_link1_link1_link1"/>
        <origin rpy="0.0 0.0 0.0" xyz="0.14656125000000003 0.0 0.0"/>
        <axis xyz="0 1 0"/>
        <limit lower="-1.047197551" upper="1.047197551" effort="0.948013269" velocity="6.338968228"/>
    </joint>
    <link name="longleg_v1_root_link0_link1_link1_link1_link1_link1">
        <inertial>
            <origin rpy="0.0 0.0 0.0" xyz="0.025730769230769245 1.734723475976807e-18 0.0"/>
            <mass value="7.800000e-02"/>
            <inertia ixx="2.396696e-05" ixy="0.000000e+00" ixz="0.000000e+00" iyy="3.656843e-05" iyz="0.000000e+00" izz="4.730539e-05"/>
        </inertial>
        <collision name="longleg_v1_root_link0_link1_link1_link1_link1_link1_geom0">
            <geometry>
                <box size="0.0583 0.0512 0.02"/>
            </geometry>
            <origin rpy="0.0 0.0 0.0" xyz="0.018000000000000016 3.469446951953614e-18 0.0"/>
        </collision>
        <collision name="longleg_v1_root_link0_link1_link1_link1_link1_link1_geom1">
            <geometry>
                <box size="0.002 0.053 0.053"/>
            </geometry>
            <origin rpy="0.0 0.0 0.0" xyz="0.04815000000000001 0.0 0.0"/>
        </collision>
    </link>
    <joint type="revolute" name="longleg_v1_root_link0_link1_link1_link1_link1_joint2">
        <parent link="longleg_v1_root_link0_link1_link1_link1_link1"/>
        <child link="longleg_v1_root_link0_link1_link1_link1_link1_link2"/>
        <origin rpy="1.5707963267948966 0.0 1.5707963267948966" xyz="0.08059312500000003 0.06596812499999999 0.0"/>
        <axis xyz="0 1 0"/>
        <limit lower="-1.047197551" upper="1.047197551" effort="0.948013269" velocity="6.338968228"/>
    </joint>
    <link name="longleg_v1_root_link0_link1_link1_link1_link1_link2">
        <inertial>
            <origin rpy="2.465190328815662e-32 0.0 0.0" xyz="0.02973764044943822 1.3096323621833204e-32 -6.116348408251943e-17"/>
            <mass value="8.900000e-02"/>
            <inertia ixx="2.451623e-05" ixy="-5.057991e-22" ixz="0.000000e+00" iyy="4.952779e-05" iyz="0.000000e+00" izz="6.030948e-05"/>
        </inertial>
        <collision name="longleg_v1_root_link0_link1_link1_link1_link1_link2_geom0">
            <geometry>
                <box size="0.0583 0.0512 0.02"/>
            </geometry>
            <origin rpy="2.465190328815662e-32 0.0 0.0" xyz="0.018000000000000016 1.2518544638517033e-32 -6.116348408251942e-17"/>
        </collision>
        <collision name="longleg_v1_root_link0_link1_link1_link1_link1_link2_geom1">
            <geometry>
                <box size="0.002 0.053 0.053"/>
            </geometry>
            <origin rpy="2.465190328815662e-32 0.0 0.0" xyz="0.04815000000000001 6.933347799794049e-33 -6.116348408251943e-17"/>
        </collision>
        <collision name="longleg_v1_root_link0_link1_link1_link1_link1_link2_geom2">
            <geometry>
                <box size="0.018 0.053 0.0165891"/>
            </geometry>
            <origin rpy="-1.5707963267948966 0.0 0.0" xyz="0.05815000000000002 6.933347799794049e-33 -6.116348408251943e-17"/>
        </collision>
    </link>
    <joint type="revolute" name="longleg_v1_root_link0_link1_link1_link1_link1_link2_joint1">
        <parent link="longleg_v1_root_link0_link1_link1_link1_link1_link2"/>
        <child link="longleg_v1_root_link0_link1_link1_link1_link1_link2_link1"/>
        <origin rpy="-1.5707963267948966 0.0 0.0" xyz="0.08367500000000003 9.244463733058732e-33 -8.17866485273308e-17"/>
        <axis xyz="0 1 0"/>
        <limit lower="-1.047197551" upper="1.047197551" effort="0.948013269" velocity="6.338968228"/>
    </joint>
    <link name="longleg_v1_root_link0_link1_link1_link1_link1_link2_link1">
        <inertial>
            <origin rpy="0.0 0.0 0.0" xyz="0.04767571153846152 5.6523328512615856e-18 1.0970096963229697e-33"/>
            <mass value="1.300000e-01"/>
            <inertia ixx="8.002664e-05" ixy="0.000000e+00" ixz="0.000000e+00" iyy="1.551974e-04" iyz="1.986631e-23" izz="2.026256e-04"/>
        </inertial>
        <collision name="longleg_v1_root_link0_link1_link1_link1_link1_link2_link1_geom0">
            <geometry>
                <box size="0.0583 0.0512 0.02"/>
            </geometry>
            <origin rpy="0.0 0.0 0.0" xyz="0.017999999999999988 5.652332851261586e-18 1.0970096963229698e-33"/>
        </collision>
        <collision name="longleg_v1_root_link0_link1_link1_link1_link1_link2_link1_geom1">
            <geometry>
                <box size="0.002 0.053 0.053"/>
            </geometry>
            <origin rpy="0.0 0.0 0.0" xyz="0.048149999999999984 5.652332851261584e-18 1.0970096963229697e-33"/>
        </collision>
        <collision name="longleg_v1_root_link0_link1_link1_link1_link1_link2_link1_geom2">
            <geometry>
                <box size="0.06288625 0.06288625 0.0603"/>
            </geometry>
            <origin rpy="0.0 0.0 0.0" xyz="0.08059312499999999 5.6523328512615856e-18 1.0970096963229698e-33"/>
        </collision>
        <collision name="longleg_v1_root_link0_link1_link1_link1_link1_link2_link1_geom3">
            <geometry>
                <box size="0.018 0.053 0.0165891"/>
            </geometry>
            <origin rpy="1.5707963267948963 0.0 1.5707963267948963" xyz="0.08059312499999999 0.04044312500000002 1.0970096963229698e-33"/>
        </collision>
        <collision name="longleg_v1_root_link0_link1_link1_link1_link1_link2_link1_geom4">
            <geometry>
                <box size="0.018 0.053 0.0165891"/>
            </geometry>
            <origin rpy="1.5707963267948966 0.0 -1.5707963267948966" xyz="0.08059312499999999 -0.04044312499999999 1.0970096963229698e-33"/>
        </collision>
    </link>
    <joint type="revolute" name="longleg_v1_root_link0_link1_link1_link1_link1_link2_link1_joint1">
        <parent link="longleg_v1_root_link0_link1_link1_link1_link1_link2_link1"/>
        <child link="longleg_v1_root_link0_link1_link1_link1_link1_link2_link1_link1"/>
        <origin rpy="1.5707963267948963 0.0 1.5707963267948963" xyz="0.08059312499999999 0.06596812500000002 1.0970096963229695e-33"/>
        <axis xyz="0 1 0"/>
        <limit lower="-1.047197551" upper="1.047197551" effort="0.948013269" velocity="6.338968228"/>
    </joint>
    <link name="longleg_v1_root_link0_link1_link1_link1_link1_link2_link1_link1">
        <inertial>
            <origin rpy="1.1102230246251563e-16 0.0 0.0" xyz="0.029737640449438166 0.0 -1.0408340855860843e-17"/>
            <mass value="8.900000e-02"/>
            <inertia ixx="2.679414e-05" ixy="0.000000e+00" ixz="0.000000e+00" iyy="4.724987e-05" iyz="0.000000e+00" izz="6.030948e-05"/>
        </inertial>
        <collision name="longleg_v1_root_link0_link1_link1_link1_link1_link2_link1_link1_geom0">
            <geometry>
                <box size="0.0583 0.0512 0.02"/>
            </geometry>
            <origin rpy="1.1102230246251563e-16 0.0 0.0" xyz="0.01799999999999996 0.0 -1.0408340855860843e-17"/>
        </collision>
        <collision name="longleg_v1_root_link0_link1_link1_link1_link1_link2_link1_link1_geom1">
            <geometry>
                <box size="0.002 0.053 0.053"/>
            </geometry>
            <origin rpy="1.1102230246251563e-16 0.0 0.0" xyz="0.04814999999999998 0.0 -1.0408340855860843e-17"/>
        </collision>
        <collision name="longleg_v1_root_link0_link1_link1_link1_link1_link2_link1_link1_geom2">
            <geometry>
                <box size="0.018 0.053 0.0165891"/>
            </geometry>
            <origin rpy="1.1102230246251563e-16 0.0 0.0" xyz="0.05814999999999997 -3.469446951953614e-18 -1.0408340855860843e-17"/>
        </collision>
    </link>
    <joint type="revolute" name="longleg_v1_root_link0_link1_link1_link1_link1_link2_link1_link1_joint1">
        <parent link="longleg_v1_root_link0_link1_link1_link1_link1_link2_link1_link1"/>
        <child link="longleg_v1_root_link0_link1_link1_link1_link1_link2_link1_link1_link1"/>
        <origin rpy="1.1102230246251563e-16 0.0 0.0" xyz="0.08367499999999994 6.938893903907228e-18 -2.0816681711721685e-17"/>
        <axis xyz="0 1 0"/>
        <limit lower="-1.047197551" upper="1.047197551" effort="0.948013269" velocity="6.338968228"/>
    </joint>
    <link name="longleg_v1_root_link0_link1_link1_link1_link1_link2_link1_link1_link1">
        <inertial>
            <origin rpy="1.1102230246251563e-16 0.0 0.0" xyz="0.02573076923076925 -6.938893903907228e-18 1.734723475976807e-17"/>
            <mass value="7.800000e-02"/>
            <inertia ixx="2.396696e-05" ixy="0.000000e+00" ixz="0.000000e+00" iyy="3.656843e-05" iyz="0.000000e+00" izz="4.730539e-05"/>
        </inertial>
        <collision name="longleg_v1_root_link0_link1_link1_link1_link1_link2_link1_link1_link1_geom0">
            <geometry>
                <box size="0.0583 0.0512 0.02"/>
            </geometry>
            <origin rpy="1.1102230246251563e-16 0.0 0.0" xyz="0.018000000000000016 -6.938893903907228e-18 1.734723475976807e-17"/>
        </collision>
        <collision name="longleg_v1_root_link0_link1_link1_link1_link1_link2_link1_link1_link1_geom1">
            <geometry>
                <box size="0.002 0.053 0.053"/>
            </geometry>
            <origin rpy="1.1102230246251563e-16 0.0 0.0" xyz="0.048150000000000026 -6.938893903907228e-18 1.734723475976807e-17"/>
        </collision>
    </link>
    <joint type="revolute" name="longleg_v1_root_link0_link1_link1_link1_link1_link2_link1_joint2">
        <parent link="longleg_v1_root_link0_link1_link1_link1_link1_link2_link1"/>
        <child link="longleg_v1_root_link0_link1_link1_link1_link1_link2_link1_link2"/>
        <origin rpy="1.5707963267948966 0.0 -1.5707963267948966" xyz="0.08059312499999999 -0.06596812500000002 1.0970096963229702e-33"/>
        <axis xyz="0 1 0"/>
        <limit lower="-1.047197551" upper="1.047197551" effort="0.948013269" velocity="6.338968228"/>
    </joint>
    <link name="longleg_v1_root_link0_link1_link1_link1_link1_link2_link1_link2">
        <inertial>
            <origin rpy="1.1102230246251565e-16 0.0 0.0" xyz="0.02573076923076925 0.0 -1.0408340855860843e-17"/>
            <mass value="7.800000e-02"/>
            <inertia ixx="2.396696e-05" ixy="0.000000e+00" ixz="0.000000e+00" iyy="3.656843e-05" iyz="0.000000e+00" izz="4.730539e-05"/>
        </inertial>
        <collision name="longleg_v1_root_link0_link1_link1_link1_link1_link2_link1_link2_geom0">
            <geometry>
                <box size="0.0583 0.0512 0.02"/>
            </geometry>
            <origin rpy="1.1102230246251565e-16 0.0 0.0" xyz="0.018000000000000016 0.0 -1.0408340855860843e-17"/>
        </collision>
        <collision name="longleg_v1_root_link0_link1_link1_link1_link1_link2_link1_link2_geom1">
            <geometry>
                <box size="0.002 0.053 0.053"/>
            </geometry>
            <origin rpy="1.1102230246251565e-16 0.0 0.0" xyz="0.04815000000000003 0.0 -1.0408340855860843e-17"/>
        </collision>
    </link>
    <joint type="revolute" name="longleg_v1_root_link0_link1_link1_link1_link1_joint3">
        <parent link="longleg_v1_root_link0_link1_link1_link1_link1"/>
        <child link="longleg_v1_root_link0_link1_link1_link1_link1_link3"/>
        <origin rpy="0.0 0.0 -1.5707963267948966" xyz="0.08059312499999999 -0.065968125 0.0"/>
        <axis xyz="0 1 0"/>
        <limit lower="-1.047197551" upper="1.047197551" effort="0.948013269" velocity="6.338968228"/>
    </joint>
    <link name="longleg_v1_root_link0_link1_link1_link1_link1_link3">
        <inertial>
            <origin rpy="0.0 0.0 0.0" xyz="0.02573076923076922 7.993605777301122e-18 0.0"/>
            <mass value="7.800000e-02"/>
            <inertia ixx="2.396696e-05" ixy="0.000000e+00" ixz="0.000000e+00" iyy="3.656843e-05" iyz="0.000000e+00" izz="4.730539e-05"/>
        </inertial>
        <collision name="longleg_v1_root_link0_link1_link1_link1_link1_link3_geom0">
            <geometry>
                <box size="0.0583 0.0512 0.02"/>
            </geometry>
            <origin rpy="0.0 0.0 0.0" xyz="0.017999999999999988 7.993605777301122e-18 0.0"/>
        </collision>
        <collision name="longleg_v1_root_link0_link1_link1_link1_link1_link3_geom1">
            <geometry>
                <box size="0.002 0.053 0.053"/>
            </geometry>
            <origin rpy="0.0 0.0 0.0" xyz="0.048149999999999984 7.99360577730112e-18 -0.0"/>
        </collision>
    </link>
</robot>
