<?xml version="1.0" ?>
<robot name="pentapod_v1">
    <link name="pentapod_v1_root">
        <inertial>
            <origin rpy="0.0 0.0 0.0" xyz="-5.117766576636557e-19 -0.002254789272030651 0.0"/>
            <mass value="2.610000e-01"/>
            <inertia ixx="2.714798e-04" ixy="-1.393908e-37" ixz="5.057991e-22" iyy="2.436446e-04" iyz="9.933154e-24" izz="3.630267e-04"/>
        </inertial>
        <collision name="pentapod_v1_root_geom0">
            <geometry>
                <box size="0.089 0.089 0.0603"/>
            </geometry>
            <origin rpy="0.0 0.0 0.0" xyz="0.0 0.0 0.0"/>
        </collision>
        <collision name="pentapod_v1_root_geom1">
            <geometry>
                <box size="0.018 0.053 0.0165891"/>
            </geometry>
            <origin rpy="1.5707963267948966 0.0 -1.5707963267948966" xyz="-1.214306433183765e-17 -0.0535 0.0"/>
        </collision>
    </link>
    <joint type="revolute" name="pentapod_v1_root_joint0">
        <parent link="pentapod_v1_root"/>
        <child link="pentapod_v1_root_link0"/>
        <origin rpy="1.5707963267948966 0.0 -1.5707963267948966" xyz="-1.734723475976807e-17 -0.07902499999999998 0.0"/>
        <axis xyz="0 1 0"/>
        <limit lower="-1.047197551" upper="1.047197551" effort="0.948013269" velocity="6.338968228"/>
    </joint>
    <link name="pentapod_v1_root_link0">
        <inertial>
            <origin rpy="0.0 0.0 0.0" xyz="0.029737640449438205 0.0 0.0"/>
            <mass value="8.900000e-02"/>
            <inertia ixx="2.679414e-05" ixy="0.000000e+00" ixz="0.000000e+00" iyy="4.724987e-05" iyz="0.000000e+00" izz="6.030948e-05"/>
        </inertial>
        <collision name="pentapod_v1_root_link0_geom0">
            <geometry>
                <box size="0.0583 0.0512 0.02"/>
            </geometry>
            <origin rpy="0.0 0.0 0.0" xyz="0.018000000000000002 0.0 0.0"/>
        </collision>
        <collision name="pentapod_v1_root_link0_geom1">
            <geometry>
                <box size="0.002 0.053 0.053"/>
            </geometry>
            <origin rpy="0.0 0.0 0.0" xyz="0.04815 -1.734723475976807e-18 -1.734723475976807e-18"/>
        </collision>
        <collision name="pentapod_v1_root_link0_geom2">
            <geometry>
                <box size="0.018 0.053 0.0165891"/>
            </geometry>
            <origin rpy="0.0 0.0 0.0" xyz="0.05815 -1.734723475976807e-18 -5.204170427930421e-18"/>
        </collision>
    </link>
    <joint type="revolute" name="pentapod_v1_root_link0_joint1">
        <parent link="pentapod_v1_root_link0"/>
        <child link="pentapod_v1_root_link0_link1"/>
        <origin rpy="0.0 0.0 0.0" xyz="0.083675 0.0 0.0"/>
        <axis xyz="0 1 0"/>
        <limit lower="-1.047197551" upper="1.047197551" effort="0.948013269" velocity="6.338968228"/>
    </joint>
    <link name="pentapod_v1_root_link0_link1">
        <inertial>
            <origin rpy="0.0 0.0 0.0" xyz="0.02973764044943819 0.0 -3.469446951953614e-18"/>
            <mass value="8.900000e-02"/>
            <inertia ixx="2.679414e-05" ixy="0.000000e+00" ixz="0.000000e+00" iyy="4.724987e-05" iyz="0.000000e+00" izz="6.030948e-05"/>
        </inertial>
        <collision name="pentapod_v1_root_link0_link1_geom0">
            <geometry>
                <box size="0.0583 0.0512 0.02"/>
            </geometry>
            <origin rpy="0.0 0.0 0.0" xyz="0.017999999999999988 0.0 -3.469446951953614e-18"/>
        </collision>
        <collision name="pentapod_v1_root_link0_link1_geom1">
            <geometry>
                <box size="0.002 0.053 0.053"/>
            </geometry>
            <origin rpy="0.0 0.0 0.0" xyz="0.048149999999999984 0.0 -6.938893903907228e-18"/>
        </collision>
        <collision name="pentapod_v1_root_link0_link1_geom2">
            <geometry>
                <box size="0.018 0.053 0.0165891"/>
            </geometry>
            <origin rpy="0.0 0.0 0.0" xyz="0.05814999999999998 0.0 -6.938893903907228e-18"/>
        </collision>
    </link>
    <joint type="revolute" name="pentapod_v1_root_link0_link1_joint1">
        <parent link="pentapod_v1_root_link0_link1"/>
        <child link="pentapod_v1_root_link0_link1_link1"/>
        <origin rpy="0.0 0.0 0.0" xyz="0.08367499999999997 0.0 0.0"/>
        <axis xyz="0 1 0"/>
        <limit lower="-1.047197551" upper="1.047197551" effort="0.948013269" velocity="6.338968228"/>
    </joint>
    <link name="pentapod_v1_root_link0_link1_link1">
        <inertial>
            <origin rpy="0.0 0.0 0.0" xyz="0.02973764044943822 0.0 -3.469446951953614e-18"/>
            <mass value="8.900000e-02"/>
            <inertia ixx="2.451623e-05" ixy="-5.057991e-22" ixz="0.000000e+00" iyy="4.952779e-05" iyz="0.000000e+00" izz="6.030948e-05"/>
        </inertial>
        <collision name="pentapod_v1_root_link0_link1_link1_geom0">
            <geometry>
                <box size="0.0583 0.0512 0.02"/>
            </geometry>
            <origin rpy="0.0 0.0 0.0" xyz="0.018000000000000016 0.0 -3.469446951953614e-18"/>
        </collision>
        <collision name="pentapod_v1_root_link0_link1_link1_geom1">
            <geometry>
                <box size="0.002 0.053 0.053"/>
            </geometry>
            <origin rpy="0.0 0.0 0.0" xyz="0.04815000000000001 0.0 -6.938893903907228e-18"/>
        </collision>
        <collision name="pentapod_v1_root_link0_link1_link1_geom2">
            <geometry>
                <box size="0.018 0.053 0.0165891"/>
            </geometry>
            <origin rpy="-1.5707963267948966 0.0 0.0" xyz="0.05815000000000002 0.0 -6.938893903907228e-18"/>
        </collision>
    </link>
    <joint type="revolute" name="pentapod_v1_root_link0_link1_link1_joint1">
        <parent link="pentapod_v1_root_link0_link1_link1"/>
        <child link="pentapod_v1_root_link0_link1_link1_link1"/>
        <origin rpy="-1.5707963267948966 0.0 0.0" xyz="0.083675 0.0 0.0"/>
        <axis xyz="0 1 0"/>
        <limit lower="-1.047197551" upper="1.047197551" effort="0.948013269" velocity="6.338968228"/>
    </joint>
    <link name="pentapod_v1_root_link0_link1_link1_link1">
        <inertial>
            <origin rpy="0.0 0.0 0.0" xyz="0.05109782211538462 0.0034221105769230813 -0.0"/>
            <mass value="1.300000e-01"/>
            <inertia ixx="6.279003e-05" ixy="5.057991e-22" ixz="0.000000e+00" iyy="2.009106e-04" iyz="5.157323e-22" izz="2.266358e-04"/>
        </inertial>
        <collision name="pentapod_v1_root_link0_link1_link1_link1_geom0">
            <geometry>
                <box size="0.0583 0.0512 0.02"/>
            </geometry>
            <origin rpy="0.0 0.0 0.0" xyz="0.018000000000000016 3.469446951953614e-18 -0.0"/>
        </collision>
        <collision name="pentapod_v1_root_link0_link1_link1_link1_geom1">
            <geometry>
                <box size="0.002 0.053 0.053"/>
            </geometry>
            <origin rpy="0.0 0.0 0.0" xyz="0.04815000000000001 0.0 -0.0"/>
        </collision>
        <collision name="pentapod_v1_root_link0_link1_link1_link1_geom2">
            <geometry>
                <box size="0.06288625 0.06288625 0.0603"/>
            </geometry>
            <origin rpy="0.0 0.0 0.0" xyz="0.08059312500000002 6.938893903907228e-18 -0.0"/>
        </collision>
        <collision name="pentapod_v1_root_link0_link1_link1_link1_geom3">
            <geometry>
                <box size="0.018 0.053 0.0165891"/>
            </geometry>
            <origin rpy="1.5707963267948966 0.0 0.0" xyz="0.12103625000000001 0.0 -0.0"/>
        </collision>
        <collision name="pentapod_v1_root_link0_link1_link1_link1_geom4">
            <geometry>
                <box size="0.018 0.053 0.0165891"/>
            </geometry>
            <origin rpy="0.0 0.0 1.5707963267948966" xyz="0.080593125 0.04044312500000001 -0.0"/>
        </collision>
    </link>
    <joint type="revolute" name="pentapod_v1_root_link0_link1_link1_link1_joint1">
        <parent link="pentapod_v1_root_link0_link1_link1_link1"/>
        <child link="pentapod_v1_root_link0_link1_link1_link1_link1"/>
        <origin rpy="1.5707963267948966 0.0 0.0" xyz="0.14656124999999998 0.0 -0.0"/>
        <axis xyz="0 1 0"/>
        <limit lower="-1.047197551" upper="1.047197551" effort="0.948013269" velocity="6.338968228"/>
    </joint>
    <link name="pentapod_v1_root_link0_link1_link1_link1_link1">
        <inertial>
            <origin rpy="0.0 0.0 0.0" xyz="0.056628191406250014 0.0 -0.00901070703125001"/>
            <mass value="1.600000e-01"/>
            <inertia ixx="1.920581e-04" ixy="1.867864e-22" ixz="6.925855e-22" iyy="3.624121e-04" iyz="1.116500e-36" izz="2.503486e-04"/>
        </inertial>
        <collision name="pentapod_v1_root_link0_link1_link1_link1_link1_geom0">
            <geometry>
                <box size="0.0583 0.0512 0.02"/>
            </geometry>
            <origin rpy="0.0 0.0 0.0" xyz="0.018000000000000016 0.0 -3.469446951953614e-18"/>
        </collision>
        <collision name="pentapod_v1_root_link0_link1_link1_link1_link1_geom1">
            <geometry>
                <box size="0.002 0.053 0.053"/>
            </geometry>
            <origin rpy="0.0 0.0 0.0" xyz="0.04815000000000001 0.0 -6.938893903907228e-18"/>
        </collision>
        <collision name="pentapod_v1_root_link0_link1_link1_link1_link1_geom2">
            <geometry>
                <box size="0.06288625 0.06288625 0.0603"/>
            </geometry>
            <origin rpy="-1.5707963267948966 0.0 0.0" xyz="0.08059312500000002 0.0 0.0"/>
        </collision>
        <collision name="pentapod_v1_root_link0_link1_link1_link1_link1_geom3">
            <geometry>
                <box size="0.018 0.053 0.0165891"/>
            </geometry>
            <origin rpy="0.0 0.0 0.0" xyz="0.12103625000000001 0.0 0.0"/>
        </collision>
        <collision name="pentapod_v1_root_link0_link1_link1_link1_link1_geom4">
            <geometry>
                <box size="0.06288625 0.06288625 0.0603"/>
            </geometry>
            <origin rpy="-1.5707963267948966 1.5707963267948966 0.0" xyz="0.08059312500000002 8.673617379884035e-19 -0.06288625"/>
        </collision>
        <collision name="pentapod_v1_root_link0_link1_link1_link1_link1_geom5">
            <geometry>
                <box size="0.018 0.053 0.0165891"/>
            </geometry>
            <origin rpy="-1.5707963267948966 -1.5707963267948963 0.0" xyz="0.08059312500000002 -1.0408340855860843e-17 0.040443125"/>
        </collision>
    </link>
    <joint type="revolute" name="pentapod_v1_root_link0_link1_link1_link1_link1_joint1">
        <parent link="pentapod_v1_root_link0_link1_link1_link1_link1"/>
        <child link="pentapod_v1_root_link0_link1_link1_link1_link1_link1"/>
        <origin rpy="0.0 0.0 0.0" xyz="0.14656124999999998 0.0 0.0"/>
        <axis xyz="0 1 0"/>
        <limit lower="-1.047197551" upper="1.047197551" effort="0.948013269" velocity="6.338968228"/>
    </joint>
    <link name="pentapod_v1_root_link0_link1_link1_link1_link1_link1">
        <inertial>
            <origin rpy="0.0 0.0 0.0" xyz="0.04767571153846155 0.0 -6.938893903907228e-18"/>
            <mass value="1.300000e-01"/>
            <inertia ixx="8.467194e-05" ixy="1.986631e-23" ixz="1.031465e-21" iyy="1.910921e-04" iyz="2.831928e-37" izz="1.620855e-04"/>
        </inertial>
        <collision name="pentapod_v1_root_link0_link1_link1_link1_link1_link1_geom0">
            <geometry>
                <box size="0.0583 0.0512 0.02"/>
            </geometry>
            <origin rpy="0.0 0.0 0.0" xyz="0.018000000000000016 0.0 -3.469446951953614e-18"/>
        </collision>
        <collision name="pentapod_v1_root_link0_link1_link1_link1_link1_link1_geom1">
            <geometry>
                <box size="0.002 0.053 0.053"/>
            </geometry>
            <origin rpy="0.0 0.0 0.0" xyz="0.04815000000000001 0.0 -6.938893903907228e-18"/>
        </collision>
        <collision name="pentapod_v1_root_link0_link1_link1_link1_link1_link1_geom2">
            <geometry>
                <box size="0.06288625 0.06288625 0.0603"/>
            </geometry>
            <origin rpy="-1.5707963267948966 0.0 0.0" xyz="0.08059312500000002 0.0 0.0"/>
        </collision>
        <collision name="pentapod_v1_root_link0_link1_link1_link1_link1_link1_geom3">
            <geometry>
                <box size="0.018 0.053 0.0165891"/>
            </geometry>
            <origin rpy="-1.5707963267948966 1.5707963267948966 0.0" xyz="0.08059312500000002 1.214306433183765e-17 -0.04044312500000001"/>
        </collision>
        <collision name="pentapod_v1_root_link0_link1_link1_link1_link1_link1_geom4">
            <geometry>
                <box size="0.018 0.053 0.0165891"/>
            </geometry>
            <origin rpy="-1.5707963267948966 -1.5707963267948963 0.0" xyz="0.08059312500000002 -1.0408340855860843e-17 0.040443125"/>
        </collision>
    </link>
    <joint type="revolute" name="pentapod_v1_root_link0_link1_link1_link1_link1_link1_joint1">
        <parent link="pentapod_v1_root_link0_link1_link1_link1_link1_link1"/>
        <child link="pentapod_v1_root_link0_link1_link1_link1_link1_link1_link1"/>
        <origin rpy="-1.5707963267948966 1.5707963267948966 0.0" xyz="0.08059312500000003 3.469446951953614e-18 -0.065968125"/>
        <axis xyz="0 1 0"/>
        <limit lower="-1.047197551" upper="1.047197551" effort="0.948013269" velocity="6.338968228"/>
    </joint>
    <link name="pentapod_v1_root_link0_link1_link1_link1_link1_link1_link1">
        <inertial>
            <origin rpy="0.0 0.0 0.0" xyz="0.025730769230769248 7.993605777301134e-18 3.469446951953614e-18"/>
            <mass value="7.800000e-02"/>
            <inertia ixx="2.396696e-05" ixy="0.000000e+00" ixz="0.000000e+00" iyy="3.656843e-05" iyz="0.000000e+00" izz="4.730539e-05"/>
        </inertial>
        <collision name="pentapod_v1_root_link0_link1_link1_link1_link1_link1_link1_geom0">
            <geometry>
                <box size="0.0583 0.0512 0.02"/>
            </geometry>
            <origin rpy="0.0 0.0 0.0" xyz="0.018000000000000016 7.993605777301134e-18 3.469446951953614e-18"/>
        </collision>
        <collision name="pentapod_v1_root_link0_link1_link1_link1_link1_link1_link1_geom1">
            <geometry>
                <box size="0.002 0.053 0.053"/>
            </geometry>
            <origin rpy="0.0 0.0 0.0" xyz="0.04815000000000001 7.993605777301133e-18 3.469446951953614e-18"/>
        </collision>
    </link>
    <joint type="revolute" name="pentapod_v1_root_link0_link1_link1_link1_link1_link1_joint2">
        <parent link="pentapod_v1_root_link0_link1_link1_link1_link1_link1"/>
        <child link="pentapod_v1_root_link0_link1_link1_link1_link1_link1_link2"/>
        <origin rpy="-1.5707963267948966 -1.5707963267948963 0.0" xyz="0.08059312500000006 -1.3877787807814457e-17 0.065968125"/>
        <axis xyz="0 1 0"/>
        <limit lower="-1.047197551" upper="1.047197551" effort="0.948013269" velocity="6.338968228"/>
    </joint>
    <link name="pentapod_v1_root_link0_link1_link1_link1_link1_link1_link2">
        <inertial>
            <origin rpy="0.0 0.0 0.0" xyz="0.025730769230769248 7.993605777301134e-18 0.0"/>
            <mass value="7.800000e-02"/>
            <inertia ixx="2.396696e-05" ixy="0.000000e+00" ixz="0.000000e+00" iyy="3.656843e-05" iyz="0.000000e+00" izz="4.730539e-05"/>
        </inertial>
        <collision name="pentapod_v1_root_link0_link1_link1_link1_link1_link1_link2_geom0">
            <geometry>
                <box size="0.0583 0.0512 0.02"/>
            </geometry>
            <origin rpy="0.0 0.0 0.0" xyz="0.018000000000000016 7.993605777301134e-18 0.0"/>
        </collision>
        <collision name="pentapod_v1_root_link0_link1_link1_link1_link1_link1_link2_geom1">
            <geometry>
                <box size="0.002 0.053 0.053"/>
            </geometry>
            <origin rpy="0.0 0.0 0.0" xyz="0.04815000000000001 7.993605777301133e-18 0.0"/>
        </collision>
    </link>
    <joint type="revolute" name="pentapod_v1_root_link0_link1_link1_link1_link1_joint2">
        <parent link="pentapod_v1_root_link0_link1_link1_link1_link1"/>
        <child link="pentapod_v1_root_link0_link1_link1_link1_link1_link2"/>
        <origin rpy="-1.5707963267948966 -1.5707963267948963 0.0" xyz="0.08059312500000006 -1.3877787807814457e-17 0.065968125"/>
        <axis xyz="0 1 0"/>
        <limit lower="-1.047197551" upper="1.047197551" effort="0.948013269" velocity="6.338968228"/>
    </joint>
    <link name="pentapod_v1_root_link0_link1_link1_link1_link1_link2">
        <inertial>
            <origin rpy="0.0 0.0 0.0" xyz="0.025730769230769248 7.993605777301134e-18 0.0"/>
            <mass value="7.800000e-02"/>
            <inertia ixx="2.396696e-05" ixy="0.000000e+00" ixz="0.000000e+00" iyy="3.656843e-05" iyz="0.000000e+00" izz="4.730539e-05"/>
        </inertial>
        <collision name="pentapod_v1_root_link0_link1_link1_link1_link1_link2_geom0">
            <geometry>
                <box size="0.0583 0.0512 0.02"/>
            </geometry>
            <origin rpy="0.0 0.0 0.0" xyz="0.018000000000000016 7.993605777301134e-18 0.0"/>
        </collision>
        <collision name="pentapod_v1_root_link0_link1_link1_link1_link1_link2_geom1">
            <geometry>
                <box size="0.002 0.053 0.053"/>
            </geometry>
            <origin rpy="0.0 0.0 0.0" xyz="0.04815000000000001 7.993605777301133e-18 0.0"/>
        </collision>
    </link>
    <joint type="revolute" name="pentapod_v1_root_link0_link1_link1_link1_joint2">
        <parent link="pentapod_v1_root_link0_link1_link1_link1"/>
        <child link="pentapod_v1_root_link0_link1_link1_link1_link2"/>
        <origin rpy="0.0 0.0 1.5707963267948966" xyz="0.08059312500000003 0.06596812499999999 -0.0"/>
        <axis xyz="0 1 0"/>
        <limit lower="-1.047197551" upper="1.047197551" effort="0.948013269" velocity="6.338968228"/>
    </joint>
    <link name="pentapod_v1_root_link0_link1_link1_link1_link2">
        <inertial>
            <origin rpy="0.0 0.0 0.0" xyz="0.02573076923076922 7.993605777301122e-18 0.0"/>
            <mass value="7.800000e-02"/>
            <inertia ixx="2.396696e-05" ixy="0.000000e+00" ixz="0.000000e+00" iyy="3.656843e-05" iyz="0.000000e+00" izz="4.730539e-05"/>
        </inertial>
        <collision name="pentapod_v1_root_link0_link1_link1_link1_link2_geom0">
            <geometry>
                <box size="0.0583 0.0512 0.02"/>
            </geometry>
            <origin rpy="0.0 0.0 0.0" xyz="0.017999999999999988 7.993605777301122e-18 0.0"/>
        </collision>
        <collision name="pentapod_v1_root_link0_link1_link1_link1_link2_geom1">
            <geometry>
                <box size="0.002 0.053 0.053"/>
            </geometry>
            <origin rpy="0.0 0.0 0.0" xyz="0.048149999999999984 7.99360577730112e-18 -0.0"/>
        </collision>
    </link>
</robot>
