<?xml version="1.0" ?>
<robot name="salamander_v1">
    <link name="salamander_v1_root">
        <inertial>
            <origin rpy="0.0 0.0 0.0" xyz="-0.0020795053003533565 3.831103082987648e-19 -1.8714866950759355e-36"/>
            <mass value="2.830000e-01"/>
            <inertia ixx="3.076679e-04" ixy="-5.057991e-22" ixz="-5.057991e-22" iyy="2.796047e-04" iyz="5.201870e-22" izz="4.295205e-04"/>
        </inertial>
        <collision name="salamander_v1_root_geom0">
            <geometry>
                <box size="0.089 0.089 0.0603"/>
            </geometry>
            <origin rpy="0.0 0.0 0.0" xyz="0.0 0.0 0.0"/>
        </collision>
        <collision name="salamander_v1_root_geom1">
            <geometry>
                <box size="0.018 0.053 0.0165891"/>
            </geometry>
            <origin rpy="1.5707963267948966 0.0 3.141592653589793" xyz="-0.0535 6.551860375438339e-18 -4.81482486096809e-35"/>
        </collision>
        <collision name="salamander_v1_root_geom2">
            <geometry>
                <box size="0.018 0.053 0.0165891"/>
            </geometry>
            <origin rpy="1.5707963267948963 0.0 1.5707963267948963" xyz="1.214306433183765e-17 0.0535 0.0"/>
        </collision>
        <collision name="salamander_v1_root_geom3">
            <geometry>
                <box size="0.018 0.053 0.0165891"/>
            </geometry>
            <origin rpy="0.0 0.0 -1.5707963267948966" xyz="-1.214306433183765e-17 -0.0535 0.0"/>
        </collision>
    </link>
    <joint type="revolute" name="salamander_v1_root_joint0">
        <parent link="salamander_v1_root"/>
        <child link="salamander_v1_root_link0"/>
        <origin rpy="1.5707963267948966 0.0 3.141592653589793" xyz="-0.07902499999999998 9.677771330261958e-18 -1.925929944387236e-34"/>
        <axis xyz="0 1 0"/>
        <limit lower="-1.047197551" upper="1.047197551" effort="0.948013269" velocity="6.338968228"/>
    </joint>
    <link name="salamander_v1_root_link0">
        <inertial>
            <origin rpy="3.749399456654644e-33 0.0 0.0" xyz="0.07729309941520468 1.499056931886811e-18 -0.005203209064327485"/>
            <mass value="1.710000e-01"/>
            <inertia ixx="1.018465e-04" ixy="1.986631e-23" ixz="1.031465e-21" iyy="6.245773e-04" iyz="2.831928e-37" izz="6.033194e-04"/>
        </inertial>
        <collision name="salamander_v1_root_link0_geom0">
            <geometry>
                <box size="0.0583 0.0512 0.02"/>
            </geometry>
            <origin rpy="3.749399456654644e-33 0.0 0.0" xyz="0.018000000000000016 9.62964972193618e-35 -2.311115933264683e-33"/>
        </collision>
        <collision name="salamander_v1_root_link0_geom1">
            <geometry>
                <box size="0.002 0.053 0.053"/>
            </geometry>
            <origin rpy="3.749399456654644e-33 0.0 0.0" xyz="0.04815000000000001 -5.7777898331617076e-34 -2.1185229388259594e-33"/>
        </collision>
        <collision name="salamander_v1_root_link0_geom2">
            <geometry>
                <box size="0.06288625 0.06288625 0.0603"/>
            </geometry>
            <origin rpy="-1.5707963267948966 0.0 0.0" xyz="0.08059312500000002 -7.703719777548943e-34 -1.925929944387236e-33"/>
        </collision>
        <collision name="salamander_v1_root_link0_geom3">
            <geometry>
                <box size="0.06288625 0.06288625 0.0603"/>
            </geometry>
            <origin rpy="-1.5707963267948966 0.0 0.0" xyz="0.14347937500000002 -7.703719777548943e-34 7.703719777548943e-34"/>
        </collision>
        <collision name="salamander_v1_root_link0_geom4">
            <geometry>
                <box size="0.018 0.053 0.0165891"/>
            </geometry>
            <origin rpy="-1.5707963267948966 1.5707963267948966 0.0" xyz="0.08059312500000002 2.4674528141133143e-18 -0.040443125"/>
        </collision>
        <collision name="salamander_v1_root_link0_geom5">
            <geometry>
                <box size="0.018 0.053 0.0165891"/>
            </geometry>
            <origin rpy="3.749399456654644e-33 0.0 0.0" xyz="0.18392250000000004 7.703719777548943e-34 0.0"/>
        </collision>
        <collision name="salamander_v1_root_link0_geom6">
            <geometry>
                <box size="0.018 0.053 0.0165891"/>
            </geometry>
            <origin rpy="-1.5707963267948966 1.5707963267948966 0.0" xyz="0.14347937500000002 7.862235885388934e-18 -0.040443125"/>
        </collision>
    </link>
    <joint type="revolute" name="salamander_v1_root_link0_joint1">
        <parent link="salamander_v1_root_link0"/>
        <child link="salamander_v1_root_link0_link1"/>
        <origin rpy="-1.5707963267948966 1.5707963267948966 0.0" xyz="0.08059312500000002 2.3284134525835e-17 -0.06596812499999999"/>
        <axis xyz="0 1 0"/>
        <limit lower="-1.047197551" upper="1.047197551" effort="0.948013269" velocity="6.338968228"/>
    </joint>
    <link name="salamander_v1_root_link0_link1">
        <inertial>
            <origin rpy="0.0 0.0 0.0" xyz="0.025730769230769245 1.734723475976807e-18 4.81482486096809e-35"/>
            <mass value="7.800000e-02"/>
            <inertia ixx="2.396696e-05" ixy="0.000000e+00" ixz="0.000000e+00" iyy="3.656843e-05" iyz="0.000000e+00" izz="4.730539e-05"/>
        </inertial>
        <collision name="salamander_v1_root_link0_link1_geom0">
            <geometry>
                <box size="0.0583 0.0512 0.02"/>
            </geometry>
            <origin rpy="0.0 0.0 0.0" xyz="0.018000000000000016 3.469446951953614e-18 4.81482486096809e-35"/>
        </collision>
        <collision name="salamander_v1_root_link0_link1_geom1">
            <geometry>
                <box size="0.002 0.053 0.053"/>
            </geometry>
            <origin rpy="0.0 0.0 0.0" xyz="0.04815000000000001 0.0 9.62964972193618e-35"/>
        </collision>
    </link>
    <joint type="revolute" name="salamander_v1_root_link0_joint2">
        <parent link="salamander_v1_root_link0"/>
        <child link="salamander_v1_root_link0_link2"/>
        <origin rpy="3.749399456654644e-33 0.0 0.0" xyz="0.2094475 3.851859888774472e-33 -3.851859888774472e-33"/>
        <axis xyz="0 1 0"/>
        <limit lower="-1.047197551" upper="1.047197551" effort="0.948013269" velocity="6.338968228"/>
    </joint>
    <link name="salamander_v1_root_link0_link2">
        <inertial>
            <origin rpy="3.749399456654644e-33 0.0 0.0" xyz="0.12867423295454544 9.037461050537122e-19 -0.005514971590909089"/>
            <mass value="2.420000e-01"/>
            <inertia ixx="1.579335e-04" ixy="2.979946e-23" ixz="1.547197e-21" iyy="2.299277e-03" iyz="4.247893e-37" izz="2.262073e-03"/>
        </inertial>
        <collision name="salamander_v1_root_link0_link2_geom0">
            <geometry>
                <box size="0.0583 0.0512 0.02"/>
            </geometry>
            <origin rpy="3.749399456654644e-33 0.0 0.0" xyz="0.018000000000000016 -5.7777898331617076e-34 -6.7407548053553255e-34"/>
        </collision>
        <collision name="salamander_v1_root_link0_link2_geom1">
            <geometry>
                <box size="0.002 0.053 0.053"/>
            </geometry>
            <origin rpy="3.749399456654644e-33 0.0 0.0" xyz="0.04815000000000001 -1.1555579666323415e-33 -1.1555579666323415e-33"/>
        </collision>
        <collision name="salamander_v1_root_link0_link2_geom2">
            <geometry>
                <box size="0.06288625 0.06288625 0.0603"/>
            </geometry>
            <origin rpy="-1.5707963267948966 0.0 0.0" xyz="0.08059312500000002 -7.703719777548943e-34 3.851859888774472e-34"/>
        </collision>
        <collision name="salamander_v1_root_link0_link2_geom3">
            <geometry>
                <box size="0.06288625 0.06288625 0.0603"/>
            </geometry>
            <origin rpy="-1.5707963267948966 0.0 0.0" xyz="0.14347937500000002 -7.703719777548943e-34 7.703719777548943e-34"/>
        </collision>
        <collision name="salamander_v1_root_link0_link2_geom4">
            <geometry>
                <box size="0.018 0.053 0.0165891"/>
            </geometry>
            <origin rpy="-1.5707963267948966 1.5707963267948966 0.0" xyz="0.08059312500000002 2.4674528141133143e-18 -0.040443125"/>
        </collision>
        <collision name="salamander_v1_root_link0_link2_geom5">
            <geometry>
                <box size="0.06288625 0.06288625 0.0603"/>
            </geometry>
            <origin rpy="-1.5707963267948966 0.0 0.0" xyz="0.20636562500000005 0.0 -1.5407439555097887e-33"/>
        </collision>
        <collision name="salamander_v1_root_link0_link2_geom6">
            <geometry>
                <box size="0.018 0.053 0.0165891"/>
            </geometry>
            <origin rpy="-1.5707963267948966 1.5707963267948966 0.0" xyz="0.14347937500000002 7.862235885388934e-18 -0.040443125"/>
        </collision>
        <collision name="salamander_v1_root_link0_link2_geom7">
            <geometry>
                <box size="0.06288625 0.06288625 0.0603"/>
            </geometry>
            <origin rpy="-1.5707963267948966 0.0 0.0" xyz="0.26925187500000014 0.0 -1.0785207688568521e-32"/>
        </collision>
        <collision name="salamander_v1_root_link0_link2_geom8">
            <geometry>
                <box size="0.018 0.053 0.0165891"/>
            </geometry>
            <origin rpy="-1.5707963267948966 1.5707963267948966 0.0" xyz="0.20636562500000005 6.3181250527573276e-18 -0.040443125"/>
        </collision>
        <collision name="salamander_v1_root_link0_link2_geom9">
            <geometry>
                <box size="0.018 0.053 0.0165891"/>
            </geometry>
            <origin rpy="3.749399456654644e-33 0.0 0.0" xyz="0.3096950000000001 -3.0814879110195774e-33 -3.0814879110195774e-33"/>
        </collision>
    </link>
    <joint type="revolute" name="salamander_v1_root_link0_link2_joint1">
        <parent link="salamander_v1_root_link0_link2"/>
        <child link="salamander_v1_root_link0_link2_link1"/>
        <origin rpy="-1.5707963267948966 1.5707963267948966 0.0" xyz="0.08059312500000004 2.3284134525835e-17 -0.06596812499999999"/>
        <axis xyz="0 1 0"/>
        <limit lower="-1.047197551" upper="1.047197551" effort="0.948013269" velocity="6.338968228"/>
    </joint>
    <link name="salamander_v1_root_link0_link2_link1">
        <inertial>
            <origin rpy="0.0 0.0 0.0" xyz="0.05485896812080539 0.012661661073825506 1.925929944387236e-34"/>
            <mass value="1.490000e-01"/>
            <inertia ixx="1.572232e-04" ixy="5.057991e-22" ixz="0.000000e+00" iyy="2.322338e-04" iyz="1.768532e-22" izz="3.377685e-04"/>
        </inertial>
        <collision name="salamander_v1_root_link0_link2_link1_geom0">
            <geometry>
                <box size="0.0583 0.0512 0.02"/>
            </geometry>
            <origin rpy="0.0 0.0 0.0" xyz="0.018000000000000016 3.469446951953614e-18 4.81482486096809e-35"/>
        </collision>
        <collision name="salamander_v1_root_link0_link2_link1_geom1">
            <geometry>
                <box size="0.002 0.053 0.053"/>
            </geometry>
            <origin rpy="0.0 0.0 0.0" xyz="0.04815000000000001 0.0 9.62964972193618e-35"/>
        </collision>
        <collision name="salamander_v1_root_link0_link2_link1_geom2">
            <geometry>
                <box size="0.06288625 0.06288625 0.0603"/>
            </geometry>
            <origin rpy="0.0 0.0 0.0" xyz="0.08059312500000002 6.938893903907228e-18 0.0"/>
        </collision>
        <collision name="salamander_v1_root_link0_link2_link1_geom3">
            <geometry>
                <box size="0.018 0.053 0.0165891"/>
            </geometry>
            <origin rpy="1.5707963267948966 0.0 0.0" xyz="0.12103625000000001 0.0 0.0"/>
        </collision>
        <collision name="salamander_v1_root_link0_link2_link1_geom4">
            <geometry>
                <box size="0.06288625 0.06288625 0.0603"/>
            </geometry>
            <origin rpy="0.0 0.0 1.5707963267948966" xyz="0.080593125 0.06288625000000003 -7.703719777548943e-34"/>
        </collision>
    </link>
    <joint type="revolute" name="salamander_v1_root_link0_link2_link1_joint1">
        <parent link="salamander_v1_root_link0_link2_link1"/>
        <child link="salamander_v1_root_link0_link2_link1_link1"/>
        <origin rpy="1.5707963267948966 0.0 0.0" xyz="0.14656125000000003 2.7755575615628914e-17 -1.5407439555097887e-33"/>
        <axis xyz="0 1 0"/>
        <limit lower="-1.047197551" upper="1.047197551" effort="0.948013269" velocity="6.338968228"/>
    </joint>
    <link name="salamander_v1_root_link0_link2_link1_link1">
        <inertial>
            <origin rpy="0.0 0.0 0.0" xyz="0.02973764044943822 0.0 -3.469446951953614e-18"/>
            <mass value="8.900000e-02"/>
            <inertia ixx="2.451623e-05" ixy="-5.057991e-22" ixz="0.000000e+00" iyy="4.952779e-05" iyz="0.000000e+00" izz="6.030948e-05"/>
        </inertial>
        <collision name="salamander_v1_root_link0_link2_link1_link1_geom0">
            <geometry>
                <box size="0.0583 0.0512 0.02"/>
            </geometry>
            <origin rpy="0.0 0.0 0.0" xyz="0.018000000000000016 0.0 -3.469446951953614e-18"/>
        </collision>
        <collision name="salamander_v1_root_link0_link2_link1_link1_geom1">
            <geometry>
                <box size="0.002 0.053 0.053"/>
            </geometry>
            <origin rpy="0.0 0.0 0.0" xyz="0.04815000000000001 0.0 -6.938893903907228e-18"/>
        </collision>
        <collision name="salamander_v1_root_link0_link2_link1_link1_geom2">
            <geometry>
                <box size="0.018 0.053 0.0165891"/>
            </geometry>
            <origin rpy="-1.5707963267948966 0.0 0.0" xyz="0.05815000000000002 0.0 -6.938893903907228e-18"/>
        </collision>
    </link>
    <joint type="revolute" name="salamander_v1_root_link0_link2_link1_link1_joint1">
        <parent link="salamander_v1_root_link0_link2_link1_link1"/>
        <child link="salamander_v1_root_link0_link2_link1_link1_link1"/>
        <origin rpy="-1.5707963267948966 0.0 0.0" xyz="0.083675 0.0 -1.3877787807814457e-17"/>
        <axis xyz="0 1 0"/>
        <limit lower="-1.047197551" upper="1.047197551" effort="0.948013269" velocity="6.338968228"/>
    </joint>
    <link name="salamander_v1_root_link0_link2_link1_link1_link1">
        <inertial>
            <origin rpy="0.0 0.0 0.0" xyz="0.025730769230769245 1.734723475976807e-18 -0.0"/>
            <mass value="7.800000e-02"/>
            <inertia ixx="2.396696e-05" ixy="0.000000e+00" ixz="0.000000e+00" iyy="3.656843e-05" iyz="0.000000e+00" izz="4.730539e-05"/>
        </inertial>
        <collision name="salamander_v1_root_link0_link2_link1_link1_link1_geom0">
            <geometry>
                <box size="0.0583 0.0512 0.02"/>
            </geometry>
            <origin rpy="0.0 0.0 0.0" xyz="0.018000000000000016 3.469446951953614e-18 -0.0"/>
        </collision>
        <collision name="salamander_v1_root_link0_link2_link1_link1_link1_geom1">
            <geometry>
                <box size="0.002 0.053 0.053"/>
            </geometry>
            <origin rpy="0.0 0.0 0.0" xyz="0.04815000000000001 0.0 -0.0"/>
        </collision>
    </link>
    <joint type="revolute" name="salamander_v1_root_link0_link2_joint2">
        <parent link="salamander_v1_root_link0_link2"/>
        <child link="salamander_v1_root_link0_link2_link2"/>
        <origin rpy="-1.5707963267948966 1.5707963267948966 0.0" xyz="0.14347937500000002 1.8270576741249777e-17 -0.065968125"/>
        <axis xyz="0 1 0"/>
        <limit lower="-1.047197551" upper="1.047197551" effort="0.948013269" velocity="6.338968228"/>
    </joint>
    <link name="salamander_v1_root_link0_link2_link2">
        <inertial>
            <origin rpy="0.0 0.0 0.0" xyz="0.025730769230769234 5.204170427930421e-18 -9.62964972193618e-35"/>
            <mass value="7.800000e-02"/>
            <inertia ixx="2.396696e-05" ixy="0.000000e+00" ixz="0.000000e+00" iyy="3.656843e-05" iyz="0.000000e+00" izz="4.730539e-05"/>
        </inertial>
        <collision name="salamander_v1_root_link0_link2_link2_geom0">
            <geometry>
                <box size="0.0583 0.0512 0.02"/>
            </geometry>
            <origin rpy="0.0 0.0 0.0" xyz="0.018000000000000002 1.734723475976807e-18 4.81482486096809e-35"/>
        </collision>
        <collision name="salamander_v1_root_link0_link2_link2_geom1">
            <geometry>
                <box size="0.002 0.053 0.053"/>
            </geometry>
            <origin rpy="0.0 0.0 0.0" xyz="0.04815 -6.938893903907228e-18 3.851859888774472e-34"/>
        </collision>
    </link>
    <joint type="revolute" name="salamander_v1_root_link0_link2_joint3">
        <parent link="salamander_v1_root_link0_link2"/>
        <child link="salamander_v1_root_link0_link2_link3"/>
        <origin rpy="-1.5707963267948966 1.5707963267948966 0.0" xyz="0.20636562500000005 2.0195912860571784e-17 -0.065968125"/>
        <axis xyz="0 1 0"/>
        <limit lower="-1.047197551" upper="1.047197551" effort="0.948013269" velocity="6.338968228"/>
    </joint>
    <link name="salamander_v1_root_link0_link2_link3">
        <inertial>
            <origin rpy="0.0 0.0 0.0" xyz="0.025730769230769234 5.204170427930421e-18 -9.62964972193618e-35"/>
            <mass value="7.800000e-02"/>
            <inertia ixx="2.396696e-05" ixy="0.000000e+00" ixz="0.000000e+00" iyy="3.656843e-05" iyz="0.000000e+00" izz="4.730539e-05"/>
        </inertial>
        <collision name="salamander_v1_root_link0_link2_link3_geom0">
            <geometry>
                <box size="0.0583 0.0512 0.02"/>
            </geometry>
            <origin rpy="0.0 0.0 0.0" xyz="0.018000000000000002 1.734723475976807e-18 4.81482486096809e-35"/>
        </collision>
        <collision name="salamander_v1_root_link0_link2_link3_geom1">
            <geometry>
                <box size="0.002 0.053 0.053"/>
            </geometry>
            <origin rpy="0.0 0.0 0.0" xyz="0.04815 -6.938893903907228e-18 3.851859888774472e-34"/>
        </collision>
    </link>
    <joint type="revolute" name="salamander_v1_root_link0_link2_joint4">
        <parent link="salamander_v1_root_link0_link2"/>
        <child link="salamander_v1_root_link0_link2_link4"/>
        <origin rpy="3.749399456654644e-33 0.0 0.0" xyz="0.3352200000000002 3.0814879110195774e-33 -4.622231866529366e-33"/>
        <axis xyz="0 1 0"/>
        <limit lower="-1.047197551" upper="1.047197551" effort="0.948013269" velocity="6.338968228"/>
    </joint>
    <link name="salamander_v1_root_link0_link2_link4">
        <inertial>
            <origin rpy="3.749399456654644e-33 0.0 0.0" xyz="0.054858968120805277 1.6795714928417723e-18 -0.012661661073825504"/>
            <mass value="1.490000e-01"/>
            <inertia ixx="1.602976e-04" ixy="1.768532e-22" ixz="1.768532e-22" iyy="3.239125e-04" iyz="9.749040e-37" izz="2.430155e-04"/>
        </inertial>
        <collision name="salamander_v1_root_link0_link2_link4_geom0">
            <geometry>
                <box size="0.0583 0.0512 0.02"/>
            </geometry>
            <origin rpy="3.749399456654644e-33 0.0 0.0" xyz="0.017999999999999905 -2.8888949165808538e-33 -5.585196838722984e-33"/>
        </collision>
        <collision name="salamander_v1_root_link0_link2_link4_geom1">
            <geometry>
                <box size="0.002 0.053 0.053"/>
            </geometry>
            <origin rpy="3.749399456654644e-33 0.0 0.0" xyz="0.0481499999999999 -2.6963019221421302e-33 -5.7777898331617076e-33"/>
        </collision>
        <collision name="salamander_v1_root_link0_link2_link4_geom2">
            <geometry>
                <box size="0.06288625 0.06288625 0.0603"/>
            </geometry>
            <origin rpy="-1.5707963267948966 0.0 0.0" xyz="0.0805931249999999 -4.237045877651919e-33 -6.548161810916602e-33"/>
        </collision>
        <collision name="salamander_v1_root_link0_link2_link4_geom3">
            <geometry>
                <box size="0.018 0.053 0.0165891"/>
            </geometry>
            <origin rpy="3.749399456654644e-33 0.0 0.0" xyz="0.1210362499999999 -3.851859888774472e-33 -5.3926038442842604e-33"/>
        </collision>
        <collision name="salamander_v1_root_link0_link2_link4_geom4">
            <geometry>
                <box size="0.06288625 0.06288625 0.0603"/>
            </geometry>
            <origin rpy="-1.5707963267948966 1.5707963267948966 0.0" xyz="0.0805931249999999 2.3284134525834994e-17 -0.06288625"/>
        </collision>
    </link>
    <joint type="revolute" name="salamander_v1_root_link0_link2_link4_joint1">
        <parent link="salamander_v1_root_link0_link2_link4"/>
        <child link="salamander_v1_root_link0_link2_link4_link1"/>
        <origin rpy="3.749399456654644e-33 0.0 0.0" xyz="0.14656124999999987 -3.0814879110195774e-33 -7.703719777548943e-34"/>
        <axis xyz="0 1 0"/>
        <limit lower="-1.047197551" upper="1.047197551" effort="0.948013269" velocity="6.338968228"/>
    </joint>
    <link name="salamander_v1_root_link0_link2_link4_link1">
        <inertial>
            <origin rpy="3.749399456654644e-33 0.0 0.0" xyz="0.025730769230769245 5.7777898331617076e-34 -6.548161810916602e-33"/>
            <mass value="7.800000e-02"/>
            <inertia ixx="2.396696e-05" ixy="0.000000e+00" ixz="0.000000e+00" iyy="3.656843e-05" iyz="0.000000e+00" izz="4.730539e-05"/>
        </inertial>
        <collision name="salamander_v1_root_link0_link2_link4_link1_geom0">
            <geometry>
                <box size="0.0583 0.0512 0.02"/>
            </geometry>
            <origin rpy="3.749399456654644e-33 0.0 0.0" xyz="0.018000000000000016 1.925929944387236e-34 -6.933347799794049e-33"/>
        </collision>
        <collision name="salamander_v1_root_link0_link2_link4_link1_geom1">
            <geometry>
                <box size="0.002 0.053 0.053"/>
            </geometry>
            <origin rpy="3.749399456654644e-33 0.0 0.0" xyz="0.04815000000000001 -1.925929944387236e-34 -7.703719777548943e-33"/>
        </collision>
    </link>
    <joint type="revolute" name="salamander_v1_root_link0_joint3">
        <parent link="salamander_v1_root_link0"/>
        <child link="salamander_v1_root_link0_link3"/>
        <origin rpy="-1.5707963267948966 1.5707963267948966 0.0" xyz="0.14347937500000002 1.8270576741249777e-17 -0.065968125"/>
        <axis xyz="0 1 0"/>
        <limit lower="-1.047197551" upper="1.047197551" effort="0.948013269" velocity="6.338968228"/>
    </joint>
    <link name="salamander_v1_root_link0_link3">
        <inertial>
            <origin rpy="0.0 0.0 0.0" xyz="0.025730769230769234 5.204170427930421e-18 -9.62964972193618e-35"/>
            <mass value="7.800000e-02"/>
            <inertia ixx="2.396696e-05" ixy="0.000000e+00" ixz="0.000000e+00" iyy="3.656843e-05" iyz="0.000000e+00" izz="4.730539e-05"/>
        </inertial>
        <collision name="salamander_v1_root_link0_link3_geom0">
            <geometry>
                <box size="0.0583 0.0512 0.02"/>
            </geometry>
            <origin rpy="0.0 0.0 0.0" xyz="0.018000000000000002 1.734723475976807e-18 4.81482486096809e-35"/>
        </collision>
        <collision name="salamander_v1_root_link0_link3_geom1">
            <geometry>
                <box size="0.002 0.053 0.053"/>
            </geometry>
            <origin rpy="0.0 0.0 0.0" xyz="0.04815 -6.938893903907228e-18 3.851859888774472e-34"/>
        </collision>
    </link>
    <joint type="revolute" name="salamander_v1_root_joint1">
        <parent link="salamander_v1_root"/>
        <child link="salamander_v1_root_link1"/>
        <origin rpy="1.5707963267948963 0.0 1.5707963267948963" xyz="1.734723475976807e-17 0.07902499999999998 0.0"/>
        <axis xyz="0 1 0"/>
        <limit lower="-1.047197551" upper="1.047197551" effort="0.948013269" velocity="6.338968228"/>
    </joint>
    <link name="salamander_v1_root_link1">
        <inertial>
            <origin rpy="0.0 0.0 0.0" xyz="0.029737640449438205 0.0 0.0"/>
            <mass value="8.900000e-02"/>
            <inertia ixx="2.451623e-05" ixy="-5.057991e-22" ixz="0.000000e+00" iyy="4.952779e-05" iyz="0.000000e+00" izz="6.030948e-05"/>
        </inertial>
        <collision name="salamander_v1_root_link1_geom0">
            <geometry>
                <box size="0.0583 0.0512 0.02"/>
            </geometry>
            <origin rpy="0.0 0.0 0.0" xyz="0.018000000000000002 0.0 0.0"/>
        </collision>
        <collision name="salamander_v1_root_link1_geom1">
            <geometry>
                <box size="0.002 0.053 0.053"/>
            </geometry>
            <origin rpy="0.0 0.0 0.0" xyz="0.04815 -1.734723475976807e-18 -1.734723475976807e-18"/>
        </collision>
        <collision name="salamander_v1_root_link1_geom2">
            <geometry>
                <box size="0.018 0.053 0.0165891"/>
            </geometry>
            <origin rpy="-1.5707963267948966 0.0 0.0" xyz="0.05815000000000001 -1.734723475976807e-18 -5.204170427930421e-18"/>
        </collision>
    </link>
    <joint type="revolute" name="salamander_v1_root_link1_joint1">
        <parent link="salamander_v1_root_link1"/>
        <child link="salamander_v1_root_link1_link1"/>
        <origin rpy="-1.5707963267948966 0.0 0.0" xyz="0.083675 0.0 0.0"/>
        <axis xyz="0 1 0"/>
        <limit lower="-1.047197551" upper="1.047197551" effort="0.948013269" velocity="6.338968228"/>
    </joint>
    <link name="salamander_v1_root_link1_link1">
        <inertial>
            <origin rpy="0.0 0.0 0.0" xyz="0.02573076923076922 3.469446951953614e-18 0.0"/>
            <mass value="7.800000e-02"/>
            <inertia ixx="2.396696e-05" ixy="0.000000e+00" ixz="0.000000e+00" iyy="3.656843e-05" iyz="0.000000e+00" izz="4.730539e-05"/>
        </inertial>
        <collision name="salamander_v1_root_link1_link1_geom0">
            <geometry>
                <box size="0.0583 0.0512 0.02"/>
            </geometry>
            <origin rpy="0.0 0.0 0.0" xyz="0.017999999999999988 3.469446951953614e-18 0.0"/>
        </collision>
        <collision name="salamander_v1_root_link1_link1_geom1">
            <geometry>
                <box size="0.002 0.053 0.053"/>
            </geometry>
            <origin rpy="0.0 0.0 0.0" xyz="0.048149999999999984 0.0 0.0"/>
        </collision>
    </link>
    <joint type="revolute" name="salamander_v1_root_joint2">
        <parent link="salamander_v1_root"/>
        <child link="salamander_v1_root_link2"/>
        <origin rpy="0.0 0.0 -1.5707963267948966" xyz="-1.8214596497756474e-17 -0.07902499999999998 0.0"/>
        <axis xyz="0 1 0"/>
        <limit lower="-1.047197551" upper="1.047197551" effort="0.948013269" velocity="6.338968228"/>
    </joint>
    <link name="salamander_v1_root_link2">
        <inertial>
            <origin rpy="0.0 0.0 0.0" xyz="0.025730769230769248 -3.469446951953614e-18 -0.0"/>
            <mass value="7.800000e-02"/>
            <inertia ixx="2.396696e-05" ixy="0.000000e+00" ixz="0.000000e+00" iyy="3.656843e-05" iyz="0.000000e+00" izz="4.730539e-05"/>
        </inertial>
        <collision name="salamander_v1_root_link2_geom0">
            <geometry>
                <box size="0.0583 0.0512 0.02"/>
            </geometry>
            <origin rpy="0.0 0.0 0.0" xyz="0.018000000000000016 0.0 -0.0"/>
        </collision>
        <collision name="salamander_v1_root_link2_geom1">
            <geometry>
                <box size="0.002 0.053 0.053"/>
            </geometry>
            <origin rpy="0.0 0.0 0.0" xyz="0.04815000000000001 0.0 -0.0"/>
        </collision>
    </link>
</robot>
