<?xml version="1.0" ?>
<robot name="stingray_v1">
    <link name="stingray_v1_root">
        <inertial>
            <origin rpy="0.0 0.0 0.0" xyz="-0.0021636029411764707 -0.00216360294117647 -1.9471718187738595e-36"/>
            <mass value="2.720000e-01"/>
            <inertia ixx="2.720827e-04" ixy="-5.057991e-22" ixz="5.057991e-22" iyy="2.766833e-04" iyz="4.454703e-24" izz="3.961637e-04"/>
        </inertial>
        <collision name="stingray_v1_root_geom0">
            <geometry>
                <box size="0.089 0.089 0.0603"/>
            </geometry>
            <origin rpy="0.0 0.0 0.0" xyz="0.0 0.0 0.0"/>
        </collision>
        <collision name="stingray_v1_root_geom1">
            <geometry>
                <box size="0.018 0.053 0.0165891"/>
            </geometry>
            <origin rpy="1.5707963267948966 0.0 3.141592653589793" xyz="-0.0535 6.551860375438339e-18 -4.81482486096809e-35"/>
        </collision>
        <collision name="stingray_v1_root_geom2">
            <geometry>
                <box size="0.018 0.053 0.0165891"/>
            </geometry>
            <origin rpy="1.5707963267948966 0.0 -1.5707963267948966" xyz="-1.214306433183765e-17 -0.0535 0.0"/>
        </collision>
    </link>
    <joint type="revolute" name="stingray_v1_root_joint0">
        <parent link="stingray_v1_root"/>
        <child link="stingray_v1_root_link0"/>
        <origin rpy="1.5707963267948966 0.0 3.141592653589793" xyz="-0.07902499999999998 9.677771330261958e-18 -1.925929944387236e-34"/>
        <axis xyz="0 1 0"/>
        <limit lower="-1.047197551" upper="1.047197551" effort="0.948013269" velocity="6.338968228"/>
    </joint>
    <link name="stingray_v1_root_link0">
        <inertial>
            <origin rpy="3.749399456654644e-33 0.0 0.0" xyz="0.025730769230769245 2.8888949165808538e-34 -2.0222264416065976e-33"/>
            <mass value="7.800000e-02"/>
            <inertia ixx="2.396696e-05" ixy="0.000000e+00" ixz="0.000000e+00" iyy="3.656843e-05" iyz="0.000000e+00" izz="4.730539e-05"/>
        </inertial>
        <collision name="stingray_v1_root_link0_geom0">
            <geometry>
                <box size="0.0583 0.0512 0.02"/>
            </geometry>
            <origin rpy="3.749399456654644e-33 0.0 0.0" xyz="0.018000000000000016 9.62964972193618e-35 -2.311115933264683e-33"/>
        </collision>
        <collision name="stingray_v1_root_link0_geom1">
            <geometry>
                <box size="0.002 0.053 0.053"/>
            </geometry>
            <origin rpy="3.749399456654644e-33 0.0 0.0" xyz="0.04815000000000001 -5.7777898331617076e-34 -2.1185229388259594e-33"/>
        </collision>
    </link>
    <joint type="revolute" name="stingray_v1_root_joint1">
        <parent link="stingray_v1_root"/>
        <child link="stingray_v1_root_link1"/>
        <origin rpy="1.5707963267948966 0.0 -1.5707963267948966" xyz="-1.734723475976807e-17 -0.07902499999999998 0.0"/>
        <axis xyz="0 1 0"/>
        <limit lower="-1.047197551" upper="1.047197551" effort="0.948013269" velocity="6.338968228"/>
    </joint>
    <link name="stingray_v1_root_link1">
        <inertial>
            <origin rpy="0.0 0.0 0.0" xyz="0.029737640449438205 0.0 0.0"/>
            <mass value="8.900000e-02"/>
            <inertia ixx="2.451623e-05" ixy="-5.057991e-22" ixz="0.000000e+00" iyy="4.952779e-05" iyz="0.000000e+00" izz="6.030948e-05"/>
        </inertial>
        <collision name="stingray_v1_root_link1_geom0">
            <geometry>
                <box size="0.0583 0.0512 0.02"/>
            </geometry>
            <origin rpy="0.0 0.0 0.0" xyz="0.018000000000000002 0.0 0.0"/>
        </collision>
        <collision name="stingray_v1_root_link1_geom1">
            <geometry>
                <box size="0.002 0.053 0.053"/>
            </geometry>
            <origin rpy="0.0 0.0 0.0" xyz="0.04815 -1.734723475976807e-18 -1.734723475976807e-18"/>
        </collision>
        <collision name="stingray_v1_root_link1_geom2">
            <geometry>
                <box size="0.018 0.053 0.0165891"/>
            </geometry>
            <origin rpy="-1.5707963267948966 0.0 0.0" xyz="0.05815 -1.734723475976807e-18 -5.204170427930421e-18"/>
        </collision>
    </link>
    <joint type="revolute" name="stingray_v1_root_link1_joint1">
        <parent link="stingray_v1_root_link1"/>
        <child link="stingray_v1_root_link1_link1"/>
        <origin rpy="-1.5707963267948966 0.0 0.0" xyz="0.083675 0.0 0.0"/>
        <axis xyz="0 1 0"/>
        <limit lower="-1.047197551" upper="1.047197551" effort="0.948013269" velocity="6.338968228"/>
    </joint>
    <link name="stingray_v1_root_link1_link1">
        <inertial>
            <origin rpy="0.0 0.0 0.0" xyz="0.08119427771226412 -0.006800533608490561 -0.0"/>
            <mass value="2.120000e-01"/>
            <inertia ixx="2.504630e-04" ixy="5.057991e-22" ixz="5.057991e-22" iyy="6.635224e-04" iyz="1.218251e-21" izz="8.332229e-04"/>
        </inertial>
        <collision name="stingray_v1_root_link1_link1_geom0">
            <geometry>
                <box size="0.0583 0.0512 0.02"/>
            </geometry>
            <origin rpy="0.0 0.0 0.0" xyz="0.017999999999999988 3.469446951953614e-18 -0.0"/>
        </collision>
        <collision name="stingray_v1_root_link1_link1_geom1">
            <geometry>
                <box size="0.002 0.053 0.053"/>
            </geometry>
            <origin rpy="0.0 0.0 0.0" xyz="0.048149999999999984 0.0 -0.0"/>
        </collision>
        <collision name="stingray_v1_root_link1_link1_geom2">
            <geometry>
                <box size="0.06288625 0.06288625 0.0603"/>
            </geometry>
            <origin rpy="0.0 0.0 0.0" xyz="0.08059312499999999 6.938893903907228e-18 -0.0"/>
        </collision>
        <collision name="stingray_v1_root_link1_link1_geom3">
            <geometry>
                <box size="0.06288625 0.06288625 0.0603"/>
            </geometry>
            <origin rpy="0.0 0.0 0.0" xyz="0.143479375 0.0 -0.0"/>
        </collision>
        <collision name="stingray_v1_root_link1_link1_geom4">
            <geometry>
                <box size="0.018 0.053 0.0165891"/>
            </geometry>
            <origin rpy="0.0 0.0 1.5707963267948966" xyz="0.08059312499999999 0.04044312500000001 -0.0"/>
        </collision>
        <collision name="stingray_v1_root_link1_link1_geom5">
            <geometry>
                <box size="0.06288625 0.06288625 0.0603"/>
            </geometry>
            <origin rpy="0.0 0.0 -1.5707963267948966" xyz="0.08059312499999999 -0.06288625000000002 -0.0"/>
        </collision>
        <collision name="stingray_v1_root_link1_link1_geom6">
            <geometry>
                <box size="0.018 0.053 0.0165891"/>
            </geometry>
            <origin rpy="1.5707963267948966 0.0 0.0" xyz="0.18392250000000002 -2.7755575615628914e-17 -0.0"/>
        </collision>
        <collision name="stingray_v1_root_link1_link1_geom7">
            <geometry>
                <box size="0.018 0.053 0.0165891"/>
            </geometry>
            <origin rpy="0.0 0.0 1.5707963267948966" xyz="0.143479375 0.040443124999999996 -0.0"/>
        </collision>
        <collision name="stingray_v1_root_link1_link1_geom8">
            <geometry>
                <box size="0.018 0.053 0.0165891"/>
            </geometry>
            <origin rpy="1.5707963267948966 0.0 -1.5707963267948966" xyz="0.143479375 -0.040443125 -0.0"/>
        </collision>
    </link>
    <joint type="revolute" name="stingray_v1_root_link1_link1_joint1">
        <parent link="stingray_v1_root_link1_link1"/>
        <child link="stingray_v1_root_link1_link1_link1"/>
        <origin rpy="0.0 0.0 1.5707963267948966" xyz="0.08059312500000002 0.06596812500000002 -0.0"/>
        <axis xyz="0 1 0"/>
        <limit lower="-1.047197551" upper="1.047197551" effort="0.948013269" velocity="6.338968228"/>
    </joint>
    <link name="stingray_v1_root_link1_link1_link1">
        <inertial>
            <origin rpy="0.0 0.0 0.0" xyz="0.02573076923076922 3.5749181392930035e-17 0.0"/>
            <mass value="7.800000e-02"/>
            <inertia ixx="2.396696e-05" ixy="0.000000e+00" ixz="0.000000e+00" iyy="3.656843e-05" iyz="0.000000e+00" izz="4.730539e-05"/>
        </inertial>
        <collision name="stingray_v1_root_link1_link1_link1_geom0">
            <geometry>
                <box size="0.0583 0.0512 0.02"/>
            </geometry>
            <origin rpy="0.0 0.0 0.0" xyz="0.017999999999999988 3.5749181392930035e-17 0.0"/>
        </collision>
        <collision name="stingray_v1_root_link1_link1_link1_geom1">
            <geometry>
                <box size="0.002 0.053 0.053"/>
            </geometry>
            <origin rpy="0.0 0.0 0.0" xyz="0.048149999999999984 3.5749181392930035e-17 0.0"/>
        </collision>
    </link>
    <joint type="revolute" name="stingray_v1_root_link1_link1_joint2">
        <parent link="stingray_v1_root_link1_link1"/>
        <child link="stingray_v1_root_link1_link1_link2"/>
        <origin rpy="1.5707963267948966 0.0 0.0" xyz="0.20944749999999998 0.0 -0.0"/>
        <axis xyz="0 1 0"/>
        <limit lower="-1.047197551" upper="1.047197551" effort="0.948013269" velocity="6.338968228"/>
    </joint>
    <link name="stingray_v1_root_link1_link1_link2">
        <inertial>
            <origin rpy="0.0 0.0 0.0" xyz="0.02573076923076925 -8.673617379884035e-19 -4.336808689942018e-18"/>
            <mass value="7.800000e-02"/>
            <inertia ixx="2.396696e-05" ixy="0.000000e+00" ixz="0.000000e+00" iyy="3.656843e-05" iyz="0.000000e+00" izz="4.730539e-05"/>
        </inertial>
        <collision name="stingray_v1_root_link1_link1_link2_geom0">
            <geometry>
                <box size="0.0583 0.0512 0.02"/>
            </geometry>
            <origin rpy="0.0 0.0 0.0" xyz="0.018000000000000016 0.0 -3.469446951953614e-18"/>
        </collision>
        <collision name="stingray_v1_root_link1_link1_link2_geom1">
            <geometry>
                <box size="0.002 0.053 0.053"/>
            </geometry>
            <origin rpy="0.0 0.0 0.0" xyz="0.04815000000000001 0.0 -6.938893903907228e-18"/>
        </collision>
    </link>
    <joint type="revolute" name="stingray_v1_root_link1_link1_joint3">
        <parent link="stingray_v1_root_link1_link1"/>
        <child link="stingray_v1_root_link1_link1_link3"/>
        <origin rpy="0.0 0.0 1.5707963267948966" xyz="0.14347937500000002 0.06596812500000002 -0.0"/>
        <axis xyz="0 1 0"/>
        <limit lower="-1.047197551" upper="1.047197551" effort="0.948013269" velocity="6.338968228"/>
    </joint>
    <link name="stingray_v1_root_link1_link1_link3">
        <inertial>
            <origin rpy="0.0 0.0 0.0" xyz="0.0510978221153846 -0.0034221105769230136 -0.0"/>
            <mass value="1.300000e-01"/>
            <inertia ixx="6.279003e-05" ixy="-1.393908e-37" ixz="5.057991e-22" iyy="1.986327e-04" iyz="9.933154e-24" izz="2.289137e-04"/>
        </inertial>
        <collision name="stingray_v1_root_link1_link1_link3_geom0">
            <geometry>
                <box size="0.0583 0.0512 0.02"/>
            </geometry>
            <origin rpy="0.0 0.0 0.0" xyz="0.017999999999999988 6.350475700855896e-17 0.0"/>
        </collision>
        <collision name="stingray_v1_root_link1_link1_link3_geom1">
            <geometry>
                <box size="0.002 0.053 0.053"/>
            </geometry>
            <origin rpy="0.0 0.0 0.0" xyz="0.048149999999999984 6.350475700855895e-17 0.0"/>
        </collision>
        <collision name="stingray_v1_root_link1_link1_link3_geom2">
            <geometry>
                <box size="0.06288625 0.06288625 0.0603"/>
            </geometry>
            <origin rpy="0.0 0.0 0.0" xyz="0.08059312499999999 6.350475700855895e-17 0.0"/>
        </collision>
        <collision name="stingray_v1_root_link1_link1_link3_geom3">
            <geometry>
                <box size="0.018 0.053 0.0165891"/>
            </geometry>
            <origin rpy="0.0 0.0 0.0" xyz="0.12103624999999998 6.350475700855895e-17 0.0"/>
        </collision>
        <collision name="stingray_v1_root_link1_link1_link3_geom4">
            <geometry>
                <box size="0.018 0.053 0.0165891"/>
            </geometry>
            <origin rpy="1.5707963267948966 0.0 -1.5707963267948966" xyz="0.08059312499999999 -0.040443124999999934 -0.0"/>
        </collision>
    </link>
    <joint type="revolute" name="stingray_v1_root_link1_link1_link3_joint1">
        <parent link="stingray_v1_root_link1_link1_link3"/>
        <child link="stingray_v1_root_link1_link1_link3_link1"/>
        <origin rpy="0.0 0.0 0.0" xyz="0.14656124999999998 6.508626970713748e-17 0.0"/>
        <axis xyz="0 1 0"/>
        <limit lower="-1.047197551" upper="1.047197551" effort="0.948013269" velocity="6.338968228"/>
    </joint>
    <link name="stingray_v1_root_link1_link1_link3_link1">
        <inertial>
            <origin rpy="0.0 0.0 0.0" xyz="0.040970312500000015 7.993605777301134e-18 -0.0"/>
            <mass value="1.080000e-01"/>
            <inertia ixx="4.294389e-05" ixy="0.000000e+00" ixz="0.000000e+00" iyy="1.207594e-04" iyz="0.000000e+00" izz="1.322928e-04"/>
        </inertial>
        <collision name="stingray_v1_root_link1_link1_link3_link1_geom0">
            <geometry>
                <box size="0.0583 0.0512 0.02"/>
            </geometry>
            <origin rpy="0.0 0.0 0.0" xyz="0.018000000000000016 7.993605777301134e-18 0.0"/>
        </collision>
        <collision name="stingray_v1_root_link1_link1_link3_link1_geom1">
            <geometry>
                <box size="0.002 0.053 0.053"/>
            </geometry>
            <origin rpy="0.0 0.0 0.0" xyz="0.04815000000000001 7.993605777301133e-18 -0.0"/>
        </collision>
        <collision name="stingray_v1_root_link1_link1_link3_link1_geom2">
            <geometry>
                <box size="0.06288625 0.06288625 0.0603"/>
            </geometry>
            <origin rpy="0.0 0.0 0.0" xyz="0.08059312500000002 7.993605777301134e-18 -0.0"/>
        </collision>
    </link>
    <joint type="revolute" name="stingray_v1_root_link1_link1_link3_joint2">
        <parent link="stingray_v1_root_link1_link1_link3"/>
        <child link="stingray_v1_root_link1_link1_link3_link2"/>
        <origin rpy="1.5707963267948966 0.0 -1.5707963267948966" xyz="0.08059312499999999 -0.06596812499999996 -0.0"/>
        <axis xyz="0 1 0"/>
        <limit lower="-1.047197551" upper="1.047197551" effort="0.948013269" velocity="6.338968228"/>
    </joint>
    <link name="stingray_v1_root_link1_link1_link3_link2">
        <inertial>
            <origin rpy="0.0 0.0 0.0" xyz="0.025730769230769196 0.0 -1.214306433183765e-17"/>
            <mass value="7.800000e-02"/>
            <inertia ixx="2.396696e-05" ixy="0.000000e+00" ixz="0.000000e+00" iyy="3.656843e-05" iyz="0.000000e+00" izz="4.730539e-05"/>
        </inertial>
        <collision name="stingray_v1_root_link1_link1_link3_link2_geom0">
            <geometry>
                <box size="0.0583 0.0512 0.02"/>
            </geometry>
            <origin rpy="0.0 0.0 0.0" xyz="0.01799999999999996 0.0 -1.0408340855860843e-17"/>
        </collision>
        <collision name="stingray_v1_root_link1_link1_link3_link2_geom1">
            <geometry>
                <box size="0.002 0.053 0.053"/>
            </geometry>
            <origin rpy="0.0 0.0 0.0" xyz="0.04814999999999996 0.0 -1.3877787807814457e-17"/>
        </collision>
    </link>
    <joint type="revolute" name="stingray_v1_root_link1_link1_joint4">
        <parent link="stingray_v1_root_link1_link1"/>
        <child link="stingray_v1_root_link1_link1_link4"/>
        <origin rpy="1.5707963267948963 0.0 -1.5707963267948966" xyz="0.14347937500000002 -0.06596812500000002 -0.0"/>
        <axis xyz="0 1 0"/>
        <limit lower="-1.047197551" upper="1.047197551" effort="0.948013269" velocity="6.338968228"/>
    </joint>
    <link name="stingray_v1_root_link1_link1_link4">
        <inertial>
            <origin rpy="2.465190328815662e-32 0.0 0.0" xyz="0.025730769230769217 7.703719777548943e-34 -5.6523328512615856e-18"/>
            <mass value="7.800000e-02"/>
            <inertia ixx="2.396696e-05" ixy="0.000000e+00" ixz="0.000000e+00" iyy="3.656843e-05" iyz="0.000000e+00" izz="4.730539e-05"/>
        </inertial>
        <collision name="stingray_v1_root_link1_link1_link4_geom0">
            <geometry>
                <box size="0.0583 0.0512 0.02"/>
            </geometry>
            <origin rpy="2.465190328815662e-32 0.0 0.0" xyz="0.017999999999999988 3.851859888774472e-34 -5.652332851261586e-18"/>
        </collision>
        <collision name="stingray_v1_root_link1_link1_link4_geom1">
            <geometry>
                <box size="0.002 0.053 0.053"/>
            </geometry>
            <origin rpy="2.465190328815662e-32 0.0 0.0" xyz="0.04814999999999999 7.703719777548943e-34 -5.652332851261587e-18"/>
        </collision>
    </link>
</robot>
