<?xml version="1.0" ?>
<robot name="tinlicker_v1">
    <link name="tinlicker_v1_root">
        <inertial>
            <origin rpy="0.0 0.0 0.0" xyz="-5.117766576636557e-19 -0.002254789272030651 0.0"/>
            <mass value="2.610000e-01"/>
            <inertia ixx="2.714798e-04" ixy="-1.393908e-37" ixz="5.057991e-22" iyy="2.436446e-04" iyz="9.933154e-24" izz="3.630267e-04"/>
        </inertial>
        <collision name="tinlicker_v1_root_geom0">
            <geometry>
                <box size="0.089 0.089 0.0603"/>
            </geometry>
            <origin rpy="0.0 0.0 0.0" xyz="0.0 0.0 0.0"/>
        </collision>
        <collision name="tinlicker_v1_root_geom1">
            <geometry>
                <box size="0.018 0.053 0.0165891"/>
            </geometry>
            <origin rpy="1.5707963267948966 0.0 -1.5707963267948966" xyz="-1.214306433183765e-17 -0.0535 0.0"/>
        </collision>
    </link>
    <joint type="revolute" name="tinlicker_v1_root_joint0">
        <parent link="tinlicker_v1_root"/>
        <child link="tinlicker_v1_root_link0"/>
        <origin rpy="1.5707963267948966 0.0 -1.5707963267948966" xyz="-1.734723475976807e-17 -0.07902499999999998 0.0"/>
        <axis xyz="0 1 0"/>
        <limit lower="-1.047197551" upper="1.047197551" effort="0.948013269" velocity="6.338968228"/>
    </joint>
    <link name="tinlicker_v1_root_link0">
        <inertial>
            <origin rpy="0.0 0.0 0.0" xyz="0.029737640449438205 0.0 0.0"/>
            <mass value="8.900000e-02"/>
            <inertia ixx="2.679414e-05" ixy="0.000000e+00" ixz="0.000000e+00" iyy="4.724987e-05" iyz="0.000000e+00" izz="6.030948e-05"/>
        </inertial>
        <collision name="tinlicker_v1_root_link0_geom0">
            <geometry>
                <box size="0.0583 0.0512 0.02"/>
            </geometry>
            <origin rpy="0.0 0.0 0.0" xyz="0.018000000000000002 0.0 0.0"/>
        </collision>
        <collision name="tinlicker_v1_root_link0_geom1">
            <geometry>
                <box size="0.002 0.053 0.053"/>
            </geometry>
            <origin rpy="0.0 0.0 0.0" xyz="0.04815 -1.734723475976807e-18 -1.734723475976807e-18"/>
        </collision>
        <collision name="tinlicker_v1_root_link0_geom2">
            <geometry>
                <box size="0.018 0.053 0.0165891"/>
            </geometry>
            <origin rpy="0.0 0.0 0.0" xyz="0.05815 -1.734723475976807e-18 -5.204170427930421e-18"/>
        </collision>
    </link>
    <joint type="revolute" name="tinlicker_v1_root_link0_joint1">
        <parent link="tinlicker_v1_root_link0"/>
        <child link="tinlicker_v1_root_link0_link1"/>
        <origin rpy="0.0 0.0 0.0" xyz="0.083675 0.0 0.0"/>
        <axis xyz="0 1 0"/>
        <limit lower="-1.047197551" upper="1.047197551" effort="0.948013269" velocity="6.338968228"/>
    </joint>
    <link name="tinlicker_v1_root_link0_link1">
        <inertial>
            <origin rpy="0.0 0.0 0.0" xyz="0.02973764044943819 0.0 -3.469446951953614e-18"/>
            <mass value="8.900000e-02"/>
            <inertia ixx="2.679414e-05" ixy="0.000000e+00" ixz="0.000000e+00" iyy="4.724987e-05" iyz="0.000000e+00" izz="6.030948e-05"/>
        </inertial>
        <collision name="tinlicker_v1_root_link0_link1_geom0">
            <geometry>
                <box size="0.0583 0.0512 0.02"/>
            </geometry>
            <origin rpy="0.0 0.0 0.0" xyz="0.017999999999999988 0.0 -3.469446951953614e-18"/>
        </collision>
        <collision name="tinlicker_v1_root_link0_link1_geom1">
            <geometry>
                <box size="0.002 0.053 0.053"/>
            </geometry>
            <origin rpy="0.0 0.0 0.0" xyz="0.048149999999999984 0.0 -6.938893903907228e-18"/>
        </collision>
        <collision name="tinlicker_v1_root_link0_link1_geom2">
            <geometry>
                <box size="0.018 0.053 0.0165891"/>
            </geometry>
            <origin rpy="0.0 0.0 0.0" xyz="0.05814999999999998 0.0 -6.938893903907228e-18"/>
        </collision>
    </link>
    <joint type="revolute" name="tinlicker_v1_root_link0_link1_joint1">
        <parent link="tinlicker_v1_root_link0_link1"/>
        <child link="tinlicker_v1_root_link0_link1_link1"/>
        <origin rpy="0.0 0.0 0.0" xyz="0.08367499999999997 0.0 0.0"/>
        <axis xyz="0 1 0"/>
        <limit lower="-1.047197551" upper="1.047197551" effort="0.948013269" velocity="6.338968228"/>
    </joint>
    <link name="tinlicker_v1_root_link0_link1_link1">
        <inertial>
            <origin rpy="0.0 0.0 0.0" xyz="0.02973764044943822 0.0 -3.469446951953614e-18"/>
            <mass value="8.900000e-02"/>
            <inertia ixx="2.451623e-05" ixy="-5.057991e-22" ixz="0.000000e+00" iyy="4.952779e-05" iyz="0.000000e+00" izz="6.030948e-05"/>
        </inertial>
        <collision name="tinlicker_v1_root_link0_link1_link1_geom0">
            <geometry>
                <box size="0.0583 0.0512 0.02"/>
            </geometry>
            <origin rpy="0.0 0.0 0.0" xyz="0.018000000000000016 0.0 -3.469446951953614e-18"/>
        </collision>
        <collision name="tinlicker_v1_root_link0_link1_link1_geom1">
            <geometry>
                <box size="0.002 0.053 0.053"/>
            </geometry>
            <origin rpy="0.0 0.0 0.0" xyz="0.04815000000000001 0.0 -6.938893903907228e-18"/>
        </collision>
        <collision name="tinlicker_v1_root_link0_link1_link1_geom2">
            <geometry>
                <box size="0.018 0.053 0.0165891"/>
            </geometry>
            <origin rpy="-1.5707963267948966 0.0 0.0" xyz="0.05815000000000002 0.0 -6.938893903907228e-18"/>
        </collision>
    </link>
    <joint type="revolute" name="tinlicker_v1_root_link0_link1_link1_joint1">
        <parent link="tinlicker_v1_root_link0_link1_link1"/>
        <child link="tinlicker_v1_root_link0_link1_link1_link1"/>
        <origin rpy="-1.5707963267948966 0.0 0.0" xyz="0.083675 0.0 0.0"/>
        <axis xyz="0 1 0"/>
        <limit lower="-1.047197551" upper="1.047197551" effort="0.948013269" velocity="6.338968228"/>
    </joint>
    <link name="tinlicker_v1_root_link0_link1_link1_link1">
        <inertial>
            <origin rpy="0.0 0.0 0.0" xyz="0.08345919034090911 0.042612372159090896 -0.0"/>
            <mass value="2.200000e-01"/>
            <inertia ixx="5.765625e-04" ixy="1.393908e-37" ixz="-5.057991e-22" iyy="7.051810e-04" iyz="-8.446781e-22" izz="1.191507e-03"/>
        </inertial>
        <collision name="tinlicker_v1_root_link0_link1_link1_link1_geom0">
            <geometry>
                <box size="0.0583 0.0512 0.02"/>
            </geometry>
            <origin rpy="0.0 0.0 0.0" xyz="0.018000000000000016 3.469446951953614e-18 -0.0"/>
        </collision>
        <collision name="tinlicker_v1_root_link0_link1_link1_link1_geom1">
            <geometry>
                <box size="0.002 0.053 0.053"/>
            </geometry>
            <origin rpy="0.0 0.0 0.0" xyz="0.04815000000000001 0.0 -0.0"/>
        </collision>
        <collision name="tinlicker_v1_root_link0_link1_link1_link1_geom2">
            <geometry>
                <box size="0.06288625 0.06288625 0.0603"/>
            </geometry>
            <origin rpy="0.0 0.0 0.0" xyz="0.08059312500000002 6.938893903907228e-18 -0.0"/>
        </collision>
        <collision name="tinlicker_v1_root_link0_link1_link1_link1_geom3">
            <geometry>
                <box size="0.06288625 0.06288625 0.0603"/>
            </geometry>
            <origin rpy="0.0 0.0 1.5707963267948966" xyz="0.080593125 0.06288625000000003 -0.0"/>
        </collision>
        <collision name="tinlicker_v1_root_link0_link1_link1_link1_geom4">
            <geometry>
                <box size="0.018 0.053 0.0165891"/>
            </geometry>
            <origin rpy="1.5707963267948963 0.0 1.5707963267948963" xyz="0.080593125 0.103329375 0.0"/>
        </collision>
        <collision name="tinlicker_v1_root_link0_link1_link1_link1_geom5">
            <geometry>
                <box size="0.06288625 0.06288625 0.0603"/>
            </geometry>
            <origin rpy="0.0 0.0 0.0" xyz="0.14347937500000002 0.06288624999999998 -0.0"/>
        </collision>
        <collision name="tinlicker_v1_root_link0_link1_link1_link1_geom6">
            <geometry>
                <box size="0.018 0.053 0.0165891"/>
            </geometry>
            <origin rpy="0.0 0.0 0.0" xyz="0.18392250000000002 0.06288624999999998 -0.0"/>
        </collision>
        <collision name="tinlicker_v1_root_link0_link1_link1_link1_geom7">
            <geometry>
                <box size="0.06288625 0.06288625 0.0603"/>
            </geometry>
            <origin rpy="0.0 0.0 1.5707963267948957" xyz="0.14347937500000002 0.12577249999999998 -0.0"/>
        </collision>
    </link>
    <joint type="revolute" name="tinlicker_v1_root_link0_link1_link1_link1_joint1">
        <parent link="tinlicker_v1_root_link0_link1_link1_link1"/>
        <child link="tinlicker_v1_root_link0_link1_link1_link1_link1"/>
        <origin rpy="1.5707963267948966 0.0 1.5707963267948966" xyz="0.08059312500000002 0.12885437499999997 0.0"/>
        <axis xyz="0 1 0"/>
        <limit lower="-1.047197551" upper="1.047197551" effort="0.948013269" velocity="6.338968228"/>
    </joint>
    <link name="tinlicker_v1_root_link0_link1_link1_link1_link1">
        <inertial>
            <origin rpy="0.0 0.0 0.0" xyz="0.025730769230769245 8.666684749742561e-34 -5.652332851261594e-18"/>
            <mass value="7.800000e-02"/>
            <inertia ixx="2.396696e-05" ixy="0.000000e+00" ixz="0.000000e+00" iyy="3.656843e-05" iyz="0.000000e+00" izz="4.730539e-05"/>
        </inertial>
        <collision name="tinlicker_v1_root_link0_link1_link1_link1_link1_geom0">
            <geometry>
                <box size="0.0583 0.0512 0.02"/>
            </geometry>
            <origin rpy="0.0 0.0 0.0" xyz="0.018000000000000016 3.851859888774472e-34 -5.652332851261595e-18"/>
        </collision>
        <collision name="tinlicker_v1_root_link0_link1_link1_link1_link1_geom1">
            <geometry>
                <box size="0.002 0.053 0.053"/>
            </geometry>
            <origin rpy="0.0 0.0 0.0" xyz="0.04815000000000001 -5.7777898331617076e-34 -5.652332851261595e-18"/>
        </collision>
    </link>
    <joint type="revolute" name="tinlicker_v1_root_link0_link1_link1_link1_joint2">
        <parent link="tinlicker_v1_root_link0_link1_link1_link1"/>
        <child link="tinlicker_v1_root_link0_link1_link1_link1_link2"/>
        <origin rpy="0.0 0.0 0.0" xyz="0.2094475 0.06288624999999992 -0.0"/>
        <axis xyz="0 1 0"/>
        <limit lower="-1.047197551" upper="1.047197551" effort="0.948013269" velocity="6.338968228"/>
    </joint>
    <link name="tinlicker_v1_root_link0_link1_link1_link1_link2">
        <inertial>
            <origin rpy="0.0 0.0 0.0" xyz="0.05384772656250001 -0.016114601562499994 0.0"/>
            <mass value="1.600000e-01"/>
            <inertia ixx="1.836124e-04" ixy="0.000000e+00" ixz="-2.246199e-37" iyy="2.372772e-04" iyz="1.569869e-22" izz="3.686967e-04"/>
        </inertial>
        <collision name="tinlicker_v1_root_link0_link1_link1_link1_link2_geom0">
            <geometry>
                <box size="0.0583 0.0512 0.02"/>
            </geometry>
            <origin rpy="0.0 0.0 0.0" xyz="0.018000000000000016 6.938893903907228e-18 0.0"/>
        </collision>
        <collision name="tinlicker_v1_root_link0_link1_link1_link1_link2_geom1">
            <geometry>
                <box size="0.002 0.053 0.053"/>
            </geometry>
            <origin rpy="0.0 0.0 0.0" xyz="0.04815000000000001 1.3877787807814457e-17 0.0"/>
        </collision>
        <collision name="tinlicker_v1_root_link0_link1_link1_link1_link2_geom2">
            <geometry>
                <box size="0.06288625 0.06288625 0.0603"/>
            </geometry>
            <origin rpy="0.0 0.0 0.0" xyz="0.08059312500000002 1.3877787807814457e-17 0.0"/>
        </collision>
        <collision name="tinlicker_v1_root_link0_link1_link1_link1_link2_geom3">
            <geometry>
                <box size="0.018 0.053 0.0165891"/>
            </geometry>
            <origin rpy="1.5707963267948966 0.0 0.0" xyz="0.12103625000000001 2.0816681711721685e-17 0.0"/>
        </collision>
        <collision name="tinlicker_v1_root_link0_link1_link1_link1_link2_geom4">
            <geometry>
                <box size="0.06288625 0.06288625 0.0603"/>
            </geometry>
            <origin rpy="0.0 0.0 -1.5707963267948966" xyz="0.08059312500000002 -0.06288625 0.0"/>
        </collision>
        <collision name="tinlicker_v1_root_link0_link1_link1_link1_link2_geom5">
            <geometry>
                <box size="0.018 0.053 0.0165891"/>
            </geometry>
            <origin rpy="1.5707963267948963 0.0 -3.141592653589793" xyz="0.04015000000000002 -0.06288624999999999 0.0"/>
        </collision>
    </link>
    <joint type="revolute" name="tinlicker_v1_root_link0_link1_link1_link1_link2_joint1">
        <parent link="tinlicker_v1_root_link0_link1_link1_link1_link2"/>
        <child link="tinlicker_v1_root_link0_link1_link1_link1_link2_link1"/>
        <origin rpy="1.5707963267948966 -2.220446049250313e-16 1.1102230246251565e-16" xyz="0.14656124999999998 1.3877787807814457e-17 0.0"/>
        <axis xyz="0 1 0"/>
        <limit lower="-1.047197551" upper="1.047197551" effort="0.948013269" velocity="6.338968228"/>
    </joint>
    <link name="tinlicker_v1_root_link0_link1_link1_link1_link2_link1">
        <inertial>
            <origin rpy="1.1102230246251563e-16 0.0 1.1102230246251563e-16" xyz="0.025730769230769255 -1.734723475976807e-18 1.734723475976807e-18"/>
            <mass value="7.800000e-02"/>
            <inertia ixx="2.396696e-05" ixy="0.000000e+00" ixz="0.000000e+00" iyy="3.656843e-05" iyz="0.000000e+00" izz="4.730539e-05"/>
        </inertial>
        <collision name="tinlicker_v1_root_link0_link1_link1_link1_link2_link1_geom0">
            <geometry>
                <box size="0.0583 0.0512 0.02"/>
            </geometry>
            <origin rpy="1.1102230246251563e-16 0.0 1.1102230246251563e-16" xyz="0.01800000000000002 0.0 3.469446951953614e-18"/>
        </collision>
        <collision name="tinlicker_v1_root_link0_link1_link1_link1_link2_link1_geom1">
            <geometry>
                <box size="0.002 0.053 0.053"/>
            </geometry>
            <origin rpy="1.1102230246251563e-16 0.0 1.1102230246251563e-16" xyz="0.04815000000000002 -3.469446951953614e-18 -3.469446951953614e-18"/>
        </collision>
    </link>
    <joint type="revolute" name="tinlicker_v1_root_link0_link1_link1_link1_link2_joint2">
        <parent link="tinlicker_v1_root_link0_link1_link1_link1_link2"/>
        <child link="tinlicker_v1_root_link0_link1_link1_link1_link2_link2"/>
        <origin rpy="1.5707963267948966 0.0 3.1415926535897922" xyz="0.014625000000000027 -0.06288624999999996 0.0"/>
        <axis xyz="0 1 0"/>
        <limit lower="-1.047197551" upper="1.047197551" effort="0.948013269" velocity="6.338968228"/>
    </joint>
    <link name="tinlicker_v1_root_link0_link1_link1_link1_link2_link2">
        <inertial>
            <origin rpy="0.0 0.0 0.0" xyz="0.025730769230769245 -1.734723475976807e-18 1.214306433183765e-17"/>
            <mass value="7.800000e-02"/>
            <inertia ixx="2.396696e-05" ixy="0.000000e+00" ixz="0.000000e+00" iyy="3.656843e-05" iyz="0.000000e+00" izz="4.730539e-05"/>
        </inertial>
        <collision name="tinlicker_v1_root_link0_link1_link1_link1_link2_link2_geom0">
            <geometry>
                <box size="0.0583 0.0512 0.02"/>
            </geometry>
            <origin rpy="0.0 0.0 0.0" xyz="0.018000000000000016 -1.734723475976807e-18 1.214306433183765e-17"/>
        </collision>
        <collision name="tinlicker_v1_root_link0_link1_link1_link1_link2_link2_geom1">
            <geometry>
                <box size="0.002 0.053 0.053"/>
            </geometry>
            <origin rpy="0.0 0.0 0.0" xyz="0.04815000000000001 -3.469446951953614e-18 1.0408340855860843e-17"/>
        </collision>
    </link>
</robot>
