<?xml version="1.0" ?>
<robot name="zappa_v1">
    <link name="zappa_v1_root">
        <inertial>
            <origin rpy="0.0 0.0 0.0" xyz="-0.0021636029411764707 -0.00216360294117647 0.0"/>
            <mass value="2.720000e-01"/>
            <inertia ixx="2.743606e-04" ixy="-1.393908e-37" ixz="5.057991e-22" iyy="2.744054e-04" iyz="-2.745096e-22" izz="3.961637e-04"/>
        </inertial>
        <collision name="zappa_v1_root_geom0">
            <geometry>
                <box size="0.089 0.089 0.0603"/>
            </geometry>
            <origin rpy="0.0 0.0 0.0" xyz="0.0 0.0 0.0"/>
        </collision>
        <collision name="zappa_v1_root_geom1">
            <geometry>
                <box size="0.018 0.053 0.0165891"/>
            </geometry>
            <origin rpy="0.0 0.0 3.141592653589793" xyz="-0.0535 6.551860375438339e-18 0.0"/>
        </collision>
        <collision name="zappa_v1_root_geom2">
            <geometry>
                <box size="0.018 0.053 0.0165891"/>
            </geometry>
            <origin rpy="1.5707963267948966 0.0 -1.5707963267948966" xyz="-1.214306433183765e-17 -0.0535 0.0"/>
        </collision>
    </link>
    <joint type="revolute" name="zappa_v1_root_joint0">
        <parent link="zappa_v1_root"/>
        <child link="zappa_v1_root_link0"/>
        <origin rpy="0.0 0.0 3.141592653589793" xyz="-0.07902499999999998 9.677771330261958e-18 0.0"/>
        <axis xyz="0 1 0"/>
        <limit lower="-1.047197551" upper="1.047197551" effort="0.948013269" velocity="6.338968228"/>
    </joint>
    <link name="zappa_v1_root_link0">
        <inertial>
            <origin rpy="0.0 0.0 0.0" xyz="0.025730769230769234 7.703719777548943e-34 0.0"/>
            <mass value="7.800000e-02"/>
            <inertia ixx="2.396696e-05" ixy="0.000000e+00" ixz="0.000000e+00" iyy="3.656843e-05" iyz="0.000000e+00" izz="4.730539e-05"/>
        </inertial>
        <collision name="zappa_v1_root_link0_geom0">
            <geometry>
                <box size="0.0583 0.0512 0.02"/>
            </geometry>
            <origin rpy="0.0 0.0 0.0" xyz="0.018000000000000002 3.851859888774472e-34 0.0"/>
        </collision>
        <collision name="zappa_v1_root_link0_geom1">
            <geometry>
                <box size="0.002 0.053 0.053"/>
            </geometry>
            <origin rpy="0.0 0.0 0.0" xyz="0.04815 0.0 0.0"/>
        </collision>
    </link>
    <joint type="revolute" name="zappa_v1_root_joint1">
        <parent link="zappa_v1_root"/>
        <child link="zappa_v1_root_link1"/>
        <origin rpy="1.5707963267948966 0.0 -1.5707963267948966" xyz="-1.734723475976807e-17 -0.07902499999999998 0.0"/>
        <axis xyz="0 1 0"/>
        <limit lower="-1.047197551" upper="1.047197551" effort="0.948013269" velocity="6.338968228"/>
    </joint>
    <link name="zappa_v1_root_link1">
        <inertial>
            <origin rpy="0.0 0.0 0.0" xyz="0.029737640449438205 0.0 0.0"/>
            <mass value="8.900000e-02"/>
            <inertia ixx="2.679414e-05" ixy="0.000000e+00" ixz="0.000000e+00" iyy="4.724987e-05" iyz="0.000000e+00" izz="6.030948e-05"/>
        </inertial>
        <collision name="zappa_v1_root_link1_geom0">
            <geometry>
                <box size="0.0583 0.0512 0.02"/>
            </geometry>
            <origin rpy="0.0 0.0 0.0" xyz="0.018000000000000002 0.0 0.0"/>
        </collision>
        <collision name="zappa_v1_root_link1_geom1">
            <geometry>
                <box size="0.002 0.053 0.053"/>
            </geometry>
            <origin rpy="0.0 0.0 0.0" xyz="0.04815 -1.734723475976807e-18 -1.734723475976807e-18"/>
        </collision>
        <collision name="zappa_v1_root_link1_geom2">
            <geometry>
                <box size="0.018 0.053 0.0165891"/>
            </geometry>
            <origin rpy="0.0 0.0 0.0" xyz="0.05815 -1.734723475976807e-18 -5.204170427930421e-18"/>
        </collision>
    </link>
    <joint type="revolute" name="zappa_v1_root_link1_joint1">
        <parent link="zappa_v1_root_link1"/>
        <child link="zappa_v1_root_link1_link1"/>
        <origin rpy="0.0 0.0 0.0" xyz="0.083675 0.0 0.0"/>
        <axis xyz="0 1 0"/>
        <limit lower="-1.047197551" upper="1.047197551" effort="0.948013269" velocity="6.338968228"/>
    </joint>
    <link name="zappa_v1_root_link1_link1">
        <inertial>
            <origin rpy="0.0 0.0 0.0" xyz="0.02973764044943819 0.0 -3.469446951953614e-18"/>
            <mass value="8.900000e-02"/>
            <inertia ixx="2.679414e-05" ixy="0.000000e+00" ixz="0.000000e+00" iyy="4.724987e-05" iyz="0.000000e+00" izz="6.030948e-05"/>
        </inertial>
        <collision name="zappa_v1_root_link1_link1_geom0">
            <geometry>
                <box size="0.0583 0.0512 0.02"/>
            </geometry>
            <origin rpy="0.0 0.0 0.0" xyz="0.017999999999999988 0.0 -3.469446951953614e-18"/>
        </collision>
        <collision name="zappa_v1_root_link1_link1_geom1">
            <geometry>
                <box size="0.002 0.053 0.053"/>
            </geometry>
            <origin rpy="0.0 0.0 0.0" xyz="0.048149999999999984 0.0 -6.938893903907228e-18"/>
        </collision>
        <collision name="zappa_v1_root_link1_link1_geom2">
            <geometry>
                <box size="0.018 0.053 0.0165891"/>
            </geometry>
            <origin rpy="0.0 0.0 0.0" xyz="0.05814999999999998 0.0 -6.938893903907228e-18"/>
        </collision>
    </link>
    <joint type="revolute" name="zappa_v1_root_link1_link1_joint1">
        <parent link="zappa_v1_root_link1_link1"/>
        <child link="zappa_v1_root_link1_link1_link1"/>
        <origin rpy="0.0 0.0 0.0" xyz="0.08367499999999997 0.0 0.0"/>
        <axis xyz="0 1 0"/>
        <limit lower="-1.047197551" upper="1.047197551" effort="0.948013269" velocity="6.338968228"/>
    </joint>
    <link name="zappa_v1_root_link1_link1_link1">
        <inertial>
            <origin rpy="0.0 0.0 0.0" xyz="0.02973764044943822 0.0 -3.469446951953614e-18"/>
            <mass value="8.900000e-02"/>
            <inertia ixx="2.451623e-05" ixy="-5.057991e-22" ixz="0.000000e+00" iyy="4.952779e-05" iyz="0.000000e+00" izz="6.030948e-05"/>
        </inertial>
        <collision name="zappa_v1_root_link1_link1_link1_geom0">
            <geometry>
                <box size="0.0583 0.0512 0.02"/>
            </geometry>
            <origin rpy="0.0 0.0 0.0" xyz="0.018000000000000016 0.0 -3.469446951953614e-18"/>
        </collision>
        <collision name="zappa_v1_root_link1_link1_link1_geom1">
            <geometry>
                <box size="0.002 0.053 0.053"/>
            </geometry>
            <origin rpy="0.0 0.0 0.0" xyz="0.04815000000000001 0.0 -6.938893903907228e-18"/>
        </collision>
        <collision name="zappa_v1_root_link1_link1_link1_geom2">
            <geometry>
                <box size="0.018 0.053 0.0165891"/>
            </geometry>
            <origin rpy="-1.5707963267948966 0.0 0.0" xyz="0.05815000000000002 0.0 -6.938893903907228e-18"/>
        </collision>
    </link>
    <joint type="revolute" name="zappa_v1_root_link1_link1_link1_joint1">
        <parent link="zappa_v1_root_link1_link1_link1"/>
        <child link="zappa_v1_root_link1_link1_link1_link1"/>
        <origin rpy="-1.5707963267948966 0.0 0.0" xyz="0.083675 0.0 0.0"/>
        <axis xyz="0 1 0"/>
        <limit lower="-1.047197551" upper="1.047197551" effort="0.948013269" velocity="6.338968228"/>
    </joint>
    <link name="zappa_v1_root_link1_link1_link1_link1">
        <inertial>
            <origin rpy="0.0 0.0 0.0" xyz="0.02973764044943822 0.0 -0.0"/>
            <mass value="8.900000e-02"/>
            <inertia ixx="2.679414e-05" ixy="0.000000e+00" ixz="0.000000e+00" iyy="4.724987e-05" iyz="0.000000e+00" izz="6.030948e-05"/>
        </inertial>
        <collision name="zappa_v1_root_link1_link1_link1_link1_geom0">
            <geometry>
                <box size="0.0583 0.0512 0.02"/>
            </geometry>
            <origin rpy="0.0 0.0 0.0" xyz="0.018000000000000016 3.469446951953614e-18 -0.0"/>
        </collision>
        <collision name="zappa_v1_root_link1_link1_link1_link1_geom1">
            <geometry>
                <box size="0.002 0.053 0.053"/>
            </geometry>
            <origin rpy="0.0 0.0 0.0" xyz="0.04815000000000001 0.0 -0.0"/>
        </collision>
        <collision name="zappa_v1_root_link1_link1_link1_link1_geom2">
            <geometry>
                <box size="0.018 0.053 0.0165891"/>
            </geometry>
            <origin rpy="0.0 0.0 0.0" xyz="0.05815000000000002 0.0 -0.0"/>
        </collision>
    </link>
    <joint type="revolute" name="zappa_v1_root_link1_link1_link1_link1_joint1">
        <parent link="zappa_v1_root_link1_link1_link1_link1"/>
        <child link="zappa_v1_root_link1_link1_link1_link1_link1"/>
        <origin rpy="0.0 0.0 0.0" xyz="0.083675 6.938893903907228e-18 -0.0"/>
        <axis xyz="0 1 0"/>
        <limit lower="-1.047197551" upper="1.047197551" effort="0.948013269" velocity="6.338968228"/>
    </joint>
    <link name="zappa_v1_root_link1_link1_link1_link1_link1">
        <inertial>
            <origin rpy="0.0 0.0 0.0" xyz="0.05109782211538462 0.0034221105769230813 -0.0"/>
            <mass value="1.300000e-01"/>
            <inertia ixx="6.279003e-05" ixy="1.393908e-37" ixz="-5.057991e-22" iyy="1.986327e-04" iyz="9.933154e-24" izz="2.289137e-04"/>
        </inertial>
        <collision name="zappa_v1_root_link1_link1_link1_link1_link1_geom0">
            <geometry>
                <box size="0.0583 0.0512 0.02"/>
            </geometry>
            <origin rpy="0.0 0.0 0.0" xyz="0.018000000000000016 3.469446951953614e-18 -0.0"/>
        </collision>
        <collision name="zappa_v1_root_link1_link1_link1_link1_link1_geom1">
            <geometry>
                <box size="0.002 0.053 0.053"/>
            </geometry>
            <origin rpy="0.0 0.0 0.0" xyz="0.04815000000000001 0.0 -0.0"/>
        </collision>
        <collision name="zappa_v1_root_link1_link1_link1_link1_link1_geom2">
            <geometry>
                <box size="0.06288625 0.06288625 0.0603"/>
            </geometry>
            <origin rpy="0.0 0.0 0.0" xyz="0.08059312500000002 6.938893903907228e-18 -0.0"/>
        </collision>
        <collision name="zappa_v1_root_link1_link1_link1_link1_link1_geom3">
            <geometry>
                <box size="0.018 0.053 0.0165891"/>
            </geometry>
            <origin rpy="0.0 0.0 0.0" xyz="0.12103625000000001 0.0 -0.0"/>
        </collision>
        <collision name="zappa_v1_root_link1_link1_link1_link1_link1_geom4">
            <geometry>
                <box size="0.018 0.053 0.0165891"/>
            </geometry>
            <origin rpy="1.5707963267948963 0.0 1.5707963267948963" xyz="0.080593125 0.04044312500000001 -0.0"/>
        </collision>
    </link>
    <joint type="revolute" name="zappa_v1_root_link1_link1_link1_link1_link1_joint1">
        <parent link="zappa_v1_root_link1_link1_link1_link1_link1"/>
        <child link="zappa_v1_root_link1_link1_link1_link1_link1_link1"/>
        <origin rpy="0.0 0.0 0.0" xyz="0.14656125000000003 0.0 -0.0"/>
        <axis xyz="0 1 0"/>
        <limit lower="-1.047197551" upper="1.047197551" effort="0.948013269" velocity="6.338968228"/>
    </joint>
    <link name="zappa_v1_root_link1_link1_link1_link1_link1_link1">
        <inertial>
            <origin rpy="0.0 0.0 0.0" xyz="0.02973764044943822 0.0 -0.0"/>
            <mass value="8.900000e-02"/>
            <inertia ixx="2.679414e-05" ixy="0.000000e+00" ixz="0.000000e+00" iyy="4.724987e-05" iyz="0.000000e+00" izz="6.030948e-05"/>
        </inertial>
        <collision name="zappa_v1_root_link1_link1_link1_link1_link1_link1_geom0">
            <geometry>
                <box size="0.0583 0.0512 0.02"/>
            </geometry>
            <origin rpy="0.0 0.0 0.0" xyz="0.018000000000000016 3.469446951953614e-18 -0.0"/>
        </collision>
        <collision name="zappa_v1_root_link1_link1_link1_link1_link1_link1_geom1">
            <geometry>
                <box size="0.002 0.053 0.053"/>
            </geometry>
            <origin rpy="0.0 0.0 0.0" xyz="0.04815000000000001 0.0 -0.0"/>
        </collision>
        <collision name="zappa_v1_root_link1_link1_link1_link1_link1_link1_geom2">
            <geometry>
                <box size="0.018 0.053 0.0165891"/>
            </geometry>
            <origin rpy="0.0 0.0 0.0" xyz="0.05815000000000002 0.0 -0.0"/>
        </collision>
    </link>
    <joint type="revolute" name="zappa_v1_root_link1_link1_link1_link1_link1_link1_joint1">
        <parent link="zappa_v1_root_link1_link1_link1_link1_link1_link1"/>
        <child link="zappa_v1_root_link1_link1_link1_link1_link1_link1_link1"/>
        <origin rpy="0.0 0.0 0.0" xyz="0.08367500000000005 0.0 -0.0"/>
        <axis xyz="0 1 0"/>
        <limit lower="-1.047197551" upper="1.047197551" effort="0.948013269" velocity="6.338968228"/>
    </joint>
    <link name="zappa_v1_root_link1_link1_link1_link1_link1_link1_link1">
        <inertial>
            <origin rpy="0.0 0.0 0.0" xyz="0.025730769230769245 1.734723475976807e-18 -0.0"/>
            <mass value="7.800000e-02"/>
            <inertia ixx="2.396696e-05" ixy="0.000000e+00" ixz="0.000000e+00" iyy="3.656843e-05" iyz="0.000000e+00" izz="4.730539e-05"/>
        </inertial>
        <collision name="zappa_v1_root_link1_link1_link1_link1_link1_link1_link1_geom0">
            <geometry>
                <box size="0.0583 0.0512 0.02"/>
            </geometry>
            <origin rpy="0.0 0.0 0.0" xyz="0.018000000000000016 3.469446951953614e-18 -0.0"/>
        </collision>
        <collision name="zappa_v1_root_link1_link1_link1_link1_link1_link1_link1_geom1">
            <geometry>
                <box size="0.002 0.053 0.053"/>
            </geometry>
            <origin rpy="0.0 0.0 0.0" xyz="0.04815000000000001 0.0 -0.0"/>
        </collision>
    </link>
    <joint type="revolute" name="zappa_v1_root_link1_link1_link1_link1_link1_joint2">
        <parent link="zappa_v1_root_link1_link1_link1_link1_link1"/>
        <child link="zappa_v1_root_link1_link1_link1_link1_link1_link2"/>
        <origin rpy="1.5707963267948966 0.0 1.5707963267948966" xyz="0.08059312500000003 0.06596812499999999 -0.0"/>
        <axis xyz="0 1 0"/>
        <limit lower="-1.047197551" upper="1.047197551" effort="0.948013269" velocity="6.338968228"/>
    </joint>
    <link name="zappa_v1_root_link1_link1_link1_link1_link1_link2">
        <inertial>
            <origin rpy="0.0 0.0 0.0" xyz="0.05109782211538462 1.3010426069826053e-18 -0.0034221105769231376"/>
            <mass value="1.300000e-01"/>
            <inertia ixx="6.283477e-05" ixy="-4.958660e-22" ixz="5.157323e-22" iyy="2.173355e-04" iyz="1.415964e-37" izz="2.101661e-04"/>
        </inertial>
        <collision name="zappa_v1_root_link1_link1_link1_link1_link1_link2_geom0">
            <geometry>
                <box size="0.0583 0.0512 0.02"/>
            </geometry>
            <origin rpy="0.0 0.0 0.0" xyz="0.018000000000000016 1.232595164407831e-32 -6.116348408251942e-17"/>
        </collision>
        <collision name="zappa_v1_root_link1_link1_link1_link1_link1_link2_geom1">
            <geometry>
                <box size="0.002 0.053 0.053"/>
            </geometry>
            <origin rpy="0.0 0.0 0.0" xyz="0.04815000000000001 6.162975822039155e-33 -6.116348408251943e-17"/>
        </collision>
        <collision name="zappa_v1_root_link1_link1_link1_link1_link1_link2_geom2">
            <geometry>
                <box size="0.06288625 0.06288625 0.0603"/>
            </geometry>
            <origin rpy="-1.5707963267948966 0.0 0.0" xyz="0.08059312500000002 1.232595164407831e-32 -6.116348408251942e-17"/>
        </collision>
        <collision name="zappa_v1_root_link1_link1_link1_link1_link1_link2_geom3">
            <geometry>
                <box size="0.018 0.053 0.0165891"/>
            </geometry>
            <origin rpy="-1.5707963267948966 0.0 0.0" xyz="0.12103625000000001 3.0814879110195774e-33 -6.116348408251942e-17"/>
        </collision>
        <collision name="zappa_v1_root_link1_link1_link1_link1_link1_link2_geom4">
            <geometry>
                <box size="0.018 0.053 0.0165891"/>
            </geometry>
            <origin rpy="-1.5707963267948966 1.5707963267948966 0.0" xyz="0.080593125 1.3877787807814457e-17 -0.040443125000000066"/>
        </collision>
    </link>
    <joint type="revolute" name="zappa_v1_root_link1_link1_link1_link1_link1_link2_joint1">
        <parent link="zappa_v1_root_link1_link1_link1_link1_link1_link2"/>
        <child link="zappa_v1_root_link1_link1_link1_link1_link1_link2_link1"/>
        <origin rpy="-1.5707963267948966 0.0 0.0" xyz="0.14656125 7.703719777548943e-33 -4.602294267205349e-17"/>
        <axis xyz="0 1 0"/>
        <limit lower="-1.047197551" upper="1.047197551" effort="0.948013269" velocity="6.338968228"/>
    </joint>
    <link name="zappa_v1_root_link1_link1_link1_link1_link1_link2_link1">
        <inertial>
            <origin rpy="0.0 0.0 0.0" xyz="0.025730769230769248 5.6523328512615956e-18 -4.437342591868195e-34"/>
            <mass value="7.800000e-02"/>
            <inertia ixx="2.396696e-05" ixy="0.000000e+00" ixz="0.000000e+00" iyy="3.656843e-05" iyz="0.000000e+00" izz="4.730539e-05"/>
        </inertial>
        <collision name="zappa_v1_root_link1_link1_link1_link1_link1_link2_link1_geom0">
            <geometry>
                <box size="0.0583 0.0512 0.02"/>
            </geometry>
            <origin rpy="0.0 0.0 0.0" xyz="0.018000000000000016 5.652332851261595e-18 -4.437342591868195e-34"/>
        </collision>
        <collision name="zappa_v1_root_link1_link1_link1_link1_link1_link2_link1_geom1">
            <geometry>
                <box size="0.002 0.053 0.053"/>
            </geometry>
            <origin rpy="0.0 0.0 0.0" xyz="0.04815000000000001 5.652332851261593e-18 -4.4373425918681945e-34"/>
        </collision>
    </link>
    <joint type="revolute" name="zappa_v1_root_link1_link1_link1_link1_link1_link2_joint2">
        <parent link="zappa_v1_root_link1_link1_link1_link1_link1_link2"/>
        <child link="zappa_v1_root_link1_link1_link1_link1_link1_link2_link2"/>
        <origin rpy="-1.5707963267948966 1.5707963267948966 0.0" xyz="0.08059312500000002 1.3877787807814457e-17 -0.06596812500000007"/>
        <axis xyz="0 1 0"/>
        <limit lower="-1.047197551" upper="1.047197551" effort="0.948013269" velocity="6.338968228"/>
    </joint>
    <link name="zappa_v1_root_link1_link1_link1_link1_link1_link2_link2">
        <inertial>
            <origin rpy="0.0 0.0 0.0" xyz="0.04097031249999996 6.938893903907228e-18 6.938893903907228e-18"/>
            <mass value="1.080000e-01"/>
            <inertia ixx="4.294389e-05" ixy="0.000000e+00" ixz="0.000000e+00" iyy="1.207594e-04" iyz="0.000000e+00" izz="1.322928e-04"/>
        </inertial>
        <collision name="zappa_v1_root_link1_link1_link1_link1_link1_link2_link2_geom0">
            <geometry>
                <box size="0.0583 0.0512 0.02"/>
            </geometry>
            <origin rpy="0.0 0.0 0.0" xyz="0.01799999999999996 1.0408340855860843e-17 6.938893903907228e-18"/>
        </collision>
        <collision name="zappa_v1_root_link1_link1_link1_link1_link1_link2_link2_geom1">
            <geometry>
                <box size="0.002 0.053 0.053"/>
            </geometry>
            <origin rpy="0.0 0.0 0.0" xyz="0.04814999999999996 1.0408340855860843e-17 6.938893903907228e-18"/>
        </collision>
        <collision name="zappa_v1_root_link1_link1_link1_link1_link1_link2_link2_geom2">
            <geometry>
                <box size="0.06288625 0.06288625 0.0603"/>
            </geometry>
            <origin rpy="0.0 0.0 0.0" xyz="0.08059312499999996 6.938893903907228e-18 6.938893903907228e-18"/>
        </collision>
    </link>
</robot>
